Workbook
Name CoName: Setup!$C$5
Name CoAddr: Setup!$C$6
Name CoPhone: Setup!$C$7
Name CoWeb: Setup!$C$8
Name CoSpec1: Setup!$C$9
Name CoSpec2: Setup!$C$10
Name RODryW: Setup!$C$11
Name RODryH: Setup!$C$12
Name ROTolDef: Setup!$C$13
Name RevH: Setup!$C$14
Name RevL: Setup!$C$15
Name RevT: Setup!$C$16
Name UCCur: Setup!$C$17
Name UCOth: Setup!$C$18
Name LiteTop: Setup!$C$19
Name LiteEdge: Setup!$C$20
Name DBAFF: Setup!$C$21
Name LockAFF: Setup!$C$22
Name MinRail: Setup!$C$23
Name L_Fire: Lists!$A$2:$A$7
Name L_Style: Lists!$B$2:$B$3
Name L_Swing: Lists!$C$2:$C$6
Name L_Anchor: Lists!$D$2:$D$9
Name L_Hinge: Lists!$E$2:$E$7
Name L_Strike1: Lists!$F$2:$F$7
Name L_Strike2: Lists!$G$2:$G$3
Name L_Lock1: Lists!$H$2:$H$11
Name L_Lock2: Lists!$I$2:$I$4
Name L_Mfr: Lists!$J$2:$J$12
Name L_Elev: Lists!$K$2:$K$20
Name L_Wall: Lists!$L$2:$L$3
Name L_Mat: Lists!$M$2:$M$3
Name L_YN: Lists!$N$2:$N$2
Name L_Gauge: Lists!$O$2:$O$4
Name L_Face: Lists!$P$2:$P$3
Name L_WFt: Lists!$Q$2:$Q$6
Name L_HFt: Lists!$R$2:$R$7
Name L_In: Lists!$S$2:$S$13
Name L_Jamb: Lists!$U$2:$U$74
Name T_Jamb: Lists!$U$2:$W$74
Name T_Leg: Lists!$Y$2:$Z$47
Name T_Loc: Locations!$B$6:$J$32
Name T_LocKey: Locations!$B$6:$B$32

Sheet Start
B3: =CoName
B4: FRAME CALCULATOR 2.0
B6: Shop tags: frame & door sizes · rough openings · hinge, strike and lock locations · elevations · swing · jamb profile · order lines
B10: GO TO
B11: TAG 1 | C11: A tag — type the opening on the yellow cells, print one page
B12: TAG 2 | C12: A tag — type the opening on the yellow cells, print one page
B13: TAG 3 | C13: A tag — type the opening on the yellow cells, print one page
B14: TAG 4 | C14: A tag — type the opening on the yellow cells, print one page
B15: TAG 5 | C15: A tag — type the opening on the yellow cells, print one page
B16: TAG 6 | C16: A tag — type the opening on the yellow cells, print one page
B17: TAG LIST | C17: Every tag and its order lines on one page
B18: ROUGH OPENING | C18: Field R.O. → faces, outside size and door
B19: BI-PASS | C19: Bi-pass wood door sizes
B20: LOCATIONS | C20: Maker hinge / strike charts (editable)
B21: SETUP | C21: Company lines and shop rules
B24: WHAT CHANGED FROM THE 2.0 CALCULATOR
B25: ▸ | C25: Every location comes from one maker table (Locations) instead of long nested IFs — edit a number once and every tag follows.
B26: ▸ | C26: Cut-down rule kept: a 6'-5" opening takes the 6'-8" chart from the top; too short to cut is flagged NOT STOCK and re-spaced.
B27: ▸ | C27: Frame and door elevations are drawn live with every hinge, strike and lock dimension; plus the swing in plan and the jamb profile to scale.
B28: ▸ | C28: Masonry: type the rough opening and the faces work themselves out (face check 1–12"). Drywall R.O. uses the counter rule (+2-1/4", +1").
B29: ▸ | C29: Reveals, undercut and lite location default from Setup and can be changed per tag. Pairs, deadbolts (E4), mortise locks and custom locations handled.
B30: ▸ | C30: Order lines (frame and door) written in the counter format on every tag and gathered on Tag List.
B31: ▸ | C31: Six tag sheets that print one page each; add more by copying a tag sheet.

Sheet Setup
B1: SETUP
B2: Company lines that print on every tag, and the shop rules the tags use. Change once.
B5: Company | C5: SCHUHAM BUILDER'S SUPPLY CO., INC.
B6: Address | C6: 4640 N. ELSTON AVE. CHICAGO, IL 60630
B7: Phone | C7: PHONE: 773.286.0123
B8: Web | C8: WWW.SCHUHAM.COM
B9: Specs line 1 | C9: Baron Door & Frame
B10: Specs line 2 | C10: Curries Hollow Metal
B11: Drywall R.O. — add to width | C11: 2.25 | D11: Opening + 2-1/4" (counter rule).
B12: Drywall R.O. — add to height | C12: 1 | D12: Opening + 1".
B13: Masonry tolerance each side | C13: 0.25 | D13: Used when the masonry R.O. is typed and no tolerance is given.
B14: Reveal — hinge side | C14: 0.0625 | D14: 1/16" default (edit on a tag to override).
B15: Reveal — lock side / meeting edge | C15: 0.1875 | D15: 3/16" default.
B16: Reveal — top | C16: 0.125 | D16: 1/8" default.
B17: Undercut — Curries / Pioneer | C17: 0.625 | D17: 5/8".
B18: Undercut — other makers | C18: 0.75 | D18: 3/4".
B19: Lite top from top of door | C19: 7 | D19: Full and vision lites, unless typed on the tag.
B20: Narrow lite from lock edge | C20: 5.5 | D20: Lites 10" wide or less sit this far off the lock edge.
B21: Deadbolt centre line AFF | C21: 48 | D21: Strike 2 / lock 2 (E4) from the floor.
B22: ANSI lock centre line AFF | C22: 40.3125 | D22: 40-5/16" when no maker chart is used.
B23: Min. rail under bottom hinge | C23: 2.125 | D23: A stock door can be cut down while 2-1/8" stays under the bottom hinge.

Sheet Tag 1
B1: =CoName | R1: ="TAG "&IF('Tag 1'!$S$4="","1",'Tag 1'!$S$4)&" · QTY "&N('Tag 1'!$W$4)
B2: ="FRAME CALCULATOR · "&CoSpec1&" · "&CoSpec2 | R2: ="Printed "&TEXT(NOW(),"mm/dd/yyyy hh:mm")
B4: CUSTOMER | K4: P.O./JOB | R4: TAG # | S4: 1 | V4: QTY | W4: 1
B6: JAMB DEPTH | D6: FIRE RATING | F6: W FT | G6: W IN | H6: H FT | I6: H IN | J6: PAIR | K6: CONST. STYLE | M6: SWING | N6: ANCHOR | P6: HINGE | R6: STRIKE 1 | T6: STRIKE 2 | U6: LOCK 1 | W6: LOCK 2 | X6: LOCATIONS
B7: 718 | D7: 90 MIN | F7: 3 | G7: 0 | H7: 6 | I7: 5 | K7: KD-3PC | M7: LH | N7: COMP | P7: U453 | R7: E1 | U7: G2G2 | X7: STEELCRAFT
B8: ELEVATION | E8: WALL | G8: FRAME GA | H8: DOOR | J8: DOOR GA | K8: HEAD FACE | L8: JAMB FACE | M8: REV HINGE | N8: REV LOCK | O8: REV TOP | P8: UNDERCUT | Q8: MASONRY R.O. W | S8: MASONRY R.O. H | U8: TOL. EA SIDE | V8: LITE W | W8: LITE H | X8: LITE TOP
B9: FLUSH | E9: DRYWALL | G9: 16 | H9: WOOD | J9: 18 | K9: 2 | L9: 2
B10: CUSTOM A | D10: CUSTOM B | F10: CUSTOM C | H10: CUSTOM D | J10: CUSTOM E | L10: HARDWARE NOTES
B13: FRAME SIZE INFO | I13: FRAME ELEVATION — locations from the top of the frame | S13: DOOR SIZE INFO
B14: INSIDE WIDTH | E14: =Calc!$B$1 | S14: OPENING WIDTH | V14: =Calc!$B$1
B15: INSIDE HEIGHT | E15: =Calc!$B$2 | S15: OPENING HEIGHT | V15: =Calc!$B$2
B16: OUTSIDE WIDTH | E16: =Calc!$B$13 | S16: ACTUAL WIDTH | V16: =Calc!$B$24
B17: OUTSIDE HEIGHT | E17: =Calc!$B$14 | S17: ACTUAL HEIGHT | V17: =Calc!$B$25
B18: HEADER FACE | E18: =Calc!$B$12 | S18: REVEAL HINGE / LOCK / TOP | V18: =TRIM(TEXT(Calc!$B$20,"# ?/??"))&CHAR(34)&" · "&TRIM(TEXT(Calc!$B$21,"# ?/??"))&CHAR(34)&" · "&TRIM(TEXT(Calc!$B$22,"# ?/??"))&CHAR(34)
B19: HINGE & STRIKE FACE | E19: =Calc!$B$11 | S19: UNDERCUT | V19: =Calc!$B$23
B20: JAMB DEPTH | E20: =Calc!$B$7 | S20: LITE KIT | V20: =IF(Calc!$B$59,Calc!$B$86&" · top "&TRIM(TEXT(Calc!$B$58,"# ?/??"))&CHAR(34),"FLUSH")
B21: FITS WALL (throat) | E21: =Calc!$B$15
S22: HARDWARE LOCATIONS — DOOR (from top of door)
B23: ROUGH OPENING | S23: HINGE 1 | V23: =IF(ISNUMBER(Calc!$B$40),Calc!$B$40-Calc!$B$22,IF(Calc!$B$26=0,"","NONE"))
B24: DRYWALL W x H | E24: =TRIM(TEXT(Calc!$B$16,"# ?/??"))&CHAR(34)&" x "&TRIM(TEXT(Calc!$B$17,"# ?/??"))&CHAR(34) | S24: HINGE 2 | V24: =IF(ISNUMBER(Calc!$B$41),Calc!$B$41-Calc!$B$22,IF(Calc!$B$26=0,"","NONE"))
B25: MASONRY W x H | E25: =TRIM(TEXT(Calc!$B$18,"# ?/??"))&CHAR(34)&" x "&TRIM(TEXT(Calc!$B$19,"# ?/??"))&CHAR(34) | S25: HINGE 3 | V25: =IF(ISNUMBER(Calc!$B$42),Calc!$B$42-Calc!$B$22,IF(Calc!$B$26=0,"","NONE"))
B26: FACE CHECK | E26: =IF(OR(Calc!$B$11<1,Calc!$B$11>12,Calc!$B$12<1,Calc!$B$12>12),"ERROR — face out of range","OK") | S26: HINGE 4 | V26: =IF(ISNUMBER(Calc!$B$43),Calc!$B$43-Calc!$B$22,IF(Calc!$B$26=0,"","NONE"))
S27: LOCK 1 CYL CL | V27: =Calc!$B$49
B28: HARDWARE LOCATIONS — FRAME | S28: LOCK 2 CYL CL | V28: =Calc!$B$50
B29: MANUFACTURER | E29: ='Tag 1'!$X$7 | S29: TOP MORTISE LOCK | V29: =Calc!$B$51
B30: CHART | E30: =IF(Calc!$B$29,INT(ROUND(Calc!$B$28,4)/12)&"'-"&IF(ROUND(MOD(Calc!$B$28,12),4)=0,"0",TRIM(TEXT(MOD(Calc!$B$28,12),"# ?/??")))&CHAR(34)&IF(Calc!$B$36," cut down",IF(Calc!$B$38," — NOT STOCK","")),IF(Calc!$B$27,"CUSTOM","ANSI/SDI")) | S30: MORTISE TOP TO CL | V30: =Calc!$B$52
B31: HINGE 1 | E31: =IF(ISNUMBER(Calc!$B$40),Calc!$B$40,IF(Calc!$B$26=0,IF(AND(0=0,'Tag 1'!$P$7="HGC"),"CONTINUOUS",""),"NONE"))
B32: HINGE 2 | E32: =IF(ISNUMBER(Calc!$B$41),Calc!$B$41,IF(Calc!$B$26=0,IF(AND(1=0,'Tag 1'!$P$7="HGC"),"CONTINUOUS",""),"NONE")) | S32: DOOR ELEVATION
B33: HINGE 3 | E33: =IF(ISNUMBER(Calc!$B$42),Calc!$B$42,IF(Calc!$B$26=0,IF(AND(2=0,'Tag 1'!$P$7="HGC"),"CONTINUOUS",""),"NONE"))
B34: HINGE 4 | E34: =IF(ISNUMBER(Calc!$B$43),Calc!$B$43,IF(Calc!$B$26=0,IF(AND(3=0,'Tag 1'!$P$7="HGC"),"CONTINUOUS",""),"NONE")) | I34: SWING (plan) · JAMB PROFILE
B35: STRIKE 1 (E) | E35: =Calc!$B$46
B36: STRIKE 2 | E36: =Calc!$B$47
B38: OTHER MEASUREMENTS — FRAME
B39: ASA 4-7/8 TOP TO TOP | E39: =IF(ISNUMBER(Calc!$B$46),Calc!$B$46-2.4375,"")
B40: ASA 4-7/8 FTC (lock AFF) | E40: =Calc!$B$53
B41: DEADBOLT FTC | E41: =IF(ISNUMBER(Calc!$B$47),Calc!$B$2-Calc!$B$47,"")
B42: HAND / SWING | E42: =Calc!$B$87
B53: ORDER LINES
B54: FRAME | D54: =IF(Calc!$B$3,'Tag 1'!$W$4&") "&Calc!$B$64,"")
B55: DOOR | D55: =IF(Calc!$B$3,'Tag 1'!$W$4*Calc!$B$5&") "&Calc!$B$66,"")
...

Sheet Tag 2
B1: =CoName | R1: ="TAG "&IF('Tag 2'!$S$4="","2",'Tag 2'!$S$4)&" · QTY "&N('Tag 2'!$W$4)
B2: ="FRAME CALCULATOR · "&CoSpec1&" · "&CoSpec2 | R2: ="Printed "&TEXT(NOW(),"mm/dd/yyyy hh:mm")
B4: CUSTOMER | K4: P.O./JOB | R4: TAG # | S4: 2 | V4: QTY | W4: 1
B6: JAMB DEPTH | D6: FIRE RATING | F6: W FT | G6: W IN | H6: H FT | I6: H IN | J6: PAIR | K6: CONST. STYLE | M6: SWING | N6: ANCHOR | P6: HINGE | R6: STRIKE 1 | T6: STRIKE 2 | U6: LOCK 1 | W6: LOCK 2 | X6: LOCATIONS
B7: 534 | D7: 90 MIN | F7: 3 | G7: 0 | H7: 7 | I7: 0 | K7: WELDED | M7: RHR | N7: P/D+D.BOLT | P7: U453 | R7: E8 | U7: G11 | X7: STEELCRAFT
B8: ELEVATION | E8: WALL | G8: FRAME GA | H8: DOOR | J8: DOOR GA | K8: HEAD FACE | L8: JAMB FACE | M8: REV HINGE | N8: REV LOCK | O8: REV TOP | P8: UNDERCUT | Q8: MASONRY R.O. W | S8: MASONRY R.O. H | U8: TOL. EA SIDE | V8: LITE W | W8: LITE H | X8: LITE TOP
B9: HG 24"x30" | E9: MASONRY | G9: 16 | H9: HM | J9: 18 | K9: 2 | L9: 2 | Q9: 40.5 | S9: 86.25
B10: CUSTOM A | D10: CUSTOM B | F10: CUSTOM C | H10: CUSTOM D | J10: CUSTOM E | L10: HARDWARE NOTES
B13: FRAME SIZE INFO | I13: FRAME ELEVATION — locations from the top of the frame | S13: DOOR SIZE INFO
B14: INSIDE WIDTH | E14: =Calc!$G$1 | S14: OPENING WIDTH | V14: =Calc!$G$1
B15: INSIDE HEIGHT | E15: =Calc!$G$2 | S15: OPENING HEIGHT | V15: =Calc!$G$2
B16: OUTSIDE WIDTH | E16: =Calc!$G$13 | S16: ACTUAL WIDTH | V16: =Calc!$G$24
B17: OUTSIDE HEIGHT | E17: =Calc!$G$14 | S17: ACTUAL HEIGHT | V17: =Calc!$G$25
B18: HEADER FACE | E18: =Calc!$G$12 | S18: REVEAL HINGE / LOCK / TOP | V18: =TRIM(TEXT(Calc!$G$20,"# ?/??"))&CHAR(34)&" · "&TRIM(TEXT(Calc!$G$21,"# ?/??"))&CHAR(34)&" · "&TRIM(TEXT(Calc!$G$22,"# ?/??"))&CHAR(34)
B19: HINGE & STRIKE FACE | E19: =Calc!$G$11 | S19: UNDERCUT | V19: =Calc!$G$23
B20: JAMB DEPTH | E20: =Calc!$G$7 | S20: LITE KIT | V20: =IF(Calc!$G$59,Calc!$G$86&" · top "&TRIM(TEXT(Calc!$G$58,"# ?/??"))&CHAR(34),"FLUSH")
B21: FITS WALL (throat) | E21: =Calc!$G$15
S22: HARDWARE LOCATIONS — DOOR (from top of door)
B23: ROUGH OPENING | S23: HINGE 1 | V23: =IF(ISNUMBER(Calc!$G$40),Calc!$G$40-Calc!$G$22,IF(Calc!$G$26=0,"","NONE"))
B24: DRYWALL W x H | E24: =TRIM(TEXT(Calc!$G$16,"# ?/??"))&CHAR(34)&" x "&TRIM(TEXT(Calc!$G$17,"# ?/??"))&CHAR(34) | S24: HINGE 2 | V24: =IF(ISNUMBER(Calc!$G$41),Calc!$G$41-Calc!$G$22,IF(Calc!$G$26=0,"","NONE"))
B25: MASONRY W x H | E25: =TRIM(TEXT(Calc!$G$18,"# ?/??"))&CHAR(34)&" x "&TRIM(TEXT(Calc!$G$19,"# ?/??"))&CHAR(34) | S25: HINGE 3 | V25: =IF(ISNUMBER(Calc!$G$42),Calc!$G$42-Calc!$G$22,IF(Calc!$G$26=0,"","NONE"))
B26: FACE CHECK | E26: =IF(OR(Calc!$G$11<1,Calc!$G$11>12,Calc!$G$12<1,Calc!$G$12>12),"ERROR — face out of range","OK") | S26: HINGE 4 | V26: =IF(ISNUMBER(Calc!$G$43),Calc!$G$43-Calc!$G$22,IF(Calc!$G$26=0,"","NONE"))
S27: LOCK 1 CYL CL | V27: =Calc!$G$49
B28: HARDWARE LOCATIONS — FRAME | S28: LOCK 2 CYL CL | V28: =Calc!$G$50
B29: MANUFACTURER | E29: ='Tag 2'!$X$7 | S29: TOP MORTISE LOCK | V29: =Calc!$G$51
B30: CHART | E30: =IF(Calc!$G$29,INT(ROUND(Calc!$G$28,4)/12)&"'-"&IF(ROUND(MOD(Calc!$G$28,12),4)=0,"0",TRIM(TEXT(MOD(Calc!$G$28,12),"# ?/??")))&CHAR(34)&IF(Calc!$G$36," cut down",IF(Calc!$G$38," — NOT STOCK","")),IF(Calc!$G$27,"CUSTOM","ANSI/SDI")) | S30: MORTISE TOP TO CL | V30: =Calc!$G$52
B31: HINGE 1 | E31: =IF(ISNUMBER(Calc!$G$40),Calc!$G$40,IF(Calc!$G$26=0,IF(AND(0=0,'Tag 2'!$P$7="HGC"),"CONTINUOUS",""),"NONE"))
B32: HINGE 2 | E32: =IF(ISNUMBER(Calc!$G$41),Calc!$G$41,IF(Calc!$G$26=0,IF(AND(1=0,'Tag 2'!$P$7="HGC"),"CONTINUOUS",""),"NONE")) | S32: DOOR ELEVATION
B33: HINGE 3 | E33: =IF(ISNUMBER(Calc!$G$42),Calc!$G$42,IF(Calc!$G$26=0,IF(AND(2=0,'Tag 2'!$P$7="HGC"),"CONTINUOUS",""),"NONE"))
B34: HINGE 4 | E34: =IF(ISNUMBER(Calc!$G$43),Calc!$G$43,IF(Calc!$G$26=0,IF(AND(3=0,'Tag 2'!$P$7="HGC"),"CONTINUOUS",""),"NONE")) | I34: SWING (plan) · JAMB PROFILE
B35: STRIKE 1 (E) | E35: =Calc!$G$46
B36: STRIKE 2 | E36: =Calc!$G$47
B38: OTHER MEASUREMENTS — FRAME
B39: ASA 4-7/8 TOP TO TOP | E39: =IF(ISNUMBER(Calc!$G$46),Calc!$G$46-2.4375,"")
B40: ASA 4-7/8 FTC (lock AFF) | E40: =Calc!$G$53
B41: DEADBOLT FTC | E41: =IF(ISNUMBER(Calc!$G$47),Calc!$G$2-Calc!$G$47,"")
B42: HAND / SWING | E42: =Calc!$G$87
B53: ORDER LINES
B54: FRAME | D54: =IF(Calc!$G$3,'Tag 2'!$W$4&") "&Calc!$G$64,"")
B55: DOOR | D55: =IF(Calc!$G$3,'Tag 2'!$W$4*Calc!$G$5&") "&Calc!$G$66,"")
...

Sheet Tag 3
B1: =CoName | R1: ="TAG "&IF('Tag 3'!$S$4="","3",'Tag 3'!$S$4)&" · QTY "&N('Tag 3'!$W$4)
B2: ="FRAME CALCULATOR · "&CoSpec1&" · "&CoSpec2 | R2: ="Printed "&TEXT(NOW(),"mm/dd/yyyy hh:mm")
B4: CUSTOMER | K4: P.O./JOB | R4: TAG # | S4: 3 | V4: QTY | W4: 1
B6: JAMB DEPTH | D6: FIRE RATING | F6: W FT | G6: W IN | H6: H FT | I6: H IN | J6: PAIR | K6: CONST. STYLE | M6: SWING | N6: ANCHOR | P6: HINGE | R6: STRIKE 1 | T6: STRIKE 2 | U6: LOCK 1 | W6: LOCK 2 | X6: LOCATIONS
B7: 578 | D7: NO LAB | F7: 3 | G7: 6 | H7: 7 | I7: 0 | K7: KD-3PC | M7: RH | N7: COMP | P7: U453 | R7: E1E4 | T7: E4 | U7: G2 | W7: G16 | X7: STEELCRAFT
B8: ELEVATION | E8: WALL | G8: FRAME GA | H8: DOOR | J8: DOOR GA | K8: HEAD FACE | L8: JAMB FACE | M8: REV HINGE | N8: REV LOCK | O8: REV TOP | P8: UNDERCUT | Q8: MASONRY R.O. W | S8: MASONRY R.O. H | U8: TOL. EA SIDE | V8: LITE W | W8: LITE H | X8: LITE TOP
B9: FLUSH | E9: DRYWALL | G9: 16 | H9: HM | J9: 18 | K9: 2 | L9: 2
B10: CUSTOM A | D10: CUSTOM B | F10: CUSTOM C | H10: CUSTOM D | J10: CUSTOM E | L10: HARDWARE NOTES
B13: FRAME SIZE INFO | I13: FRAME ELEVATION — locations from the top of the frame | S13: DOOR SIZE INFO
B14: INSIDE WIDTH | E14: =Calc!$L$1 | S14: OPENING WIDTH | V14: =Calc!$L$1
B15: INSIDE HEIGHT | E15: =Calc!$L$2 | S15: OPENING HEIGHT | V15: =Calc!$L$2
B16: OUTSIDE WIDTH | E16: =Calc!$L$13 | S16: ACTUAL WIDTH | V16: =Calc!$L$24
B17: OUTSIDE HEIGHT | E17: =Calc!$L$14 | S17: ACTUAL HEIGHT | V17: =Calc!$L$25
B18: HEADER FACE | E18: =Calc!$L$12 | S18: REVEAL HINGE / LOCK / TOP | V18: =TRIM(TEXT(Calc!$L$20,"# ?/??"))&CHAR(34)&" · "&TRIM(TEXT(Calc!$L$21,"# ?/??"))&CHAR(34)&" · "&TRIM(TEXT(Calc!$L$22,"# ?/??"))&CHAR(34)
B19: HINGE & STRIKE FACE | E19: =Calc!$L$11 | S19: UNDERCUT | V19: =Calc!$L$23
B20: JAMB DEPTH | E20: =Calc!$L$7 | S20: LITE KIT | V20: =IF(Calc!$L$59,Calc!$L$86&" · top "&TRIM(TEXT(Calc!$L$58,"# ?/??"))&CHAR(34),"FLUSH")
B21: FITS WALL (throat) | E21: =Calc!$L$15
S22: HARDWARE LOCATIONS — DOOR (from top of door)
B23: ROUGH OPENING | S23: HINGE 1 | V23: =IF(ISNUMBER(Calc!$L$40),Calc!$L$40-Calc!$L$22,IF(Calc!$L$26=0,"","NONE"))
B24: DRYWALL W x H | E24: =TRIM(TEXT(Calc!$L$16,"# ?/??"))&CHAR(34)&" x "&TRIM(TEXT(Calc!$L$17,"# ?/??"))&CHAR(34) | S24: HINGE 2 | V24: =IF(ISNUMBER(Calc!$L$41),Calc!$L$41-Calc!$L$22,IF(Calc!$L$26=0,"","NONE"))
B25: MASONRY W x H | E25: =TRIM(TEXT(Calc!$L$18,"# ?/??"))&CHAR(34)&" x "&TRIM(TEXT(Calc!$L$19,"# ?/??"))&CHAR(34) | S25: HINGE 3 | V25: =IF(ISNUMBER(Calc!$L$42),Calc!$L$42-Calc!$L$22,IF(Calc!$L$26=0,"","NONE"))
B26: FACE CHECK | E26: =IF(OR(Calc!$L$11<1,Calc!$L$11>12,Calc!$L$12<1,Calc!$L$12>12),"ERROR — face out of range","OK") | S26: HINGE 4 | V26: =IF(ISNUMBER(Calc!$L$43),Calc!$L$43-Calc!$L$22,IF(Calc!$L$26=0,"","NONE"))
S27: LOCK 1 CYL CL | V27: =Calc!$L$49
B28: HARDWARE LOCATIONS — FRAME | S28: LOCK 2 CYL CL | V28: =Calc!$L$50
B29: MANUFACTURER | E29: ='Tag 3'!$X$7 | S29: TOP MORTISE LOCK | V29: =Calc!$L$51
B30: CHART | E30: =IF(Calc!$L$29,INT(ROUND(Calc!$L$28,4)/12)&"'-"&IF(ROUND(MOD(Calc!$L$28,12),4)=0,"0",TRIM(TEXT(MOD(Calc!$L$28,12),"# ?/??")))&CHAR(34)&IF(Calc!$L$36," cut down",IF(Calc!$L$38," — NOT STOCK","")),IF(Calc!$L$27,"CUSTOM","ANSI/SDI")) | S30: MORTISE TOP TO CL | V30: =Calc!$L$52
B31: HINGE 1 | E31: =IF(ISNUMBER(Calc!$L$40),Calc!$L$40,IF(Calc!$L$26=0,IF(AND(0=0,'Tag 3'!$P$7="HGC"),"CONTINUOUS",""),"NONE"))
B32: HINGE 2 | E32: =IF(ISNUMBER(Calc!$L$41),Calc!$L$41,IF(Calc!$L$26=0,IF(AND(1=0,'Tag 3'!$P$7="HGC"),"CONTINUOUS",""),"NONE")) | S32: DOOR ELEVATION
B33: HINGE 3 | E33: =IF(ISNUMBER(Calc!$L$42),Calc!$L$42,IF(Calc!$L$26=0,IF(AND(2=0,'Tag 3'!$P$7="HGC"),"CONTINUOUS",""),"NONE"))
B34: HINGE 4 | E34: =IF(ISNUMBER(Calc!$L$43),Calc!$L$43,IF(Calc!$L$26=0,IF(AND(3=0,'Tag 3'!$P$7="HGC"),"CONTINUOUS",""),"NONE")) | I34: SWING (plan) · JAMB PROFILE
B35: STRIKE 1 (E) | E35: =Calc!$L$46
B36: STRIKE 2 | E36: =Calc!$L$47
B38: OTHER MEASUREMENTS — FRAME
B39: ASA 4-7/8 TOP TO TOP | E39: =IF(ISNUMBER(Calc!$L$46),Calc!$L$46-2.4375,"")
B40: ASA 4-7/8 FTC (lock AFF) | E40: =Calc!$L$53
B41: DEADBOLT FTC | E41: =IF(ISNUMBER(Calc!$L$47),Calc!$L$2-Calc!$L$47,"")
B42: HAND / SWING | E42: =Calc!$L$87
B53: ORDER LINES
B54: FRAME | D54: =IF(Calc!$L$3,'Tag 3'!$W$4&") "&Calc!$L$64,"")
B55: DOOR | D55: =IF(Calc!$L$3,'Tag 3'!$W$4*Calc!$L$5&") "&Calc!$L$66,"")
...

Sheet Tag 4
B1: =CoName | R1: ="TAG "&IF('Tag 4'!$S$4="","4",'Tag 4'!$S$4)&" · QTY "&N('Tag 4'!$W$4)
B2: ="FRAME CALCULATOR · "&CoSpec1&" · "&CoSpec2 | R2: ="Printed "&TEXT(NOW(),"mm/dd/yyyy hh:mm")
B4: CUSTOMER | K4: P.O./JOB | R4: TAG # | S4: 4 | V4: QTY | W4: 1
B6: JAMB DEPTH | D6: FIRE RATING | F6: W FT | G6: W IN | H6: H FT | I6: H IN | J6: PAIR | K6: CONST. STYLE | M6: SWING | N6: ANCHOR | P6: HINGE | R6: STRIKE 1 | T6: STRIKE 2 | U6: LOCK 1 | W6: LOCK 2 | X6: LOCATIONS
B7: 534 | D7: NO LAB | F7: 6 | G7: 0 | H7: 7 | I7: 0 | J7: Y | K7: WELDED | M7: RHR | N7: SSA | P7: U453 | R7: G18 | U7: G2 | X7: STEELCRAFT
B8: ELEVATION | E8: WALL | G8: FRAME GA | H8: DOOR | J8: DOOR GA | K8: HEAD FACE | L8: JAMB FACE | M8: REV HINGE | N8: REV LOCK | O8: REV TOP | P8: UNDERCUT | Q8: MASONRY R.O. W | S8: MASONRY R.O. H | U8: TOL. EA SIDE | V8: LITE W | W8: LITE H | X8: LITE TOP
B9: FNV 6"x27" | E9: MASONRY | G9: 16 | H9: HM | J9: 18 | K9: 2 | L9: 2
B10: CUSTOM A | D10: CUSTOM B | F10: CUSTOM C | H10: CUSTOM D | J10: CUSTOM E | L10: HARDWARE NOTES
B13: FRAME SIZE INFO | I13: FRAME ELEVATION — locations from the top of the frame | S13: DOOR SIZE INFO
B14: INSIDE WIDTH | E14: =Calc!$Q$1 | S14: OPENING WIDTH | V14: =Calc!$Q$1
B15: INSIDE HEIGHT | E15: =Calc!$Q$2 | S15: OPENING HEIGHT | V15: =Calc!$Q$2
B16: OUTSIDE WIDTH | E16: =Calc!$Q$13 | S16: ACTUAL WIDTH | V16: =Calc!$Q$24
B17: OUTSIDE HEIGHT | E17: =Calc!$Q$14 | S17: ACTUAL HEIGHT | V17: =Calc!$Q$25
B18: HEADER FACE | E18: =Calc!$Q$12 | S18: REVEAL HINGE / LOCK / TOP | V18: =TRIM(TEXT(Calc!$Q$20,"# ?/??"))&CHAR(34)&" · "&TRIM(TEXT(Calc!$Q$21,"# ?/??"))&CHAR(34)&" · "&TRIM(TEXT(Calc!$Q$22,"# ?/??"))&CHAR(34)
B19: HINGE & STRIKE FACE | E19: =Calc!$Q$11 | S19: UNDERCUT | V19: =Calc!$Q$23
B20: JAMB DEPTH | E20: =Calc!$Q$7 | S20: LITE KIT | V20: =IF(Calc!$Q$59,Calc!$Q$86&" · top "&TRIM(TEXT(Calc!$Q$58,"# ?/??"))&CHAR(34),"FLUSH")
B21: FITS WALL (throat) | E21: =Calc!$Q$15
S22: HARDWARE LOCATIONS — DOOR (from top of door)
B23: ROUGH OPENING | S23: HINGE 1 | V23: =IF(ISNUMBER(Calc!$Q$40),Calc!$Q$40-Calc!$Q$22,IF(Calc!$Q$26=0,"","NONE"))
B24: DRYWALL W x H | E24: =TRIM(TEXT(Calc!$Q$16,"# ?/??"))&CHAR(34)&" x "&TRIM(TEXT(Calc!$Q$17,"# ?/??"))&CHAR(34) | S24: HINGE 2 | V24: =IF(ISNUMBER(Calc!$Q$41),Calc!$Q$41-Calc!$Q$22,IF(Calc!$Q$26=0,"","NONE"))
B25: MASONRY W x H | E25: =TRIM(TEXT(Calc!$Q$18,"# ?/??"))&CHAR(34)&" x "&TRIM(TEXT(Calc!$Q$19,"# ?/??"))&CHAR(34) | S25: HINGE 3 | V25: =IF(ISNUMBER(Calc!$Q$42),Calc!$Q$42-Calc!$Q$22,IF(Calc!$Q$26=0,"","NONE"))
B26: FACE CHECK | E26: =IF(OR(Calc!$Q$11<1,Calc!$Q$11>12,Calc!$Q$12<1,Calc!$Q$12>12),"ERROR — face out of range","OK") | S26: HINGE 4 | V26: =IF(ISNUMBER(Calc!$Q$43),Calc!$Q$43-Calc!$Q$22,IF(Calc!$Q$26=0,"","NONE"))
S27: LOCK 1 CYL CL | V27: =Calc!$Q$49
B28: HARDWARE LOCATIONS — FRAME | S28: LOCK 2 CYL CL | V28: =Calc!$Q$50
B29: MANUFACTURER | E29: ='Tag 4'!$X$7 | S29: TOP MORTISE LOCK | V29: =Calc!$Q$51
B30: CHART | E30: =IF(Calc!$Q$29,INT(ROUND(Calc!$Q$28,4)/12)&"'-"&IF(ROUND(MOD(Calc!$Q$28,12),4)=0,"0",TRIM(TEXT(MOD(Calc!$Q$28,12),"# ?/??")))&CHAR(34)&IF(Calc!$Q$36," cut down",IF(Calc!$Q$38," — NOT STOCK","")),IF(Calc!$Q$27,"CUSTOM","ANSI/SDI")) | S30: MORTISE TOP TO CL | V30: =Calc!$Q$52
B31: HINGE 1 | E31: =IF(ISNUMBER(Calc!$Q$40),Calc!$Q$40,IF(Calc!$Q$26=0,IF(AND(0=0,'Tag 4'!$P$7="HGC"),"CONTINUOUS",""),"NONE"))
B32: HINGE 2 | E32: =IF(ISNUMBER(Calc!$Q$41),Calc!$Q$41,IF(Calc!$Q$26=0,IF(AND(1=0,'Tag 4'!$P$7="HGC"),"CONTINUOUS",""),"NONE")) | S32: DOOR ELEVATION
B33: HINGE 3 | E33: =IF(ISNUMBER(Calc!$Q$42),Calc!$Q$42,IF(Calc!$Q$26=0,IF(AND(2=0,'Tag 4'!$P$7="HGC"),"CONTINUOUS",""),"NONE"))
B34: HINGE 4 | E34: =IF(ISNUMBER(Calc!$Q$43),Calc!$Q$43,IF(Calc!$Q$26=0,IF(AND(3=0,'Tag 4'!$P$7="HGC"),"CONTINUOUS",""),"NONE")) | I34: SWING (plan) · JAMB PROFILE
B35: STRIKE 1 (E) | E35: =Calc!$Q$46
B36: STRIKE 2 | E36: =Calc!$Q$47
B38: OTHER MEASUREMENTS — FRAME
B39: ASA 4-7/8 TOP TO TOP | E39: =IF(ISNUMBER(Calc!$Q$46),Calc!$Q$46-2.4375,"")
B40: ASA 4-7/8 FTC (lock AFF) | E40: =Calc!$Q$53
B41: DEADBOLT FTC | E41: =IF(ISNUMBER(Calc!$Q$47),Calc!$Q$2-Calc!$Q$47,"")
B42: HAND / SWING | E42: =Calc!$Q$87
B53: ORDER LINES
B54: FRAME | D54: =IF(Calc!$Q$3,'Tag 4'!$W$4&") "&Calc!$Q$64,"")
B55: DOOR | D55: =IF(Calc!$Q$3,'Tag 4'!$W$4*Calc!$Q$5&") "&Calc!$Q$66,"")
...

Sheet Tag 5
B1: =CoName | R1: ="TAG "&IF('Tag 5'!$S$4="","5",'Tag 5'!$S$4)&" · QTY "&N('Tag 5'!$W$4)
B2: ="FRAME CALCULATOR · "&CoSpec1&" · "&CoSpec2 | R2: ="Printed "&TEXT(NOW(),"mm/dd/yyyy hh:mm")
B4: CUSTOMER | K4: P.O./JOB | R4: TAG # | S4: 5 | V4: QTY | W4: 1
B6: JAMB DEPTH | D6: FIRE RATING | F6: W FT | G6: W IN | H6: H FT | I6: H IN | J6: PAIR | K6: CONST. STYLE | M6: SWING | N6: ANCHOR | P6: HINGE | R6: STRIKE 1 | T6: STRIKE 2 | U6: LOCK 1 | W6: LOCK 2 | X6: LOCATIONS
B7: 534 | D7: 60 MIN | F7: 3 | G7: 0 | H7: 8 | I7: 0 | K7: WELDED | M7: LHR | N7: SSA | P7: U454 | R7: E1 | U7: G3A | X7: CURRIES
B8: ELEVATION | E8: WALL | G8: FRAME GA | H8: DOOR | J8: DOOR GA | K8: HEAD FACE | L8: JAMB FACE | M8: REV HINGE | N8: REV LOCK | O8: REV TOP | P8: UNDERCUT | Q8: MASONRY R.O. W | S8: MASONRY R.O. H | U8: TOL. EA SIDE | V8: LITE W | W8: LITE H | X8: LITE TOP
B9: FG 24"x64" | E9: MASONRY | G9: 16 | H9: HM | J9: 18 | K9: 2 | L9: 2
B10: CUSTOM A | D10: CUSTOM B | F10: CUSTOM C | H10: CUSTOM D | J10: CUSTOM E | L10: HARDWARE NOTES
B13: FRAME SIZE INFO | I13: FRAME ELEVATION — locations from the top of the frame | S13: DOOR SIZE INFO
B14: INSIDE WIDTH | E14: =Calc!$V$1 | S14: OPENING WIDTH | V14: =Calc!$V$1
B15: INSIDE HEIGHT | E15: =Calc!$V$2 | S15: OPENING HEIGHT | V15: =Calc!$V$2
B16: OUTSIDE WIDTH | E16: =Calc!$V$13 | S16: ACTUAL WIDTH | V16: =Calc!$V$24
B17: OUTSIDE HEIGHT | E17: =Calc!$V$14 | S17: ACTUAL HEIGHT | V17: =Calc!$V$25
B18: HEADER FACE | E18: =Calc!$V$12 | S18: REVEAL HINGE / LOCK / TOP | V18: =TRIM(TEXT(Calc!$V$20,"# ?/??"))&CHAR(34)&" · "&TRIM(TEXT(Calc!$V$21,"# ?/??"))&CHAR(34)&" · "&TRIM(TEXT(Calc!$V$22,"# ?/??"))&CHAR(34)
B19: HINGE & STRIKE FACE | E19: =Calc!$V$11 | S19: UNDERCUT | V19: =Calc!$V$23
B20: JAMB DEPTH | E20: =Calc!$V$7 | S20: LITE KIT | V20: =IF(Calc!$V$59,Calc!$V$86&" · top "&TRIM(TEXT(Calc!$V$58,"# ?/??"))&CHAR(34),"FLUSH")
B21: FITS WALL (throat) | E21: =Calc!$V$15
S22: HARDWARE LOCATIONS — DOOR (from top of door)
B23: ROUGH OPENING | S23: HINGE 1 | V23: =IF(ISNUMBER(Calc!$V$40),Calc!$V$40-Calc!$V$22,IF(Calc!$V$26=0,"","NONE"))
B24: DRYWALL W x H | E24: =TRIM(TEXT(Calc!$V$16,"# ?/??"))&CHAR(34)&" x "&TRIM(TEXT(Calc!$V$17,"# ?/??"))&CHAR(34) | S24: HINGE 2 | V24: =IF(ISNUMBER(Calc!$V$41),Calc!$V$41-Calc!$V$22,IF(Calc!$V$26=0,"","NONE"))
B25: MASONRY W x H | E25: =TRIM(TEXT(Calc!$V$18,"# ?/??"))&CHAR(34)&" x "&TRIM(TEXT(Calc!$V$19,"# ?/??"))&CHAR(34) | S25: HINGE 3 | V25: =IF(ISNUMBER(Calc!$V$42),Calc!$V$42-Calc!$V$22,IF(Calc!$V$26=0,"","NONE"))
B26: FACE CHECK | E26: =IF(OR(Calc!$V$11<1,Calc!$V$11>12,Calc!$V$12<1,Calc!$V$12>12),"ERROR — face out of range","OK") | S26: HINGE 4 | V26: =IF(ISNUMBER(Calc!$V$43),Calc!$V$43-Calc!$V$22,IF(Calc!$V$26=0,"","NONE"))
S27: LOCK 1 CYL CL | V27: =Calc!$V$49
B28: HARDWARE LOCATIONS — FRAME | S28: LOCK 2 CYL CL | V28: =Calc!$V$50
B29: MANUFACTURER | E29: ='Tag 5'!$X$7 | S29: TOP MORTISE LOCK | V29: =Calc!$V$51
B30: CHART | E30: =IF(Calc!$V$29,INT(ROUND(Calc!$V$28,4)/12)&"'-"&IF(ROUND(MOD(Calc!$V$28,12),4)=0,"0",TRIM(TEXT(MOD(Calc!$V$28,12),"# ?/??")))&CHAR(34)&IF(Calc!$V$36," cut down",IF(Calc!$V$38," — NOT STOCK","")),IF(Calc!$V$27,"CUSTOM","ANSI/SDI")) | S30: MORTISE TOP TO CL | V30: =Calc!$V$52
B31: HINGE 1 | E31: =IF(ISNUMBER(Calc!$V$40),Calc!$V$40,IF(Calc!$V$26=0,IF(AND(0=0,'Tag 5'!$P$7="HGC"),"CONTINUOUS",""),"NONE"))
B32: HINGE 2 | E32: =IF(ISNUMBER(Calc!$V$41),Calc!$V$41,IF(Calc!$V$26=0,IF(AND(1=0,'Tag 5'!$P$7="HGC"),"CONTINUOUS",""),"NONE")) | S32: DOOR ELEVATION
B33: HINGE 3 | E33: =IF(ISNUMBER(Calc!$V$42),Calc!$V$42,IF(Calc!$V$26=0,IF(AND(2=0,'Tag 5'!$P$7="HGC"),"CONTINUOUS",""),"NONE"))
B34: HINGE 4 | E34: =IF(ISNUMBER(Calc!$V$43),Calc!$V$43,IF(Calc!$V$26=0,IF(AND(3=0,'Tag 5'!$P$7="HGC"),"CONTINUOUS",""),"NONE")) | I34: SWING (plan) · JAMB PROFILE
B35: STRIKE 1 (E) | E35: =Calc!$V$46
B36: STRIKE 2 | E36: =Calc!$V$47
B38: OTHER MEASUREMENTS — FRAME
B39: ASA 4-7/8 TOP TO TOP | E39: =IF(ISNUMBER(Calc!$V$46),Calc!$V$46-2.4375,"")
B40: ASA 4-7/8 FTC (lock AFF) | E40: =Calc!$V$53
B41: DEADBOLT FTC | E41: =IF(ISNUMBER(Calc!$V$47),Calc!$V$2-Calc!$V$47,"")
B42: HAND / SWING | E42: =Calc!$V$87
B53: ORDER LINES
B54: FRAME | D54: =IF(Calc!$V$3,'Tag 5'!$W$4&") "&Calc!$V$64,"")
B55: DOOR | D55: =IF(Calc!$V$3,'Tag 5'!$W$4*Calc!$V$5&") "&Calc!$V$66,"")
...

Sheet Tag 6
B1: =CoName | R1: ="TAG "&IF('Tag 6'!$S$4="","6",'Tag 6'!$S$4)&" · QTY "&N('Tag 6'!$W$4)
B2: ="FRAME CALCULATOR · "&CoSpec1&" · "&CoSpec2 | R2: ="Printed "&TEXT(NOW(),"mm/dd/yyyy hh:mm")
B4: CUSTOMER | K4: P.O./JOB | R4: TAG # | S4: 6 | V4: QTY | W4: 1
B6: JAMB DEPTH | D6: FIRE RATING | F6: W FT | G6: W IN | H6: H FT | I6: H IN | J6: PAIR | K6: CONST. STYLE | M6: SWING | N6: ANCHOR | P6: HINGE | R6: STRIKE 1 | T6: STRIKE 2 | U6: LOCK 1 | W6: LOCK 2 | X6: LOCATIONS
B7: 534 | D7: NO LAB | F7: 3 | G7: 0 | H7: 7 | I7: 0 | K7: KD-3PC | M7: LH | N7: COMP | P7: U453 | R7: E1 | U7: G2 | X7: CUSTOM
B8: ELEVATION | E8: WALL | G8: FRAME GA | H8: DOOR | J8: DOOR GA | K8: HEAD FACE | L8: JAMB FACE | M8: REV HINGE | N8: REV LOCK | O8: REV TOP | P8: UNDERCUT | Q8: MASONRY R.O. W | S8: MASONRY R.O. H | U8: TOL. EA SIDE | V8: LITE W | W8: LITE H | X8: LITE TOP
B9: FLUSH | E9: DRYWALL | G9: 16 | H9: HM | J9: 18 | K9: 2 | L9: 2
B10: CUSTOM A | D10: CUSTOM B | F10: CUSTOM C | H10: CUSTOM D | J10: CUSTOM E | L10: HARDWARE NOTES
B11: 6 | D11: 36 | F11: 66 | J11: 42
B13: FRAME SIZE INFO | I13: FRAME ELEVATION — locations from the top of the frame | S13: DOOR SIZE INFO
B14: INSIDE WIDTH | E14: =Calc!$AA$1 | S14: OPENING WIDTH | V14: =Calc!$AA$1
B15: INSIDE HEIGHT | E15: =Calc!$AA$2 | S15: OPENING HEIGHT | V15: =Calc!$AA$2
B16: OUTSIDE WIDTH | E16: =Calc!$AA$13 | S16: ACTUAL WIDTH | V16: =Calc!$AA$24
B17: OUTSIDE HEIGHT | E17: =Calc!$AA$14 | S17: ACTUAL HEIGHT | V17: =Calc!$AA$25
B18: HEADER FACE | E18: =Calc!$AA$12 | S18: REVEAL HINGE / LOCK / TOP | V18: =TRIM(TEXT(Calc!$AA$20,"# ?/??"))&CHAR(34)&" · "&TRIM(TEXT(Calc!$AA$21,"# ?/??"))&CHAR(34)&" · "&TRIM(TEXT(Calc!$AA$22,"# ?/??"))&CHAR(34)
B19: HINGE & STRIKE FACE | E19: =Calc!$AA$11 | S19: UNDERCUT | V19: =Calc!$AA$23
B20: JAMB DEPTH | E20: =Calc!$AA$7 | S20: LITE KIT | V20: =IF(Calc!$AA$59,Calc!$AA$86&" · top "&TRIM(TEXT(Calc!$AA$58,"# ?/??"))&CHAR(34),"FLUSH")
B21: FITS WALL (throat) | E21: =Calc!$AA$15
S22: HARDWARE LOCATIONS — DOOR (from top of door)
B23: ROUGH OPENING | S23: HINGE 1 | V23: =IF(ISNUMBER(Calc!$AA$40),Calc!$AA$40-Calc!$AA$22,IF(Calc!$AA$26=0,"","NONE"))
B24: DRYWALL W x H | E24: =TRIM(TEXT(Calc!$AA$16,"# ?/??"))&CHAR(34)&" x "&TRIM(TEXT(Calc!$AA$17,"# ?/??"))&CHAR(34) | S24: HINGE 2 | V24: =IF(ISNUMBER(Calc!$AA$41),Calc!$AA$41-Calc!$AA$22,IF(Calc!$AA$26=0,"","NONE"))
B25: MASONRY W x H | E25: =TRIM(TEXT(Calc!$AA$18,"# ?/??"))&CHAR(34)&" x "&TRIM(TEXT(Calc!$AA$19,"# ?/??"))&CHAR(34) | S25: HINGE 3 | V25: =IF(ISNUMBER(Calc!$AA$42),Calc!$AA$42-Calc!$AA$22,IF(Calc!$AA$26=0,"","NONE"))
B26: FACE CHECK | E26: =IF(OR(Calc!$AA$11<1,Calc!$AA$11>12,Calc!$AA$12<1,Calc!$AA$12>12),"ERROR — face out of range","OK") | S26: HINGE 4 | V26: =IF(ISNUMBER(Calc!$AA$43),Calc!$AA$43-Calc!$AA$22,IF(Calc!$AA$26=0,"","NONE"))
S27: LOCK 1 CYL CL | V27: =Calc!$AA$49
B28: HARDWARE LOCATIONS — FRAME | S28: LOCK 2 CYL CL | V28: =Calc!$AA$50
B29: MANUFACTURER | E29: ='Tag 6'!$X$7 | S29: TOP MORTISE LOCK | V29: =Calc!$AA$51
B30: CHART | E30: =IF(Calc!$AA$29,INT(ROUND(Calc!$AA$28,4)/12)&"'-"&IF(ROUND(MOD(Calc!$AA$28,12),4)=0,"0",TRIM(TEXT(MOD(Calc!$AA$28,12),"# ?/??")))&CHAR(34)&IF(Calc!$AA$36," cut down",IF(Calc!$AA$38," — NOT STOCK","")),IF(Calc!$AA$27,"CUSTOM","ANSI/SDI")) | S30: MORTISE TOP TO CL | V30: =Calc!$AA$52
B31: HINGE 1 | E31: =IF(ISNUMBER(Calc!$AA$40),Calc!$AA$40,IF(Calc!$AA$26=0,IF(AND(0=0,'Tag 6'!$P$7="HGC"),"CONTINUOUS",""),"NONE"))
B32: HINGE 2 | E32: =IF(ISNUMBER(Calc!$AA$41),Calc!$AA$41,IF(Calc!$AA$26=0,IF(AND(1=0,'Tag 6'!$P$7="HGC"),"CONTINUOUS",""),"NONE")) | S32: DOOR ELEVATION
B33: HINGE 3 | E33: =IF(ISNUMBER(Calc!$AA$42),Calc!$AA$42,IF(Calc!$AA$26=0,IF(AND(2=0,'Tag 6'!$P$7="HGC"),"CONTINUOUS",""),"NONE"))
B34: HINGE 4 | E34: =IF(ISNUMBER(Calc!$AA$43),Calc!$AA$43,IF(Calc!$AA$26=0,IF(AND(3=0,'Tag 6'!$P$7="HGC"),"CONTINUOUS",""),"NONE")) | I34: SWING (plan) · JAMB PROFILE
B35: STRIKE 1 (E) | E35: =Calc!$AA$46
B36: STRIKE 2 | E36: =Calc!$AA$47
B38: OTHER MEASUREMENTS — FRAME
B39: ASA 4-7/8 TOP TO TOP | E39: =IF(ISNUMBER(Calc!$AA$46),Calc!$AA$46-2.4375,"")
B40: ASA 4-7/8 FTC (lock AFF) | E40: =Calc!$AA$53
B41: DEADBOLT FTC | E41: =IF(ISNUMBER(Calc!$AA$47),Calc!$AA$2-Calc!$AA$47,"")
B42: HAND / SWING | E42: =Calc!$AA$87
B53: ORDER LINES
B54: FRAME | D54: =IF(Calc!$AA$3,'Tag 6'!$W$4&") "&Calc!$AA$64,"")
...

Sheet Tag List
B1: TAG LIST
B2: Every tag on one page, with its order lines — copy straight into the order.
A5: SHEET | B5: TAG | C5: QTY | D5: SIZE | E5: HAND | F5: FRAME ORDER LINE | G5: DOOR ORDER LINE | H5: OUTSIDE W x H | I5: DRYWALL R.O. | J5: HINGES (frame) | K5: E
A6: Tag 1 | B6: ='Tag 1'!$S$4&"" | C6: ='Tag 1'!$W$4 | D6: =Calc!$B$63 | E6: =Calc!$B$87 | F6: =Calc!$B$64 | G6: =Calc!$B$66 | H6: =TRIM(TEXT(Calc!$B$13,"# ?/??"))&CHAR(34)&" x "&TRIM(TEXT(Calc!$B$14,"# ?/??"))&CHAR(34) | I6: =TRIM(TEXT(Calc!$B$16,"# ?/??"))&CHAR(34)&" x "&TRIM(TEXT(Calc!$B$17,"# ?/??"))&CHAR(34) | J6: =IF(ISNUMBER(Calc!$B$40),TRIM(TEXT(Calc!$B$40,"# ?/??"))&CHAR(34),"")&" "&IF(ISNUMBER(Calc!$B$41),TRIM(TEXT(Calc!$B$41,"# ?/??"))&CHAR(34),"")&" "&IF(ISNUMBER(Calc!$B$42),TRIM(TEXT(Calc!$B$42,"# ?/??"))&CHAR(34),"")&" "&IF(ISNUMBER(Calc!$B$43),TRIM(TEXT(Calc!$B$43,"# ?/??"))&CHAR(34),"") | K6: =IF(ISNUMBER(Calc!$B$46),TRIM(TEXT(Calc!$B$46,"# ?/??"))&CHAR(34),"")
A7: Tag 2 | B7: ='Tag 2'!$S$4&"" | C7: ='Tag 2'!$W$4 | D7: =Calc!$G$63 | E7: =Calc!$G$87 | F7: =Calc!$G$64 | G7: =Calc!$G$66 | H7: =TRIM(TEXT(Calc!$G$13,"# ?/??"))&CHAR(34)&" x "&TRIM(TEXT(Calc!$G$14,"# ?/??"))&CHAR(34) | I7: =TRIM(TEXT(Calc!$G$16,"# ?/??"))&CHAR(34)&" x "&TRIM(TEXT(Calc!$G$17,"# ?/??"))&CHAR(34) | J7: =IF(ISNUMBER(Calc!$G$40),TRIM(TEXT(Calc!$G$40,"# ?/??"))&CHAR(34),"")&" "&IF(ISNUMBER(Calc!$G$41),TRIM(TEXT(Calc!$G$41,"# ?/??"))&CHAR(34),"")&" "&IF(ISNUMBER(Calc!$G$42),TRIM(TEXT(Calc!$G$42,"# ?/??"))&CHAR(34),"")&" "&IF(ISNUMBER(Calc!$G$43),TRIM(TEXT(Calc!$G$43,"# ?/??"))&CHAR(34),"") | K7: =IF(ISNUMBER(Calc!$G$46),TRIM(TEXT(Calc!$G$46,"# ?/??"))&CHAR(34),"")
A8: Tag 3 | B8: ='Tag 3'!$S$4&"" | C8: ='Tag 3'!$W$4 | D8: =Calc!$L$63 | E8: =Calc!$L$87 | F8: =Calc!$L$64 | G8: =Calc!$L$66 | H8: =TRIM(TEXT(Calc!$L$13,"# ?/??"))&CHAR(34)&" x "&TRIM(TEXT(Calc!$L$14,"# ?/??"))&CHAR(34) | I8: =TRIM(TEXT(Calc!$L$16,"# ?/??"))&CHAR(34)&" x "&TRIM(TEXT(Calc!$L$17,"# ?/??"))&CHAR(34) | J8: =IF(ISNUMBER(Calc!$L$40),TRIM(TEXT(Calc!$L$40,"# ?/??"))&CHAR(34),"")&" "&IF(ISNUMBER(Calc!$L$41),TRIM(TEXT(Calc!$L$41,"# ?/??"))&CHAR(34),"")&" "&IF(ISNUMBER(Calc!$L$42),TRIM(TEXT(Calc!$L$42,"# ?/??"))&CHAR(34),"")&" "&IF(ISNUMBER(Calc!$L$43),TRIM(TEXT(Calc!$L$43,"# ?/??"))&CHAR(34),"") | K8: =IF(ISNUMBER(Calc!$L$46),TRIM(TEXT(Calc!$L$46,"# ?/??"))&CHAR(34),"")
A9: Tag 4 | B9: ='Tag 4'!$S$4&"" | C9: ='Tag 4'!$W$4 | D9: =Calc!$Q$63 | E9: =Calc!$Q$87 | F9: =Calc!$Q$64 | G9: =Calc!$Q$66 | H9: =TRIM(TEXT(Calc!$Q$13,"# ?/??"))&CHAR(34)&" x "&TRIM(TEXT(Calc!$Q$14,"# ?/??"))&CHAR(34) | I9: =TRIM(TEXT(Calc!$Q$16,"# ?/??"))&CHAR(34)&" x "&TRIM(TEXT(Calc!$Q$17,"# ?/??"))&CHAR(34) | J9: =IF(ISNUMBER(Calc!$Q$40),TRIM(TEXT(Calc!$Q$40,"# ?/??"))&CHAR(34),"")&" "&IF(ISNUMBER(Calc!$Q$41),TRIM(TEXT(Calc!$Q$41,"# ?/??"))&CHAR(34),"")&" "&IF(ISNUMBER(Calc!$Q$42),TRIM(TEXT(Calc!$Q$42,"# ?/??"))&CHAR(34),"")&" "&IF(ISNUMBER(Calc!$Q$43),TRIM(TEXT(Calc!$Q$43,"# ?/??"))&CHAR(34),"") | K9: =IF(ISNUMBER(Calc!$Q$46),TRIM(TEXT(Calc!$Q$46,"# ?/??"))&CHAR(34),"")
A10: Tag 5 | B10: ='Tag 5'!$S$4&"" | C10: ='Tag 5'!$W$4 | D10: =Calc!$V$63 | E10: =Calc!$V$87 | F10: =Calc!$V$64 | G10: =Calc!$V$66 | H10: =TRIM(TEXT(Calc!$V$13,"# ?/??"))&CHAR(34)&" x "&TRIM(TEXT(Calc!$V$14,"# ?/??"))&CHAR(34) | I10: =TRIM(TEXT(Calc!$V$16,"# ?/??"))&CHAR(34)&" x "&TRIM(TEXT(Calc!$V$17,"# ?/??"))&CHAR(34) | J10: =IF(ISNUMBER(Calc!$V$40),TRIM(TEXT(Calc!$V$40,"# ?/??"))&CHAR(34),"")&" "&IF(ISNUMBER(Calc!$V$41),TRIM(TEXT(Calc!$V$41,"# ?/??"))&CHAR(34),"")&" "&IF(ISNUMBER(Calc!$V$42),TRIM(TEXT(Calc!$V$42,"# ?/??"))&CHAR(34),"")&" "&IF(ISNUMBER(Calc!$V$43),TRIM(TEXT(Calc!$V$43,"# ?/??"))&CHAR(34),"") | K10: =IF(ISNUMBER(Calc!$V$46),TRIM(TEXT(Calc!$V$46,"# ?/??"))&CHAR(34),"")
A11: Tag 6 | B11: ='Tag 6'!$S$4&"" | C11: ='Tag 6'!$W$4 | D11: =Calc!$AA$63 | E11: =Calc!$AA$87 | F11: =Calc!$AA$64 | G11: =Calc!$AA$66 | H11: =TRIM(TEXT(Calc!$AA$13,"# ?/??"))&CHAR(34)&" x "&TRIM(TEXT(Calc!$AA$14,"# ?/??"))&CHAR(34) | I11: =TRIM(TEXT(Calc!$AA$16,"# ?/??"))&CHAR(34)&" x "&TRIM(TEXT(Calc!$AA$17,"# ?/??"))&CHAR(34) | J11: =IF(ISNUMBER(Calc!$AA$40),TRIM(TEXT(Calc!$AA$40,"# ?/??"))&CHAR(34),"")&" "&IF(ISNUMBER(Calc!$AA$41),TRIM(TEXT(Calc!$AA$41,"# ?/??"))&CHAR(34),"")&" "&IF(ISNUMBER(Calc!$AA$42),TRIM(TEXT(Calc!$AA$42,"# ?/??"))&CHAR(34),"")&" "&IF(ISNUMBER(Calc!$AA$43),TRIM(TEXT(Calc!$AA$43,"# ?/??"))&CHAR(34),"") | K11: =IF(ISNUMBER(Calc!$AA$46),TRIM(TEXT(Calc!$AA$46,"# ?/??"))&CHAR(34),"")

Sheet Rough Opening
B1: ROUGH OPENING → FRAME
B2: Field measured an opening? Type the rough opening and the frame you want: faces, outside size and the door come out.
B5: TYPE
B6: ROUGH OPENING WIDTH | C6: 40.625
B7: ROUGH OPENING HEIGHT | C7: 86.5
B8: NOMINAL FRAME WIDTH | C8: 36
B9: NOMINAL FRAME HEIGHT | C9: 84
B10: TOLERANCE EACH SIDE | C10: 0
B12: RESULT
B13: HEADER FACE | C13: =C7-C9-C10
B14: HINGE & STRIKE FACE | C14: =(C6-C8)/2-C10
B15: FRAME OUTSIDE WIDTH | C15: =C8+2*C14-0.25
B16: FRAME OUTSIDE HEIGHT | C16: =C9+C13
B17: NET DOOR WIDTH | C17: =C8-0.25
B18: NET DOOR HEIGHT | C18: =C9-0.75
B19: LARGEST STANDARD FRAME WITH 2" FACES | C19: =FLOOR((C6-4-2*C10),2)&" x "&FLOOR((C7-2-C10),1)
B20: CHECK | C20: =IF(OR(C13<1,C13>12,C14<1,C14>12),"Face out of range (1–12): pick another frame size","OK")
B23: Same rule as the 2.0 Frame Calc sheet: header face = R.O. height − frame height; jamb face = (R.O. width − frame width) / 2; outside width less 1/4".

Sheet Bi-Pass
B1: BI-PASS DOOR SIZE — WOOD DOORS
B2: 1" overlap at the centre, 2-7/8" for track and hangers. Type the opening in inches.
B5: NOMINAL FRAME WIDTH | C5: 60
B6: NOMINAL FRAME HEIGHT | C6: 80
B7: LEAVES | C7: 2
B8: CENTRE OVERLAP (each) | C8: 1
B9: TRACK & HANGER CLEARANCE | C9: 2.875
B11: EACH LEAF WIDTH | C11: =C5/C7+C8/2*(C7-1)/(C7/2)
B12: EACH LEAF HEIGHT | C12: =C6-C9
B13: ORDER | C13: =C7&" LEAVES "&TRIM(TEXT(C11,"# ?/??"))&CHAR(34)&" x "&TRIM(TEXT(C12,"# ?/??"))&CHAR(34)
B15: Two leaves: width / 2 + 1/2" (the 2.0 rule). More leaves share the overlaps.

Sheet Locations
B1: MANUFACTURER LOCATIONS
B2: Frame: top inside of frame to the TOP of each hinge; E = strike centre line. Door = frame less 1/8". Edit to suit a maker.
B5: KEY | C5: MAKER | D5: CHART HT | E5: A | F5: B | G5: C | H5: D | I5: E | J5: LEAST NOMINAL (cut-down)
B6: CURRIES|80 | C6: CURRIES | D6: 80 | E6: 5 | F6: 35.25 | G6: 65.5 | I6: 40 | J6: =IF(F6="","",IF(H6<>"",H6,G6)+4.5+MinRail+0.75)
B7: CURRIES|84 | C7: CURRIES | D7: 84 | E7: 5 | F7: 37.25 | G7: 69.5 | I7: 44 | J7: =IF(F7="","",IF(H7<>"",H7,G7)+4.5+MinRail+0.75)
B8: CURRIES|96 | C8: CURRIES | D8: 96 | E8: 5 | F8: 30.5 | G8: 56 | H8: 81.5 | I8: 56 | J8: =IF(F8="","",IF(H8<>"",H8,G8)+4.5+MinRail+0.75)
B9: STEELCRAFT|80 | C9: STEELCRAFT | D9: 80 | E9: 7.5 | F9: 37.4375 | G9: 67.375 | I9: 39.6875 | J9: =IF(F9="","",IF(H9<>"",H9,G9)+4.5+MinRail+0.75)
B10: STEELCRAFT|84 | C10: STEELCRAFT | D10: 84 | E10: 7.5 | F10: 39.4375 | G10: 71.375 | I10: 43.6875 | J10: =IF(F10="","",IF(H10<>"",H10,G10)+4.5+MinRail+0.75)
B11: STEELCRAFT|96 | C11: STEELCRAFT | D11: 96 | E11: 7.5 | F11: 32.78125 | G11: 58.0625 | H11: 83.375 | I11: 55.6875 | J11: =IF(F11="","",IF(H11<>"",H11,G11)+4.5+MinRail+0.75)
B12: AMWELD|80 | C12: AMWELD | D12: 80 | E12: 7.5 | F12: 37.4375 | G12: 67.375 | I12: 39.6875 | J12: =IF(F12="","",IF(H12<>"",H12,G12)+4.5+MinRail+0.75)
B13: AMWELD|84 | C13: AMWELD | D13: 84 | E13: 7.5 | F13: 39.4375 | G13: 71.375 | I13: 43.6875 | J13: =IF(F13="","",IF(H13<>"",H13,G13)+4.5+MinRail+0.75)
B14: AMWELD|96 | C14: AMWELD | D14: 96 | E14: 7.5 | F14: 32.8125 | G14: 58.125 | H14: 83.4375 | I14: 55.6875 | J14: =IF(F14="","",IF(H14<>"",H14,G14)+4.5+MinRail+0.75)
B15: CECO|80 | C15: CECO | D15: 80 | E15: 6.75 | F15: 37.75 | G15: 68.75 | I15: 38.1875 | J15: =IF(F15="","",IF(H15<>"",H15,G15)+4.5+MinRail+0.75)
B16: CECO|84 | C16: CECO | D16: 84 | E16: 6.75 | F16: 39.75 | G16: 72.75 | I16: 42.1875 | J16: =IF(F16="","",IF(H16<>"",H16,G16)+4.5+MinRail+0.75)
B17: CECO|96 | C17: CECO | D17: 96 | E17: 6.75 | F17: 32.75 | G17: 58.75 | H17: 84.75 | I17: 54.1875 | J17: =IF(F17="","",IF(H17<>"",H17,G17)+4.5+MinRail+0.75)
B18: FENESTRA|80 | C18: FENESTRA | D18: 80 | E18: 5.25 | F18: 35.25 | G18: 65.25 | I18: 39.6875 | J18: =IF(F18="","",IF(H18<>"",H18,G18)+4.5+MinRail+0.75)
B19: FENESTRA|84 | C19: FENESTRA | D19: 84 | E19: 5.25 | F19: 37.25 | G19: 69.25 | I19: 43.6875 | J19: =IF(F19="","",IF(H19<>"",H19,G19)+4.5+MinRail+0.75)
B20: FENESTRA|96 | C20: FENESTRA | D20: 96 | E20: 5.25 | F20: 30.625 | G20: 55.9375 | H20: 81.25 | I20: 55.6875 | J20: =IF(F20="","",IF(H20<>"",H20,G20)+4.5+MinRail+0.75)
B21: KEWANEE|80 | C21: KEWANEE | D21: 80 | E21: 7.375 | F21: 37.4375 | G21: 67.5 | I21: 39.6875 | J21: =IF(F21="","",IF(H21<>"",H21,G21)+4.5+MinRail+0.75)
B22: KEWANEE|84 | C22: KEWANEE | D22: 84 | E22: 7.375 | F22: 39.4375 | G22: 71.5 | I22: 43.6875 | J22: =IF(F22="","",IF(H22<>"",H22,G22)+4.5+MinRail+0.75)
B23: KEWANEE|96 | C23: KEWANEE | D23: 96 | E23: 7.375 | F23: 32.75 | G23: 58.125 | H23: 83.5 | I23: 55.6875 | J23: =IF(F23="","",IF(H23<>"",H23,G23)+4.5+MinRail+0.75)
B24: MESKER|80 | C24: MESKER | D24: 80 | E24: 5 | F24: 35.25 | G24: 65.5 | I24: 39.6875 | J24: =IF(F24="","",IF(H24<>"",H24,G24)+4.5+MinRail+0.75)
B25: MESKER|84 | C25: MESKER | D25: 84 | E25: 5 | F25: 37.25 | G25: 69.5 | I25: 43.6875 | J25: =IF(F25="","",IF(H25<>"",H25,G25)+4.5+MinRail+0.75)
B26: MESKER|96 | C26: MESKER | D26: 96 | E26: 5 | F26: 30.5 | G26: 56 | H26: 81.5 | I26: 55.6875 | J26: =IF(F26="","",IF(H26<>"",H26,G26)+4.5+MinRail+0.75)
B27: PIONEER|80 | C27: PIONEER | D27: 80 | E27: 5 | F27: 35.25 | G27: 65.5 | I27: 42 | J27: =IF(F27="","",IF(H27<>"",H27,G27)+4.5+MinRail+0.75)
B28: PIONEER|84 | C28: PIONEER | D28: 84 | E28: 5 | F28: 37.25 | G28: 69.5 | I28: 46 | J28: =IF(F28="","",IF(H28<>"",H28,G28)+4.5+MinRail+0.75)
B29: PIONEER|96 | C29: PIONEER | D29: 96 | E29: 5 | F29: 30.5 | G29: 56 | H29: 81.5 | I29: 58 | J29: =IF(F29="","",IF(H29<>"",H29,G29)+4.5+MinRail+0.75)
B30: REPUBLIC|80 | C30: REPUBLIC | D30: 80 | E30: 7.5 | F30: 37.4375 | G30: 67.375 | I30: 39.6875 | J30: =IF(F30="","",IF(H30<>"",H30,G30)+4.5+MinRail+0.75)
B31: REPUBLIC|84 | C31: REPUBLIC | D31: 84 | E31: 9.5 | F31: 39.4375 | G31: 69.375 | I31: 43.6875 | J31: =IF(F31="","",IF(H31<>"",H31,G31)+4.5+MinRail+0.75)
B32: REPUBLIC|96 | C32: REPUBLIC | D32: 96 | E32: 5 | F32: 30.5 | G32: 56 | H32: 81.5 | I32: 55.6875 | J32: =IF(F32="","",IF(H32<>"",H32,G32)+4.5+MinRail+0.75)
B34: Their 2.0 rule kept: an opening shorter than a chart height takes that chart cut down from the bottom (6'-5" uses the 6'-8" row), as long as the rail under the bottom hinge stays 2-1/8". Shorter than LEAST NOMINAL = not stock: locations are re-spaced and flagged.

Sheet Lists
A1: L_Fire | B1: L_Style | C1: L_Swing | D1: L_Anchor | E1: L_Hinge | F1: L_Strike1 | G1: L_Strike2 | H1: L_Lock1 | I1: L_Lock2 | J1: L_Mfr | K1: L_Elev | L1: L_Wall | M1: L_Mat | N1: L_YN | O1: L_Gauge | P1: L_Face | Q1: L_WFt | R1: L_HFt | S1: L_In | U1: JAMB CODE | V1: INCHES | W1: PRINTS AS | Y1: CODE | Z1: PRINTS AS
A2: NO LAB | B2: KD-3PC | C2: LH | D2: COMP | E2: U453 | F2: E1 | G2: E4 | H2: G2 | I2: G2 | J2: CURRIES | K2: FLUSH | L2: DRYWALL | M2: HM | N2: Y | O2: 16 | P2: 2 | Q2: 0 | R2: 4 | S2: 0 | U2: 3 | V2: 3 | W2: 3" | Y2: LH | Z2: LH
A3: 20 MIN | B3: WELDED | C3: RH | D3: P/D+D.BOLT | E3: U454 | F3: E1E4 | G3: E3 | H3: G2G2 | I3: G16 | J3: STEELCRAFT | K3: FNV 5"x20" | L3: MASONRY | M3: WOOD | O3: 14 | P3: 4 | Q3: 1 | R3: 5 | S3: 1 | U3: 318 | V3: 3.125 | W3: 3-1/8" | Y3: RH | Z3: RH
A4: 45 MIN | C4: LHR | D4: P/D+W.SCREW | E4: HGC | F4: E8 | H4: G2A | I4: G17 | J4: AMWELD | K4: FNV 6"x27" | O4: 18 | Q4: 2 | R4: 6 | S4: 2 | U4: 314 | V4: 3.25 | W4: 3-1/4" | Y4: LHR | Z4: LHR
A5: 60 MIN | C5: RHR | D5: P/D-ONLY | E5: U453-EH | F5: E9 | H5: G3A | J5: CECO | K5: FNV 7"x22" | Q5: 3 | R5: 7 | S5: 3 | U5: 338 | V5: 3.375 | W5: 3-3/8" | Y5: RHR | Z5: RHR
A6: 90 MIN | C6: NH | D6: SSA | E6: U454-EH | F6: RL | H6: G3AEO | J6: FENESTRA | K6: FV 12"x12" | Q6: 4 | R6: 8 | S6: 4 | U6: 312 | V6: 3.5 | W6: 3-1/2" | Y6: NH
A7: 180 MIN | D7: T-MAS | E7: BLANK | F7: G18 | H7: G11 | J7: KEWANEE | K7: HG 24"x24" | R7: 9 | S7: 5 | U7: 358 | V7: 3.625 | W7: 3-5/8" | Y7: KD-3PC | Z7: KD
D8: WMA | H8: G11A | J8: MESKER | K8: HG 24"x30" | S8: 6 | U8: 334 | V8: 3.75 | W8: 3-3/4" | Y8: WELDED | Z8: WELDED
D9: NO ANCHORS | H9: G12 | J9: PIONEER | K9: HG 24"x36" | S9: 7 | U9: 378 | V9: 3.875 | W9: 3-7/8" | Y9: COMP | Z9: COMP
H10: G12A | J10: REPUBLIC | K10: FG 24"x60" | S10: 8 | U10: 4 | V10: 4 | W10: 4" | Y10: P/D+D.BOLT | Z10: P/D+DYNABOLTS
H11: G18 | J11: ANSI/SDI | K11: FG 24"x64" | S11: 9 | U11: 418 | V11: 4.125 | W11: 4-1/8" | Y11: P/D+W.SCREW | Z11: P/D+WOODSCREWS
J12: CUSTOM | K12: FG 22"x60" (WD) | S12: 10 | U12: 414 | V12: 4.25 | W12: 4-1/4" | Y12: P/D-ONLY | Z12: P/D-ONLY
K13: FG 22"x64" (WD) | S13: 11 | U13: 438 | V13: 4.375 | W13: 4-3/8" | Y13: SSA | Z13: SSA
K14: FL 12"x12" | U14: 412 | V14: 4.5 | W14: 4-1/2" | Y14: T-MAS | Z14: T-MAS
K15: FL 18"x12" | U15: 458 | V15: 4.625 | W15: 4-5/8" | Y15: WMA | Z15: WIRE.MAS
K16: FL 24"x12" | U16: 434 | V16: 4.75 | W16: 4-3/4" | Y16: NO ANCHORS
K17: FL 24"x24" | U17: 478 | V17: 4.875 | W17: 4-7/8" | Y17: U453 | Z17: 3-HNG
K18: 1/2" VIEWER | U18: 5 | V18: 5 | W18: 5" | Y18: U454 | Z18: 4-HNG
K19: 9/16" VIEWER | U19: 518 | V19: 5.125 | W19: 5-1/8" | Y19: HGC | Z19: CONT.HNG
K20: CUSTOM LITE | U20: 514 | V20: 5.25 | W20: 5-1/4" | Y20: U453-EH | Z20: 3-HNG 1-ELEC.HNG
U21: 538 | V21: 5.375 | W21: 5-3/8" | Y21: U454-EH | Z21: 4-HNG 1-ELEC.HNG
U22: 512 | V22: 5.5 | W22: 5-1/2" | Y22: BLANK | Z22: BLANK.HNG
U23: 558 | V23: 5.625 | W23: 5-5/8" | Y23: E1 | Z23: 1-478.STK
U24: 534 | V24: 5.75 | W24: 5-3/4" | Y24: E1E4 | Z24: 1-478.STK&DB.STK
U25: 578 | V25: 5.875 | W25: 5-7/8" | Y25: E8 | Z25: 1-RIM
U26: 6 | V26: 6 | W26: 6" | Y26: E9 | Z26: 1-ELEC
U27: 618 | V27: 6.125 | W27: 6-1/8" | Y27: RL | Z27: R.LATCH
U28: 614 | V28: 6.25 | W28: 6-1/4" | Y28: G18 | Z28: BLANK
U29: 638 | V29: 6.375 | W29: 6-3/8" | Y29: E4 | Z29: 1-DB.STK
U30: 612 | V30: 6.5 | W30: 6-1/2" | Y30: E3 | Z30: 1-DB.STR234
U31: 658 | V31: 6.625 | W31: 6-5/8" | Y31: G2 | Z31: CYL.161
U32: 634 | V32: 6.75 | W32: 6-3/4" | Y32: G2G2 | Z32: CYL.161&D.BOLT
... U47: 858 | V47: 8.625 | W47: 8-5/8" | Y47: 180 MIN | Z47: 180 MIN
U48: 834 | V48: 8.75 | W48: 8-3/4"
U49: 878 | V49: 8.875 | W49: 8-7/8"
U50: 9 | V50: 9 | W50: 9"
U51: 918 | V51: 9.125 | W51: 9-1/8"
U52: 914 | V52: 9.25 | W52: 9-1/4"
U53: 938 | V53: 9.375 | W53: 9-3/8"
U54: 912 | V54: 9.5 | W54: 9-1/2"
...

Sheet Calc
A1: W | B1: =N('Tag 1'!$F$7)*12+N('Tag 1'!$G$7) | F1: W | G1: =N('Tag 2'!$F$7)*12+N('Tag 2'!$G$7) | K1: W | L1: =N('Tag 3'!$F$7)*12+N('Tag 3'!$G$7) | P1: W | Q1: =N('Tag 4'!$F$7)*12+N('Tag 4'!$G$7) | U1: W | V1: =N('Tag 5'!$F$7)*12+N('Tag 5'!$G$7) | Z1: W | AA1: =N('Tag 6'!$F$7)*12+N('Tag 6'!$G$7)
A2: H | B2: =N('Tag 1'!$H$7)*12+N('Tag 1'!$I$7) | F2: H | G2: =N('Tag 2'!$H$7)*12+N('Tag 2'!$I$7) | K2: H | L2: =N('Tag 3'!$H$7)*12+N('Tag 3'!$I$7) | P2: H | Q2: =N('Tag 4'!$H$7)*12+N('Tag 4'!$I$7) | U2: H | V2: =N('Tag 5'!$H$7)*12+N('Tag 5'!$I$7) | Z2: H | AA2: =N('Tag 6'!$H$7)*12+N('Tag 6'!$I$7)
A3: ok | B3: =AND(Calc!$B$1>0,Calc!$B$2>0) | F3: ok | G3: =AND(Calc!$G$1>0,Calc!$G$2>0) | K3: ok | L3: =AND(Calc!$L$1>0,Calc!$L$2>0) | P3: ok | Q3: =AND(Calc!$Q$1>0,Calc!$Q$2>0) | U3: ok | V3: =AND(Calc!$V$1>0,Calc!$V$2>0) | Z3: ok | AA3: =AND(Calc!$AA$1>0,Calc!$AA$2>0)
A4: pair | B4: ='Tag 1'!$J$7="Y" | F4: pair | G4: ='Tag 2'!$J$7="Y" | K4: pair | L4: ='Tag 3'!$J$7="Y" | P4: pair | Q4: ='Tag 4'!$J$7="Y" | U4: pair | V4: ='Tag 5'!$J$7="Y" | Z4: pair | AA4: ='Tag 6'!$J$7="Y"
A5: nl | B5: =IF(Calc!$B$4,2,1) | F5: nl | G5: =IF(Calc!$G$4,2,1) | K5: nl | L5: =IF(Calc!$L$4,2,1) | P5: nl | Q5: =IF(Calc!$Q$4,2,1) | U5: nl | V5: =IF(Calc!$V$4,2,1) | Z5: nl | AA5: =IF(Calc!$AA$4,2,1)
A6: JD | B6: =IFERROR(VLOOKUP('Tag 1'!$B$7,T_Jamb,2,FALSE),5.75) | F6: JD | G6: =IFERROR(VLOOKUP('Tag 2'!$B$7,T_Jamb,2,FALSE),5.75) | K6: JD | L6: =IFERROR(VLOOKUP('Tag 3'!$B$7,T_Jamb,2,FALSE),5.75) | P6: JD | Q6: =IFERROR(VLOOKUP('Tag 4'!$B$7,T_Jamb,2,FALSE),5.75) | U6: JD | V6: =IFERROR(VLOOKUP('Tag 5'!$B$7,T_Jamb,2,FALSE),5.75) | Z6: JD | AA6: =IFERROR(VLOOKUP('Tag 6'!$B$7,T_Jamb,2,FALSE),5.75)
A7: JDT | B7: =IFERROR(VLOOKUP('Tag 1'!$B$7,T_Jamb,3,FALSE),"") | F7: JDT | G7: =IFERROR(VLOOKUP('Tag 2'!$B$7,T_Jamb,3,FALSE),"") | K7: JDT | L7: =IFERROR(VLOOKUP('Tag 3'!$B$7,T_Jamb,3,FALSE),"") | P7: JDT | Q7: =IFERROR(VLOOKUP('Tag 4'!$B$7,T_Jamb,3,FALSE),"") | U7: JDT | V7: =IFERROR(VLOOKUP('Tag 5'!$B$7,T_Jamb,3,FALSE),"") | Z7: JDT | AA7: =IFERROR(VLOOKUP('Tag 6'!$B$7,T_Jamb,3,FALSE),"")
A8: mas | B8: ='Tag 1'!$E$9="MASONRY" | F8: mas | G8: ='Tag 2'!$E$9="MASONRY" | K8: mas | L8: ='Tag 3'!$E$9="MASONRY" | P8: mas | Q8: ='Tag 4'!$E$9="MASONRY" | U8: mas | V8: ='Tag 5'!$E$9="MASONRY" | Z8: mas | AA8: ='Tag 6'!$E$9="MASONRY"
A9: weld | B9: ='Tag 1'!$K$7="WELDED" | F9: weld | G9: ='Tag 2'!$K$7="WELDED" | K9: weld | L9: ='Tag 3'!$K$7="WELDED" | P9: weld | Q9: ='Tag 4'!$K$7="WELDED" | U9: weld | V9: ='Tag 5'!$K$7="WELDED" | Z9: weld | AA9: ='Tag 6'!$K$7="WELDED"
A10: tol | B10: =IF(N('Tag 1'!$U$9)>0,'Tag 1'!$U$9,ROTolDef) | F10: tol | G10: =IF(N('Tag 2'!$U$9)>0,'Tag 2'!$U$9,ROTolDef) | K10: tol | L10: =IF(N('Tag 3'!$U$9)>0,'Tag 3'!$U$9,ROTolDef) | P10: tol | Q10: =IF(N('Tag 4'!$U$9)>0,'Tag 4'!$U$9,ROTolDef) | U10: tol | V10: =IF(N('Tag 5'!$U$9)>0,'Tag 5'!$U$9,ROTolDef) | Z10: tol | AA10: =IF(N('Tag 6'!$U$9)>0,'Tag 6'!$U$9,ROTolDef)
A11: jf | B11: =IF(AND(Calc!$B$8,N('Tag 1'!$Q$9)>0),(('Tag 1'!$Q$9-Calc!$B$1)-2*Calc!$B$10)/2,IF(N('Tag 1'!$L$9)>0,'Tag 1'!$L$9,2)) | F11: jf | G11: =IF(AND(Calc!$G$8,N('Tag 2'!$Q$9)>0),(('Tag 2'!$Q$9-Calc!$G$1)-2*Calc!$G$10)/2,IF(N('Tag 2'!$L$9)>0,'Tag 2'!$L$9,2)) | K11: jf | L11: =IF(AND(Calc!$L$8,N('Tag 3'!$Q$9)>0),(('Tag 3'!$Q$9-Calc!$L$1)-2*Calc!$L$10)/2,IF(N('Tag 3'!$L$9)>0,'Tag 3'!$L$9,2)) | P11: jf | Q11: =IF(AND(Calc!$Q$8,N('Tag 4'!$Q$9)>0),(('Tag 4'!$Q$9-Calc!$Q$1)-2*Calc!$Q$10)/2,IF(N('Tag 4'!$L$9)>0,'Tag 4'!$L$9,2)) | U11: jf | V11: =IF(AND(Calc!$V$8,N('Tag 5'!$Q$9)>0),(('Tag 5'!$Q$9-Calc!$V$1)-2*Calc!$V$10)/2,IF(N('Tag 5'!$L$9)>0,'Tag 5'!$L$9,2)) | Z11: jf | AA11: =IF(AND(Calc!$AA$8,N('Tag 6'!$Q$9)>0),(('Tag 6'!$Q$9-Calc!$AA$1)-2*Calc!$AA$10)/2,IF(N('Tag 6'!$L$9)>0,'Tag 6'!$L$9,2))
A12: hf | B12: =IF(AND(Calc!$B$8,N('Tag 1'!$S$9)>0),'Tag 1'!$S$9-Calc!$B$2-Calc!$B$10,IF(N('Tag 1'!$K$9)>0,'Tag 1'!$K$9,2)) | F12: hf | G12: =IF(AND(Calc!$G$8,N('Tag 2'!$S$9)>0),'Tag 2'!$S$9-Calc!$G$2-Calc!$G$10,IF(N('Tag 2'!$K$9)>0,'Tag 2'!$K$9,2)) | K12: hf | L12: =IF(AND(Calc!$L$8,N('Tag 3'!$S$9)>0),'Tag 3'!$S$9-Calc!$L$2-Calc!$L$10,IF(N('Tag 3'!$K$9)>0,'Tag 3'!$K$9,2)) | P12: hf | Q12: =IF(AND(Calc!$Q$8,N('Tag 4'!$S$9)>0),'Tag 4'!$S$9-Calc!$Q$2-Calc!$Q$10,IF(N('Tag 4'!$K$9)>0,'Tag 4'!$K$9,2)) | U12: hf | V12: =IF(AND(Calc!$V$8,N('Tag 5'!$S$9)>0),'Tag 5'!$S$9-Calc!$V$2-Calc!$V$10,IF(N('Tag 5'!$K$9)>0,'Tag 5'!$K$9,2)) | Z12: hf | AA12: =IF(AND(Calc!$AA$8,N('Tag 6'!$S$9)>0),'Tag 6'!$S$9-Calc!$AA$2-Calc!$AA$10,IF(N('Tag 6'!$K$9)>0,'Tag 6'!$K$9,2))
A13: OW | B13: =Calc!$B$1+2*Calc!$B$11 | F13: OW | G13: =Calc!$G$1+2*Calc!$G$11 | K13: OW | L13: =Calc!$L$1+2*Calc!$L$11 | P13: OW | Q13: =Calc!$Q$1+2*Calc!$Q$11 | U13: OW | V13: =Calc!$V$1+2*Calc!$V$11 | Z13: OW | AA13: =Calc!$AA$1+2*Calc!$AA$11
A14: OH | B14: =Calc!$B$2+Calc!$B$12 | F14: OH | G14: =Calc!$G$2+Calc!$G$12 | K14: OH | L14: =Calc!$L$2+Calc!$L$12 | P14: OH | Q14: =Calc!$Q$2+Calc!$Q$12 | U14: OH | V14: =Calc!$V$2+Calc!$V$12 | Z14: OH | AA14: =Calc!$AA$2+Calc!$AA$12
A15: throat | B15: =IF(Calc!$B$8,Calc!$B$6-1.125,Calc!$B$6-0.875) | F15: throat | G15: =IF(Calc!$G$8,Calc!$G$6-1.125,Calc!$G$6-0.875) | K15: throat | L15: =IF(Calc!$L$8,Calc!$L$6-1.125,Calc!$L$6-0.875) | P15: throat | Q15: =IF(Calc!$Q$8,Calc!$Q$6-1.125,Calc!$Q$6-0.875) | U15: throat | V15: =IF(Calc!$V$8,Calc!$V$6-1.125,Calc!$V$6-0.875) | Z15: throat | AA15: =IF(Calc!$AA$8,Calc!$AA$6-1.125,Calc!$AA$6-0.875)
A16: RDW | B16: =Calc!$B$1+RODryW | F16: RDW | G16: =Calc!$G$1+RODryW | K16: RDW | L16: =Calc!$L$1+RODryW | P16: RDW | Q16: =Calc!$Q$1+RODryW | U16: RDW | V16: =Calc!$V$1+RODryW | Z16: RDW | AA16: =Calc!$AA$1+RODryW
A17: RDH | B17: =Calc!$B$2+RODryH | F17: RDH | G17: =Calc!$G$2+RODryH | K17: RDH | L17: =Calc!$L$2+RODryH | P17: RDH | Q17: =Calc!$Q$2+RODryH | U17: RDH | V17: =Calc!$V$2+RODryH | Z17: RDH | AA17: =Calc!$AA$2+RODryH
A18: RMW | B18: =IF(N('Tag 1'!$Q$9)>0,'Tag 1'!$Q$9,Calc!$B$13+2*Calc!$B$10) | F18: RMW | G18: =IF(N('Tag 2'!$Q$9)>0,'Tag 2'!$Q$9,Calc!$G$13+2*Calc!$G$10) | K18: RMW | L18: =IF(N('Tag 3'!$Q$9)>0,'Tag 3'!$Q$9,Calc!$L$13+2*Calc!$L$10) | P18: RMW | Q18: =IF(N('Tag 4'!$Q$9)>0,'Tag 4'!$Q$9,Calc!$Q$13+2*Calc!$Q$10) | U18: RMW | V18: =IF(N('Tag 5'!$Q$9)>0,'Tag 5'!$Q$9,Calc!$V$13+2*Calc!$V$10) | Z18: RMW | AA18: =IF(N('Tag 6'!$Q$9)>0,'Tag 6'!$Q$9,Calc!$AA$13+2*Calc!$AA$10)
A19: RMH | B19: =IF(N('Tag 1'!$S$9)>0,'Tag 1'!$S$9,Calc!$B$14+Calc!$B$10) | F19: RMH | G19: =IF(N('Tag 2'!$S$9)>0,'Tag 2'!$S$9,Calc!$G$14+Calc!$G$10) | K19: RMH | L19: =IF(N('Tag 3'!$S$9)>0,'Tag 3'!$S$9,Calc!$L$14+Calc!$L$10) | P19: RMH | Q19: =IF(N('Tag 4'!$S$9)>0,'Tag 4'!$S$9,Calc!$Q$14+Calc!$Q$10) | U19: RMH | V19: =IF(N('Tag 5'!$S$9)>0,'Tag 5'!$S$9,Calc!$V$14+Calc!$V$10) | Z19: RMH | AA19: =IF(N('Tag 6'!$S$9)>0,'Tag 6'!$S$9,Calc!$AA$14+Calc!$AA$10)
A20: rvh | B20: =IF(ISNUMBER('Tag 1'!$M$9),'Tag 1'!$M$9,RevH) | F20: rvh | G20: =IF(ISNUMBER('Tag 2'!$M$9),'Tag 2'!$M$9,RevH) | K20: rvh | L20: =IF(ISNUMBER('Tag 3'!$M$9),'Tag 3'!$M$9,RevH) | P20: rvh | Q20: =IF(ISNUMBER('Tag 4'!$M$9),'Tag 4'!$M$9,RevH) | U20: rvh | V20: =IF(ISNUMBER('Tag 5'!$M$9),'Tag 5'!$M$9,RevH) | Z20: rvh | AA20: =IF(ISNUMBER('Tag 6'!$M$9),'Tag 6'!$M$9,RevH)
A21: rvl | B21: =IF(ISNUMBER('Tag 1'!$N$9),'Tag 1'!$N$9,RevL) | F21: rvl | G21: =IF(ISNUMBER('Tag 2'!$N$9),'Tag 2'!$N$9,RevL) | K21: rvl | L21: =IF(ISNUMBER('Tag 3'!$N$9),'Tag 3'!$N$9,RevL) | P21: rvl | Q21: =IF(ISNUMBER('Tag 4'!$N$9),'Tag 4'!$N$9,RevL) | U21: rvl | V21: =IF(ISNUMBER('Tag 5'!$N$9),'Tag 5'!$N$9,RevL) | Z21: rvl | AA21: =IF(ISNUMBER('Tag 6'!$N$9),'Tag 6'!$N$9,RevL)
A22: rvt | B22: =IF(ISNUMBER('Tag 1'!$O$9),'Tag 1'!$O$9,RevT) | F22: rvt | G22: =IF(ISNUMBER('Tag 2'!$O$9),'Tag 2'!$O$9,RevT) | K22: rvt | L22: =IF(ISNUMBER('Tag 3'!$O$9),'Tag 3'!$O$9,RevT) | P22: rvt | Q22: =IF(ISNUMBER('Tag 4'!$O$9),'Tag 4'!$O$9,RevT) | U22: rvt | V22: =IF(ISNUMBER('Tag 5'!$O$9),'Tag 5'!$O$9,RevT) | Z22: rvt | AA22: =IF(ISNUMBER('Tag 6'!$O$9),'Tag 6'!$O$9,RevT)
A23: uc | B23: =IF(ISNUMBER('Tag 1'!$P$9),'Tag 1'!$P$9,IF(OR('Tag 1'!$X$7="CURRIES",'Tag 1'!$X$7="PIONEER"),UCCur,UCOth)) | F23: uc | G23: =IF(ISNUMBER('Tag 2'!$P$9),'Tag 2'!$P$9,IF(OR('Tag 2'!$X$7="CURRIES",'Tag 2'!$X$7="PIONEER"),UCCur,UCOth)) | K23: uc | L23: =IF(ISNUMBER('Tag 3'!$P$9),'Tag 3'!$P$9,IF(OR('Tag 3'!$X$7="CURRIES",'Tag 3'!$X$7="PIONEER"),UCCur,UCOth)) | P23: uc | Q23: =IF(ISNUMBER('Tag 4'!$P$9),'Tag 4'!$P$9,IF(OR('Tag 4'!$X$7="CURRIES",'Tag 4'!$X$7="PIONEER"),UCCur,UCOth)) | U23: uc | V23: =IF(ISNUMBER('Tag 5'!$P$9),'Tag 5'!$P$9,IF(OR('Tag 5'!$X$7="CURRIES",'Tag 5'!$X$7="PIONEER"),UCCur,UCOth)) | Z23: uc | AA23: =IF(ISNUMBER('Tag 6'!$P$9),'Tag 6'!$P$9,IF(OR('Tag 6'!$X$7="CURRIES",'Tag 6'!$X$7="PIONEER"),UCCur,UCOth))
A24: LW | B24: =IF(Calc!$B$4,(Calc!$B$1-2*Calc!$B$20-Calc!$B$21)/2,Calc!$B$1-Calc!$B$20-Calc!$B$21) | F24: LW | G24: =IF(Calc!$G$4,(Calc!$G$1-2*Calc!$G$20-Calc!$G$21)/2,Calc!$G$1-Calc!$G$20-Calc!$G$21) | K24: LW | L24: =IF(Calc!$L$4,(Calc!$L$1-2*Calc!$L$20-Calc!$L$21)/2,Calc!$L$1-Calc!$L$20-Calc!$L$21) | P24: LW | Q24: =IF(Calc!$Q$4,(Calc!$Q$1-2*Calc!$Q$20-Calc!$Q$21)/2,Calc!$Q$1-Calc!$Q$20-Calc!$Q$21) | U24: LW | V24: =IF(Calc!$V$4,(Calc!$V$1-2*Calc!$V$20-Calc!$V$21)/2,Calc!$V$1-Calc!$V$20-Calc!$V$21) | Z24: LW | AA24: =IF(Calc!$AA$4,(Calc!$AA$1-2*Calc!$AA$20-Calc!$AA$21)/2,Calc!$AA$1-Calc!$AA$20-Calc!$AA$21)
A25: LH | B25: =Calc!$B$2-Calc!$B$22-Calc!$B$23 | F25: LH | G25: =Calc!$G$2-Calc!$G$22-Calc!$G$23 | K25: LH | L25: =Calc!$L$2-Calc!$L$22-Calc!$L$23 | P25: LH | Q25: =Calc!$Q$2-Calc!$Q$22-Calc!$Q$23 | U25: LH | V25: =Calc!$V$2-Calc!$V$22-Calc!$V$23 | Z25: LH | AA25: =Calc!$AA$2-Calc!$AA$22-Calc!$AA$23
A26: n | B26: =IF(OR('Tag 1'!$P$7="HGC",'Tag 1'!$P$7="BLANK"),0,IF(LEFT('Tag 1'!$P$7,4)="U454",4,IF(LEFT('Tag 1'!$P$7,4)="U453",3,IF(Calc!$B$25<=60,2,IF(Calc!$B$25<=90,3,4))))) | F26: n | G26: =IF(OR('Tag 2'!$P$7="HGC",'Tag 2'!$P$7="BLANK"),0,IF(LEFT('Tag 2'!$P$7,4)="U454",4,IF(LEFT('Tag 2'!$P$7,4)="U453",3,IF(Calc!$G$25<=60,2,IF(Calc!$G$25<=90,3,4))))) | K26: n | L26: =IF(OR('Tag 3'!$P$7="HGC",'Tag 3'!$P$7="BLANK"),0,IF(LEFT('Tag 3'!$P$7,4)="U454",4,IF(LEFT('Tag 3'!$P$7,4)="U453",3,IF(Calc!$L$25<=60,2,IF(Calc!$L$25<=90,3,4))))) | P26: n | Q26: =IF(OR('Tag 4'!$P$7="HGC",'Tag 4'!$P$7="BLANK"),0,IF(LEFT('Tag 4'!$P$7,4)="U454",4,IF(LEFT('Tag 4'!$P$7,4)="U453",3,IF(Calc!$Q$25<=60,2,IF(Calc!$Q$25<=90,3,4))))) | U26: n | V26: =IF(OR('Tag 5'!$P$7="HGC",'Tag 5'!$P$7="BLANK"),0,IF(LEFT('Tag 5'!$P$7,4)="U454",4,IF(LEFT('Tag 5'!$P$7,4)="U453",3,IF(Calc!$V$25<=60,2,IF(Calc!$V$25<=90,3,4))))) | Z26: n | AA26: =IF(OR('Tag 6'!$P$7="HGC",'Tag 6'!$P$7="BLANK"),0,IF(LEFT('Tag 6'!$P$7,4)="U454",4,IF(LEFT('Tag 6'!$P$7,4)="U453",3,IF(Calc!$AA$25<=60,2,IF(Calc!$AA$25<=90,3,4)))))
A27: cust | B27: =OR('Tag 1'!$X$7="CUSTOM",N('Tag 1'!$B$11)+N('Tag 1'!$D$11)+N('Tag 1'!$F$11)+N('Tag 1'!$H$11)+N('Tag 1'!$J$11)>0) | F27: cust | G27: =OR('Tag 2'!$X$7="CUSTOM",N('Tag 2'!$B$11)+N('Tag 2'!$D$11)+N('Tag 2'!$F$11)+N('Tag 2'!$H$11)+N('Tag 2'!$J$11)>0) | K27: cust | L27: =OR('Tag 3'!$X$7="CUSTOM",N('Tag 3'!$B$11)+N('Tag 3'!$D$11)+N('Tag 3'!$F$11)+N('Tag 3'!$H$11)+N('Tag 3'!$J$11)>0) | P27: cust | Q27: =OR('Tag 4'!$X$7="CUSTOM",N('Tag 4'!$B$11)+N('Tag 4'!$D$11)+N('Tag 4'!$F$11)+N('Tag 4'!$H$11)+N('Tag 4'!$J$11)>0) | U27: cust | V27: =OR('Tag 5'!$X$7="CUSTOM",N('Tag 5'!$B$11)+N('Tag 5'!$D$11)+N('Tag 5'!$F$11)+N('Tag 5'!$H$11)+N('Tag 5'!$J$11)>0) | Z27: cust | AA27: =OR('Tag 6'!$X$7="CUSTOM",N('Tag 6'!$B$11)+N('Tag 6'!$D$11)+N('Tag 6'!$F$11)+N('Tag 6'!$H$11)+N('Tag 6'!$J$11)>0)
A28: key | B28: =IF(Calc!$B$2<=80,80,IF(Calc!$B$2<=84,84,96)) | F28: key | G28: =IF(Calc!$G$2<=80,80,IF(Calc!$G$2<=84,84,96)) | K28: key | L28: =IF(Calc!$L$2<=80,80,IF(Calc!$L$2<=84,84,96)) | P28: key | Q28: =IF(Calc!$Q$2<=80,80,IF(Calc!$Q$2<=84,84,96)) | U28: key | V28: =IF(Calc!$V$2<=80,80,IF(Calc!$V$2<=84,84,96)) | Z28: key | AA28: =IF(Calc!$AA$2<=80,80,IF(Calc!$AA$2<=84,84,96))
A29: inC | B29: =AND(NOT(Calc!$B$27),Calc!$B$2<=96,ISNUMBER(MATCH('Tag 1'!$X$7&"|80",T_LocKey,0))) | F29: inC | G29: =AND(NOT(Calc!$G$27),Calc!$G$2<=96,ISNUMBER(MATCH('Tag 2'!$X$7&"|80",T_LocKey,0))) | K29: inC | L29: =AND(NOT(Calc!$L$27),Calc!$L$2<=96,ISNUMBER(MATCH('Tag 3'!$X$7&"|80",T_LocKey,0))) | P29: inC | Q29: =AND(NOT(Calc!$Q$27),Calc!$Q$2<=96,ISNUMBER(MATCH('Tag 4'!$X$7&"|80",T_LocKey,0))) | U29: inC | V29: =AND(NOT(Calc!$V$27),Calc!$V$2<=96,ISNUMBER(MATCH('Tag 5'!$X$7&"|80",T_LocKey,0))) | Z29: inC | AA29: =AND(NOT(Calc!$AA$27),Calc!$AA$2<=96,ISNUMBER(MATCH('Tag 6'!$X$7&"|80",T_LocKey,0)))
A30: cA | B30: =IF(Calc!$B$29,VLOOKUP('Tag 1'!$X$7&"|"&Calc!$B$28,T_Loc,4,FALSE),5) | F30: cA | G30: =IF(Calc!$G$29,VLOOKUP('Tag 2'!$X$7&"|"&Calc!$G$28,T_Loc,4,FALSE),5) | K30: cA | L30: =IF(Calc!$L$29,VLOOKUP('Tag 3'!$X$7&"|"&Calc!$L$28,T_Loc,4,FALSE),5) | P30: cA | Q30: =IF(Calc!$Q$29,VLOOKUP('Tag 4'!$X$7&"|"&Calc!$Q$28,T_Loc,4,FALSE),5) | U30: cA | V30: =IF(Calc!$V$29,VLOOKUP('Tag 5'!$X$7&"|"&Calc!$V$28,T_Loc,4,FALSE),5) | Z30: cA | AA30: =IF(Calc!$AA$29,VLOOKUP('Tag 6'!$X$7&"|"&Calc!$AA$28,T_Loc,4,FALSE),5)
A31: cB | B31: =IF(Calc!$B$29,VLOOKUP('Tag 1'!$X$7&"|"&Calc!$B$28,T_Loc,5,FALSE),"") | F31: cB | G31: =IF(Calc!$G$29,VLOOKUP('Tag 2'!$X$7&"|"&Calc!$G$28,T_Loc,5,FALSE),"") | K31: cB | L31: =IF(Calc!$L$29,VLOOKUP('Tag 3'!$X$7&"|"&Calc!$L$28,T_Loc,5,FALSE),"") | P31: cB | Q31: =IF(Calc!$Q$29,VLOOKUP('Tag 4'!$X$7&"|"&Calc!$Q$28,T_Loc,5,FALSE),"") | U31: cB | V31: =IF(Calc!$V$29,VLOOKUP('Tag 5'!$X$7&"|"&Calc!$V$28,T_Loc,5,FALSE),"") | Z31: cB | AA31: =IF(Calc!$AA$29,VLOOKUP('Tag 6'!$X$7&"|"&Calc!$AA$28,T_Loc,5,FALSE),"")
A32: cC | B32: =IF(Calc!$B$29,VLOOKUP('Tag 1'!$X$7&"|"&Calc!$B$28,T_Loc,6,FALSE),"") | F32: cC | G32: =IF(Calc!$G$29,VLOOKUP('Tag 2'!$X$7&"|"&Calc!$G$28,T_Loc,6,FALSE),"") | K32: cC | L32: =IF(Calc!$L$29,VLOOKUP('Tag 3'!$X$7&"|"&Calc!$L$28,T_Loc,6,FALSE),"") | P32: cC | Q32: =IF(Calc!$Q$29,VLOOKUP('Tag 4'!$X$7&"|"&Calc!$Q$28,T_Loc,6,FALSE),"") | U32: cC | V32: =IF(Calc!$V$29,VLOOKUP('Tag 5'!$X$7&"|"&Calc!$V$28,T_Loc,6,FALSE),"") | Z32: cC | AA32: =IF(Calc!$AA$29,VLOOKUP('Tag 6'!$X$7&"|"&Calc!$AA$28,T_Loc,6,FALSE),"")
A33: cD | B33: =IF(Calc!$B$29,N(VLOOKUP('Tag 1'!$X$7&"|"&Calc!$B$28,T_Loc,7,FALSE)),0) | F33: cD | G33: =IF(Calc!$G$29,N(VLOOKUP('Tag 2'!$X$7&"|"&Calc!$G$28,T_Loc,7,FALSE)),0) | K33: cD | L33: =IF(Calc!$L$29,N(VLOOKUP('Tag 3'!$X$7&"|"&Calc!$L$28,T_Loc,7,FALSE)),0) | P33: cD | Q33: =IF(Calc!$Q$29,N(VLOOKUP('Tag 4'!$X$7&"|"&Calc!$Q$28,T_Loc,7,FALSE)),0) | U33: cD | V33: =IF(Calc!$V$29,N(VLOOKUP('Tag 5'!$X$7&"|"&Calc!$V$28,T_Loc,7,FALSE)),0) | Z33: cD | AA33: =IF(Calc!$AA$29,N(VLOOKUP('Tag 6'!$X$7&"|"&Calc!$AA$28,T_Loc,7,FALSE)),0)
