Workbook
Name Scope: Lists!$A$5:$A$7
Name Floor: Lists!$B$5:$B$15
Name Category: Lists!$C$5:$C$6
Name FireRating: Lists!$D$5:$D$10
Name FrameType: Lists!$E$5:$E$10
Name Profile: Lists!$F$5:$F$8
Name JambDepth: Lists!$G$5:$G$77
Name GaugeFrame: Lists!$H$5:$H$6
Name SteelType: Lists!$I$5:$I$8
Name Construction: Lists!$J$5:$J$6
Name AnchorType: Lists!$K$5:$K$12
Name Handing: Lists!$L$5:$L$20
Name YesNo: Lists!$M$5:$M$6
Name Manufacturer: Lists!$N$5:$N$6
Name HingePrep: Lists!$O$5:$O$12
Name StrikePrep: Lists!$P$5:$P$15
Name HeaderPrep: Lists!$Q$5:$Q$9
Name CloserPrep: Lists!$R$5:$R$11
Name DoorMaterial: Lists!$S$5:$S$14
Name GaugeDoor: Lists!$T$5:$T$7
Name WoodCore: Lists!$U$5:$U$8
Name FaceType: Lists!$V$5:$V$23
Name ManufLoc: Lists!$W$5:$W$15
Name LockPrep: Lists!$X$5:$X$27
Name Edge: Lists!$Y$5:$Y$8
Name Astragal: Lists!$Z$5:$Z$6
Name Series: Lists!$AA$5:$AA$11
Name WoodFinish: Lists!$AB$5:$AB$12
Name WallType: Lists!$AD$5:$AD$12
Name WallHR: Lists!$AE$5:$AE$11
Name SLSide: Lists!$AF$5:$AF$7
Name HingeSize: Lists!$AG$5:$AG$7
Name HingeQty: Lists!$AH$5:$AH$9
Name HWUnit: Lists!$AI$5:$AI$9
Name HWItem: Lists!$AJ$5:$AJ$39
Name HWFinish: Lists!$AK$5:$AK$17
Name IBC: Lists!$AM$5:$AN$23
Name CODES: Codes!$A$5:$B$400
Name LocTable: Reference!$B$7:$I$33
Name LocKeys: Reference!$B$7:$B$33
Name JobName: Job!$C$6
Name JobNo: Job!$C$7
Name JobAddress: Job!$C$8
Name JobGC: Job!$C$9
Name JobArch: Job!$C$10
Name JobEst: Job!$C$11
Name JobDate: Job!$C$12
Name JobBid: Job!$C$13
Name JobSupplier: Job!$C$14
Name JobRev: Job!$C$15
Name JobDocs: Job!$C$16
Name FaceW: Job!$C$20
Name EdgeClr: Job!$C$21
Name MeetClr: Job!$C$22
Name HeadClr: Job!$C$23
Name Undercut: Job!$C$24
Name ROSide: Job!$C$25
Name ROTop: Job!$C$26
Name ClearDeduct: Job!$C$27
Name LockAFF: Job!$C$28

Sheet Start
B3: OPENING TAKEOFF
B4: TAKEOFF FORM 3.2
B6: Doors · frames · hardware · live elevations with hinge locations · code checks · door schedule · order lines
B7: =IF(JobName="","",JobName&IF(JobNo="",""," · JOB "&JobNo)&" · "&TEXT(JobDate,"mmmm d, yyyy"))
B11: GO TO
B12: JOB | C12: Job name, dates and clearances
B13: TAKEOFF | C13: One row per opening — the only place you type openings
B14: ELEVATION | C14: Pick a mark: drawing, hinge & strike locations, sizes, checks
B15: ELEVATIONS | C15: Every elevation type, six to a page
B16: DOOR SCHEDULE | C16: Architectural door schedule, ready to print
B17: HW SETS | C17: Hardware sets: set number once, items carry down (2.1 style)
B18: HW SCHEDULE | C18: By set with marks, and job totals by item
B19: SUPPLIER ORDER | C19: Counter format: grouped lines, marks with hands, every part
B20: FRAME ORDER | C20: Frame order lines with anchors and locations
B21: DOOR ORDER | C21: Door order lines with leaf sizes and locations
B22: SUMMARY | C22: Counts by rating, scope, floor, material, lite, location standard
B23: REFERENCE | C23: Hinge location charts, label classes, weld codes, anchors, handing
... B25: HOW TO USE IT | C25: What each code prints on an order line
B26: 1 | C26: Fill in the Job sheet once. Set the clearances (undercut, edge gaps, frame face) to suit your frame maker.
B27: 2 | C27: On Takeoff type one row per opening. Pick SCOPE first: it decides whether the row makes a frame line, a door line, or both.
B28: 3 | C28: Size: W FT, W IN, H FT, H IN (3 · 0 · 7 · 0 = 3070). Fractions as decimals: 0.5 = 1/2". PAIR = Y for a pair. Transom and sidelite are glass sizes in inches.
B29: 4 | C29: LOCATIONS: pick the standard (ANSI/SDI or a maker chart) and the hinges and strike are placed for you. For a custom job pick CUSTOM LOC, or just type A–D and E (inches from the top of the frame to the top of each hinge / strike centre line).
B30: 5 | C30: Give WALL TYPE and WALL HR when the plans show them: the door rating is checked against IBC Table 716.1(2).
B31: 6 | C31: Amber cells are required and still empty. CHECK says OK, CHECK (worth a look) or FIX (missing or wrong) and the next column says why.
B32: 7 | C32: Elevation draws any mark at scale with its hinges, strike, lite and dimensions; Elevations draws one of each type. Door Schedule lists every opening.
B33: 8 | C33: HW Sets: type the set number once and the items under it; pick the set on the Takeoff. HW Schedule, Supplier Order, Frame order and Door order build themselves.
B34: 9 | C34: The eight sample openings (101–108) show every feature (102 has custom hinge locations). Select the input cells of those rows and press Delete to start a job; the formulas stay.
B36: COLOUR KEY
C37: Opening inputs
C38: Frame inputs
C39: Door inputs
C40: Hinge & strike locations
C41: Hardware
C42: Calculated — do not type
C43: Required and still empty
C44: Custom hinge locations in use
B45: Blue | C45: Values you typed
B47: NEW IN 3.2
B48: ▸ | C48: From your 2.1 (Oct): HW Sets typed the 2.1 way (set number once, items carry down, set index feeds the dropdown), HW Schedule by set with the marks and job totals by item, and door groups.
B49: ▸ | C49: Supplier Order in the counter format of the order confirmations: S.HM item, "N) order line", marks with hands, then every part — HD/HJ/SJ, anchors, reinforcements, labels, preps, cut downs, door slab with net size.
...

Sheet Job
B1: JOB | E1: =IF(JobName="","OPENING TAKEOFF · FORM 3.2",JobName&IF(JobNo="",""," · JOB "&JobNo))
B2: Fill this in once. It prints on every sheet, the elevations and the order sheets. | E2: =TEXT(JobDate,"mmm d, yyyy")&IF(JobRev="",""," · "&JobRev)
B5: PROJECT
B6: Job name
B7: Job number
B8: Address
B9: General contractor
B10: Architect
B11: Estimator / drawn by
B12: Date | C12: =TODAY()
B13: Bid date
B14: Supplier | C14: CURRIES
B15: Revision | C15: REV 0
B16: Drawings / addenda
B19: SIZES AND CLEARANCES (inches) — used for leaf size, frame overall, rough opening, clear width and the elevations
B20: Frame face (jamb & head) | C20: 2 | D20: Standard 2" face. A 4" head is picked per opening.
B21: Hinge & strike edge clearance | C21: 0.125 | D21: Each side, leaf to rabbet (NFPA 80: 1/8" max on steel).
B22: Meeting edge clearance (pairs) | C22: 0.125 | D22: Between the leaves of a pair.
B23: Head clearance | C23: 0.125 | D23: Top of leaf to head rabbet. Door hinge dims = frame dims less this.
B24: Undercut | C24: 0.75 | D24: Floor to bottom of leaf. NFPA 80: 3/4" max over a non-combustible floor.
B25: Rough opening allowance, each side | C25: 0.25 | D25: Added to frame overall width, each side.
B26: Rough opening allowance, head | C26: 0.25 | D26: Added to frame overall height.
B27: Clear width deduction | C27: 2.625 | D27: Leaf width minus this = approx. clear opening at 90°.
B28: Lock / lever centre line (AFF) | C28: 40.3125 | D28: ANSI/SDI 40-5/16". Maker charts and CUSTOM E override it.

Sheet Takeoff
A1: =IF(JobName="","TAKEOFF — fill in the job on the Job sheet","TAKEOFF — "&JobName&IF(JobNo="",""," · JOB "&JobNo))
A2: =COUNTIF(tk_MARK,"?*")&" rows · "&SUM(tk_QTY)&" openings · "&SUMPRODUCT(tk_QTY,tk_LEAVES)&" leaves · "&SUMPRODUCT(tk_QTY,--(tk_DMIN>0))&" rated · "&COUNTIF(tk_CHECK,"FIX")&" to fix · "&COUNTIF(tk_CHECK,"CHECK")&" to check"
A4: OPENING | S4: FRAME | AH4: DOOR | AT4: LOCATIONS | BB4: HARDWARE | BD4: CALCULATED
A5: MARK | B5: QTY | C5: SCOPE | D5: FLOOR | E5: CATEGORY | F5: ROOM FROM | G5: ROOM TO | H5: FIRE RATING | I5: WALL TYPE | J5: WALL HR | K5: W FT | L5: W IN | M5: H FT | N5: H IN | O5: PAIR | P5: TRANSOM H (IN) | Q5: SIDELITE W (IN) | R5: SIDELITE SIDE | S5: FRAME TYPE | T5: PROFILE | U5: JAMB DEPTH | V5: GAUGE | W5: STEEL | X5: CONSTR. | Y5: ANCHOR | Z5: HAND | AA5: MANUF. | AB5: 4" HEAD | AC5: HINGE PREP | AD5: STRIKE PREP | AE5: HEADER PREP | AF5: CLOSER REINF. | AG5: FRAME NOTES | AH5: MATERIAL | AI5: GAUGE | AJ5: WOOD CORE | AK5: WOOD FINISH | AL5: FACE TYPE | AM5: SERIES | AN5: DOOR HAND (blank = frame) | AO5: HINGE PREP (blank = frame) | AP5: LOCK PREP | AQ5: EDGE | AR5: ASTRAGAL | AS5: DOOR NOTES | AT5: LOCATION STANDARD | AU5: HINGE SIZE (blank 4.5) | AV5: HINGE QTY (blank = auto) | AW5: CUSTOM A | AX5: CUSTOM B | AY5: CUSTOM C | AZ5: CUSTOM D | BA5: CUSTOM E (STRIKE) | BB5: HW SET | BC5: HARDWARE NOTES | BD5: CHECK | BE5: WHAT TO FIX / CHECK | BF5: SIZE | BG5: CODE | BH5: W (IN) | BI5: H (IN) | BJ5: LEAVES | BK5: LEAF W | BL5: LEAF H | BM5: FRAME O/A W | BN5: FRAME O/A H | BO5: ROUGH OPG W | BP5: ROUGH OPG H | BQ5: CLEAR W (approx) | BR5: LABEL | BS5: HINGES / LEAF | BT5: LOCATIONS FROM | BU5: HINGE A | BV5: HINGE B | BW5: HINGE C | BX5: HINGE D | BY5: HINGE F | BZ5: STRIKE E | CA5: LOCK CL AFF | CB5: ANCHORS / JAMB | CC5: JAMB ANCHORS TOTAL | CD5: BASE ANCHORS | CE5: LITE KIT | CF5: LITE W | CG5: LITE H | CH5: DOOR MIN | CI5: WALL NEEDS (MIN) | CJ5: FRAME ORDER LINE | CK5: DOOR ORDER LINE | CL5: ELEV TYPE | CM5: FSEQ | CN5: DSEQ | CO5: ASEQ | CP5: EKEY | CQ5: NH | CR5: HL | CS5: NOHINGE | CT5: LCUST | CU5: LKEY | CV5: LIN | CW5: LFIRST | CX5: LLAST | CY5: LOC TEXT FRAME | CZ5: LOC TEXT DOOR | DA5: HAND LEG | DB5: JAMB HAND | DC5: ORDER ITEM | DD5: FRAME LINE NO HAND | DE5: DOOR LINE NO HAND | DF5: FRAME GROUP KEY | DG5: FRAME GROUP | DH5: DOOR GROUP KEY | DI5: DOOR GROUP | DJ5: ERRS | DK5: WARNS
A6: 101 | B6: 1 | C6: FRAME & DOOR | D6: 1st | E6: INTERIOR | F6: CORRIDOR | G6: OFFICE 101 | H6: 20 MIN | I6: CORRIDOR | J6: 1 | K6: 3 | L6: 0 | M6: 7 | N6: 0 | S6: 3F | T6: M | U6: 534 | V6: 16 | W6: CR | X6: KD | Y6: SC | Z6: R | AA6: CU | AC6: U453 | AD6: E1 | AF6: E11 | AH6: CR | AI6: 18 | AL6: FNV-6"x27" | AM6: 707 | AP6: G2 | AT6: CURRIES | BB6: 1 | BD6: =IF($A6="","",IF($DJ6<>"","FIX",IF($DK6<>"","CHECK","OK"))) | BE6: =IF($A6="","",IF($DJ6<>"","FIX: "&LEFT($DJ6,LEN($DJ6)-2)&IF($DK6<>""," · ",""),"")&IF($DK6<>"","CHECK: "&LEFT($DK6,LEN($DK6)-2),"")) | BF6: =IF(OR($A6="",$K6=""),"",$K6&"'-"&N($L6)&CHAR(34)&" x "&$M6&"'-"&N($N6)&CHAR(34)) | BG6: =IF(OR($A6="",$K6=""),"",$K6&N($L6)&$M6&N($N6)) | BH6: =IF(OR($A6="",$K6=""),"",$K6*12+N($L6)) | BI6: =IF(OR($A6="",$M6=""),"",$M6*12+N($N6)) | BJ6: =IF($A6="","",IF(OR($C6="FRAME ONLY",$S6="BL"),0,IF($O6="Y",2,1))) | BK6: =IF(OR(N($BJ6)=0,$BH6=""),"",($BH6-2*EdgeClr-IF($BJ6=2,MeetClr,0))/$BJ6) | BL6: =IF(OR(N($BJ6)=0,$BI6=""),"",$BI6-HeadClr-Undercut) | BM6: =IF($BH6="","",$BH6+2*FaceW+IF(N($Q6)>0,($Q6+FaceW)*IF($R6="LR",2,1),0)) | BN6: =IF($BI6="","",$BI6+IF($AB6="Y",4,FaceW)+IF(N($P6)>0,$P6+FaceW,0)+IF(OR($S6="4F",$S6="BL"),FaceW,0)) | BO6: =IF($BM6="","",$BM6+2*ROSide) | BP6: =IF($BN6="","",$BN6+ROTop) | BQ6: =IF(OR(N($BJ6)=0,$BH6=""),"",$BH6/$BJ6-ClearDeduct) | BR6: =IF(N($CH6)=0,"",IF($CH6>=180,"A · 3 HR",IF($CH6>=90,"B · 1-1/2 HR",IF($CH6>=60,"B · 1 HR",IF($CH6>=45,"C · 3/4 HR","20 MIN")))))&IF(AND(N($CH6)>0,OR($I6="CORRIDOR",$I6="SMOKE BARRIER"))," · S","") | BS6: =IF($CS6,"",IF($AV6<>"",$AV6,IF(OR($AC6="HGC",$AO6="HGC"),"CONT",IF(($BI6-HeadClr-Undercut)<=60,2,IF(($BI6-HeadClr-Undercut)<=90,3,IF(($BI6-HeadClr-Undercut)<=120,4,5)))))) | BT6: =IF($CS6,"",IF($CT6,"CUSTOM (typed)",IF($CV6,$AT6&" "&$CU6&CHAR(34)&IF($CU6<>$BI6,IF(AND($BI6<$CU6,$BI6-IF(N(VLOOKUP($AT6&"|"&$CU6,LocTable,7,FALSE))>0,VLOOKUP($AT6&"|"&$CU6,LocTable,7,FALSE),VLOOKUP($AT6&"|"&$CU6,LocTable,6,FALSE))-$CR6-0.75>=2.125)," cut down"," adj."),""),"ANSI/SDI A250.6"))) | BU6: =IF($CS6,"",IF($CT6,IF(N($AW6)>0,N($AW6),""),IF(1>$CQ6,"",IF($CQ6=1,$CW6,$CW6+($CX6-$CW6)*0/($CQ6-1))))) | BV6: =IF($CS6,"",IF($CT6,IF(N($AX6)>0,N($AX6),""),IF(2>$CQ6,"",IF($CQ6=1,$CW6,$CW6+($CX6-$CW6)*1/($CQ6-1))))) | BW6: =IF($CS6,"",IF($CT6,IF(N($AY6)>0,N($AY6),""),IF(3>$CQ6,"",IF($CQ6=1,$CW6,$CW6+($CX6-$CW6)*2/($CQ6-1))))) | BX6: =IF($CS6,"",IF($CT6,IF(N($AZ6)>0,N($AZ6),""),IF(4>$CQ6,"",IF($CQ6=1,$CW6,$CW6+($CX6-$CW6)*3/($CQ6-1))))) | BY6: =IF($CS6,"",IF($CT6,"",IF(5>$CQ6,"",IF($CQ6=1,$CW6,$CW6+($CX6-$CW6)*4/($CQ6-1))))) | BZ6: =IF(OR($CS6,$AP6="-",AND($AP6="",$AD6="")),"",IF(N($BA6)>0,N($BA6),IF($CV6,IF(AND($BI6<$CU6,$BI6-IF(N(VLOOKUP($AT6&"|"&$CU6,LocTable,7,FALSE))>0,VLOOKUP($AT6&"|"&$CU6,LocTable,7,FALSE),VLOOKUP($AT6&"|"&$CU6,LocTable,6,FALSE))-$CR6-0.75>=2.125),VLOOKUP($AT6&"|"&$CU6,LocTable,8,FALSE),VLOOKUP($AT6&"|"&$CU6,LocTable,8,FALSE)+($BI6-$CU6)),$BI6-LockAFF))) | CA6: =IF($BZ6="","",$BI6-$BZ6) | CB6: =IF(OR(NOT(AND($A6<>"",$C6<>"DOOR ONLY")),$BI6=""),"",IF(($BI6+IF(N($P6)>0,$P6+FaceW,0))<=90,3,IF(($BI6+IF(N($P6)>0,$P6+FaceW,0))<=114,4,5))) | CC6: =IF($CB6="","",$CB6*(2+IF(N($Q6)>0,IF($R6="LR",2,1),0))) | CD6: =IF($CB6="","",(2+IF(N($Q6)>0,IF($R6="LR",2,1),0))) | CE6: =IF(N($BJ6)=0,"",IF(OR($AL6="",$AL6="FLUSH"),"FLUSH",IFERROR(LEFT($AL6,FIND("-",$AL6)-1),LEFT($AL6,2)))) | CF6: =IF($CE6="","",IFERROR(VALUE(MID($AL6,FIND("-",$AL6)+1,FIND(CHAR(34)&"x",$AL6)-FIND("-",$AL6)-1)),0)) | CG6: =IF($CE6="","",IFERROR(VALUE(MID($AL6,FIND(CHAR(34)&"x",$AL6)+2,FIND(CHAR(34),$AL6,FIND(CHAR(34)&"x",$AL6)+2)-FIND(CHAR(34)&"x",$AL6)-2)),0)) | CH6: =IF(OR($A6="",$H6="",$H6="NO LAB"),0,IFERROR(VALUE(LEFT($H6,FIND(" ",$H6)-1)),0)) | CI6: =IF(OR($A6="",$I6="",$I6="NON-RATED",N($J6)=0),"",IFERROR(VLOOKUP($I6&"|"&$J6,IBC,2,FALSE),"?")) | CJ6: =IF(NOT(AND($A6<>"",$C6<>"DOOR ONLY")),"",TRIM(IFERROR(VLOOKUP($U6,CODES,2,FALSE),"")&" "&$BG6&" "&IFERROR(VLOOKUP($Z6,CODES,2,FALSE),"")&" "&IFERROR(VLOOKUP($X6,CODES,2,FALSE),"")&" "&IFERROR(VLOOKUP($S6,CODES,2,FALSE),"")&IF(N($P6)>0," w/TRANSOM "&$P6&CHAR(34),"")&IF(N($Q6)>0," w/SIDELITE "&$Q6&CHAR(34)&" "&IF($R6="","R",$R6),"")&IF($Y6=""," | "," | "&IFERROR(VLOOKUP($Y6,CODES,2,FALSE),"")&" | ")&IFERROR(VLOOKUP($AC6,CODES,2,FALSE),"")&" "&IFERROR(VLOOKUP($AD6,CODES,2,FALSE),"")&IF(OR($AE6="",$AE6="-"),""," "&$AE6)&IF(OR($AF6="",$AF6="-"),""," "&$AF6)&IF($AB6="Y"," 4"&CHAR(34)&" HEAD","")&" "&IFERROR(VLOOKUP($H6,CODES,2,FALSE),"")&IF($CT6," | LOC "&$CY6,""))) | CK6: =IF(NOT(AND($A6<>"",N($BJ6)>0)),"",TRIM(IFERROR(VLOOKUP($AH6,CODES,2,FALSE),"")&IF($AI6=""," "," "&$AI6&"GA ")&$BG6&" "&IF($AN6="",IFERROR(VLOOKUP($Z6,CODES,2,FALSE),""),IFERROR(VLOOKUP($AN6,CODES,2,FALSE),""))&IF($BJ6=2," PAIR","")&" DOOR | "&IF($AL6="","?",$AL6)&" | "&IF($AO6="",IFERROR(VLOOKUP($AC6,CODES,2,FALSE),""),IFERROR(VLOOKUP($AO6,CODES,2,FALSE),""))&" "&IFERROR(VLOOKUP($AP6,CODES,2,FALSE),"")&IF(OR($AQ6="",$AQ6="-"),""," SEAM "&$AQ6)&IF($AR6="Y"," ASTRAGAL","")&IF($AJ6=""," "," "&$AJ6)&IF($AK6=""," "," "&$AK6)&IF(OR($AT6="",$AT6="ANSI/SDI",$AT6="CUSTOM LOC"),""," "&$AT6)&IF($AM6=""," "," SERIES "&$AM6)&" "&IFERROR(VLOOKUP($H6,CODES,2,FALSE),"")&IF($CT6," | LOC "&$CZ6,""))) | CL6: =IF(CP6="","",IF(COUNTIF($CP$6:CP6,CP6)=1,MAX($CL$5:CL5)+1,INDEX($CL$5:CL5,MATCH(CP6,$CP$5:CP5,0)))) | CM6: =IF(NOT(AND($A6<>"",$C6<>"DOOR ONLY")),"",MAX($CM$5:CM5)+1) | CN6: =IF(NOT(AND($A6<>"",N($BJ6)>0)),"",MAX($CN$5:CN5)+1) | CO6: =IF($A6="","",MAX($CO$5:CO5)+1) | CP6: =IF(OR($A6="",$BH6="",$BI6=""),"",$BG6&"|"&$O6&"|"&$AL6&"|"&$S6&"|"&$P6&"|"&$Q6&$R6&"|"&$C6&"|"&$AB6) | CQ6: =N($BS6) | CR6: =IF(N($AU6)>0,N($AU6),4.5) | CS6: =OR($A6="",$BI6="",$S6="BL",AND($C6="FRAME ONLY",OR($AC6="",$AC6="BLK"))) | CT6: =AND(NOT($CS6),OR($AT6="CUSTOM LOC",N($AW6)+N($AX6)+N($AY6)+N($AZ6)+N($BA6)>0)) | CU6: =IF($BI6="","",IF($BI6<=80,80,IF($BI6<=84,84,96))) | CV6: =ISNUMBER(MATCH($AT6&"|80",LocKeys,0)) | CW6: =IF($CS6,"",IF($CV6,VLOOKUP($AT6&"|"&$CU6,LocTable,4,FALSE),5)) | CX6: =IF($CS6,"",IF($CV6,IF(OR($BI6=$CU6,AND($BI6<$CU6,$BI6-IF(N(VLOOKUP($AT6&"|"&$CU6,LocTable,7,FALSE))>0,VLOOKUP($AT6&"|"&$CU6,LocTable,7,FALSE),VLOOKUP($AT6&"|"&$CU6,LocTable,6,FALSE))-$CR6-0.75>=2.125)),IF(N(VLOOKUP($AT6&"|"&$CU6,LocTable,7,FALSE))>0,VLOOKUP($AT6&"|"&$CU6,LocTable,7,FALSE),VLOOKUP($AT6&"|"&$CU6,LocTable,6,FALSE)),$BI6-($CU6-IF(N(VLOOKUP($AT6&"|"&$CU6,LocTable,7,FALSE))>0,VLOOKUP($AT6&"|"&$CU6,LocTable,7,FALSE),VLOOKUP($AT6&"|"&$CU6,LocTable,6,FALSE)))),$BI6-10-$CR6)) | CY6: =IF($CS6,"",TRIM(IF(ISNUMBER($BU6),"A "&TRIM(TEXT($BU6,"# ?/??"))&CHAR(34)&" ","")&IF(ISNUMBER($BV6),"B "&TRIM(TEXT($BV6,"# ?/??"))&CHAR(34)&" ","")&IF(ISNUMBER($BW6),"C "&TRIM(TEXT($BW6,"# ?/??"))&CHAR(34)&" ","")&IF(ISNUMBER($BX6),"D "&TRIM(TEXT($BX6,"# ?/??"))&CHAR(34)&" ","")&IF(ISNUMBER($BY6),"F "&TRIM(TEXT($BY6,"# ?/??"))&CHAR(34)&" ","")&IF(ISNUMBER($BZ6),"E "&TRIM(TEXT($BZ6,"# ?/??"))&CHAR(34)&" ",""))) | CZ6: =IF(OR($CS6,N($BJ6)=0),"",TRIM(IF(ISNUMBER($BU6),"A "&TRIM(TEXT($BU6-HeadClr,"# ?/??"))&CHAR(34)&" ","")&IF(ISNUMBER($BV6),"B "&TRIM(TEXT($BV6-HeadClr,"# ?/??"))&CHAR(34)&" ","")&IF(ISNUMBER($BW6),"C "&TRIM(TEXT($BW6-HeadClr,"# ?/??"))&CHAR(34)&" ","")&IF(ISNUMBER($BX6),"D "&TRIM(TEXT($BX6-HeadClr,"# ?/??"))&CHAR(34)&" ","")&IF(ISNUMBER($BY6),"F "&TRIM(TEXT($BY6-HeadClr,"# ?/??"))&CHAR(34)&" ","")&IF(ISNUMBER($BZ6),"E "&TRIM(TEXT($BZ6-HeadClr,"# ?/??"))&CHAR(34)&" ",""))) | DA6: =IF($A6="","",IF($AN6="",IFERROR(VLOOKUP($Z6,CODES,2,FALSE),""),IFERROR(VLOOKUP($AN6,CODES,2,FALSE),""))) | DB6: =IF($A6="","",IF($O6="Y","PR",IF(OR($Z6="L",$Z6="RR",LEFT($Z6,2)="L-",LEFT($Z6,3)="RR-"),"LH","RH"))) | DC6: =IF($A6="","","S.HM"&IF(OR($C6="DOOR ONLY",$X6<>"KD"),"MASONRY","DRYWALL")&IF($C6="DOOR ONLY","",$U6)&IF(AND($C6<>"FRAME ONLY",OR(LEFT($AH6,3)="OAK",LEFT($AH6,3)="BIR",LEFT($AH6,3)="MAP",$AH6="PC",$AH6="MC",$AH6="SCLC",$AH6="P-LAM")),"WD","HM")&"1.75") | DD6: =IF($CJ6="","",IF($O6="Y",$CJ6,SUBSTITUTE($CJ6,$BG6&" "&IFERROR(VLOOKUP($Z6,CODES,2,FALSE),"")&" ",$BG6&" "))) | DE6: =IF($CK6="","",IF($O6="Y",$CK6,SUBSTITUTE($CK6,$BG6&" "&IF($AN6="",IFERROR(VLOOKUP($Z6,CODES,2,FALSE),""),IFERROR(VLOOKUP($AN6,CODES,2,FALSE),""))&" ",$BG6&" "))) | DF6: =IF($CJ6="","",$DC6&"|"&$DD6&"|"&$DB6&"|"&$AT6&"|"&$V6&"|"&$Y6&"|"&$AB6) | DG6: =IF(DF6="","",IF(COUNTIF($DF$6:DF6,DF6)=1,MAX($DG$5:DG5)+1,INDEX($DG$5:DG5,MATCH(DF6,$DF$5:DF5,0)))) | DH6: =IF($CK6="","",$DC6&"|"&$DE6&"|"&$AI6&"|"&$BK6&"|"&$BL6) | DI6: =IF(DH6="","",IF(COUNTIF($DH$6:DH6,DH6)=1,MAX($DI$5:DI5)+1,INDEX($DI$5:DI5,MATCH(DH6,$DH$5:DH5,0)))) | DJ6: =IF($A6="","",IF($B6="","qty, ","")&IF($C6="","scope, ","")&IF(OR($K6="",$M6=""),"size, ","")&IF(AND($A6<>"",$C6<>"DOOR ONLY"),IF($U6="","jamb depth, ","")&IF($X6="","construction, ","")&IF($Y6="","anchor, ","")&IF($S6="","frame type, ",""),"")&IF(AND(N($BJ6)>0,$Z6=""),"hand, ","")&IF(N($BJ6)>0,IF($AH6="","door material, ","")&IF($AL6="","face type, ","")&IF($AP6="","lock prep, ","")&IF(AND($AO6="",$AC6=""),"hinge prep, ",""),"")&IF(AND($CH6>0,$AH6="FRP"),"FRP cannot carry a label, ","")&IF(AND($O6="Y",OR($Z6="L",$Z6="R",$Z6="LR",$Z6="RR")),"pair marked but hand is single, ","")&IF(AND($O6<>"Y",OR($Z6="PR",AND(LEN($Z6)>1,ISNUMBER(SEARCH("-",$Z6))))),"pair hand on a single door, ","")&IF(AND(ISNUMBER($CI6),$CH6<N($CI6)),"wall needs a "&$CI6&" min door, ","")&IF(AND($CH6>=180,AND(OR($CE6="FG",$CE6="HG",$CE6="FNV",$CE6="FV"),N($CF6)*N($CG6)>100)),"180 min lite over 100 sq in, ","")&IF(N($BK6)>48,"leaf wider than 4'-0"&CHAR(34)&", ","")&IF(AND($CT6,COUNT($AW6:$AZ6)=0,$CQ6>0),"CUSTOM LOC with no locations typed, ","")) | DK6: =IF($A6="","",IF(AND($CH6>0,AND($A6<>"",$C6<>"DOOR ONLY"),$X6="KD",$E6="EXTERIOR"),"KD label on an exterior opening, ","")&IF(AND($E6="EXTERIOR",OR(AND(AND($A6<>"",$C6<>"DOOR ONLY"),$W6="CR"),AND(N($BJ6)>0,$AH6="CR"))),"exterior in CR steel (G9?), ","")&IF(AND(ISNUMBER($BQ6),N($BQ6)<32),"clear width ~"&TEXT($BQ6,"0.0")&CHAR(34)&" under 32"&CHAR(34)&" (ADA), ","")&IF(AND($CH6=90,AND(OR($CE6="FG",$CE6="HG",$CE6="FNV",$CE6="FV"),N($CF6)*N($CG6)>100)),"90 min lite over 100 sq in (stair/exit), ","")&IF(AND($CH6>0,AND($A6<>"",$C6<>"DOOR ONLY"),OR($AF6="",$AF6="-")),"rated: closer reinf.?, ","")&IF(OR($I6="CORRIDOR",$I6="SMOKE BARRIER"),"S label + smoke gasketing, ","")&IF($CI6="?","wall type/hr not in IBC table, ","")&IF(AND(N($BJ6)>0,$BB6=""),"no hardware set, ","")&IF(AND($BB6<>"",ISNA(MATCH($BB6&"",HWSets,0))),"set "&$BB6&" not on HW Sets, ","")&IF(N($BL6)>96,"leaf over 8'-0"&CHAR(34)&" - check listing, ","")&IF(AND($CT6,COUNT($AW6:$AZ6)>0,COUNT($AW6:$AZ6)<>$CQ6),COUNT($AW6:$AZ6)&" custom hinges typed, "&$CQ6&" expected, ","")&IF(AND(ISNUMBER($CA6),OR(N($CA6)<34,N($CA6)>48)),"lock "&TEXT($CA6,"0.0")&CHAR(34)&" AFF outside 34-48"&CHAR(34)&" (ADA), ","")&IF(AND(ISNUMBER($AV6),ISNUMBER($BL6),N($AV6)<IF(N($BL6)<=60,2,IF(N($BL6)<=90,3,IF(N($BL6)<=120,4,5)))),"fewer hinges than standard, ",""))
A7: 102 | B7: 4 | C7: FRAME & DOOR | D7: 1st | E7: INTERIOR | F7: OFFICE | G7: STORAGE | H7: NO LAB | I7: NON-RATED | K7: 3 | L7: 0 | M7: 7 | N7: 0 | S7: 3F | T7: M | U7: 478 | V7: 16 | W7: CR | X7: KD | Y7: SC | Z7: LR | AA7: CU | AC7: U453 | AD7: E1 | AH7: OAK-PC | AJ7: PC | AK7: RNB | AL7: FLUSH | AP7: G2 | AT7: CUSTOM LOC | AW7: 7 | AX7: 38 | AY7: 69 | BA7: 43.5 | BB7: 1 | BD7: =IF($A7="","",IF($DJ7<>"","FIX",IF($DK7<>"","CHECK","OK"))) | BE7: =IF($A7="","",IF($DJ7<>"","FIX: "&LEFT($DJ7,LEN($DJ7)-2)&IF($DK7<>""," · ",""),"")&IF($DK7<>"","CHECK: "&LEFT($DK7,LEN($DK7)-2),"")) | BF7: =IF(OR($A7="",$K7=""),"",$K7&"'-"&N($L7)&CHAR(34)&" x "&$M7&"'-"&N($N7)&CHAR(34)) | BG7: =IF(OR($A7="",$K7=""),"",$K7&N($L7)&$M7&N($N7)) | BH7: =IF(OR($A7="",$K7=""),"",$K7*12+N($L7)) | BI7: =IF(OR($A7="",$M7=""),"",$M7*12+N($N7)) | BJ7: =IF($A7="","",IF(OR($C7="FRAME ONLY",$S7="BL"),0,IF($O7="Y",2,1))) | BK7: =IF(OR(N($BJ7)=0,$BH7=""),"",($BH7-2*EdgeClr-IF($BJ7=2,MeetClr,0))/$BJ7) | BL7: =IF(OR(N($BJ7)=0,$BI7=""),"",$BI7-HeadClr-Undercut) | BM7: =IF($BH7="","",$BH7+2*FaceW+IF(N($Q7)>0,($Q7+FaceW)*IF($R7="LR",2,1),0)) | BN7: =IF($BI7="","",$BI7+IF($AB7="Y",4,FaceW)+IF(N($P7)>0,$P7+FaceW,0)+IF(OR($S7="4F",$S7="BL"),FaceW,0)) | BO7: =IF($BM7="","",$BM7+2*ROSide) | BP7: =IF($BN7="","",$BN7+ROTop) | BQ7: =IF(OR(N($BJ7)=0,$BH7=""),"",$BH7/$BJ7-ClearDeduct) | BR7: =IF(N($CH7)=0,"",IF($CH7>=180,"A · 3 HR",IF($CH7>=90,"B · 1-1/2 HR",IF($CH7>=60,"B · 1 HR",IF($CH7>=45,"C · 3/4 HR","20 MIN")))))&IF(AND(N($CH7)>0,OR($I7="CORRIDOR",$I7="SMOKE BARRIER"))," · S","") | BS7: =IF($CS7,"",IF($AV7<>"",$AV7,IF(OR($AC7="HGC",$AO7="HGC"),"CONT",IF(($BI7-HeadClr-Undercut)<=60,2,IF(($BI7-HeadClr-Undercut)<=90,3,IF(($BI7-HeadClr-Undercut)<=120,4,5)))))) | BT7: =IF($CS7,"",IF($CT7,"CUSTOM (typed)",IF($CV7,$AT7&" "&$CU7&CHAR(34)&IF($CU7<>$BI7,IF(AND($BI7<$CU7,$BI7-IF(N(VLOOKUP($AT7&"|"&$CU7,LocTable,7,FALSE))>0,VLOOKUP($AT7&"|"&$CU7,LocTable,7,FALSE),VLOOKUP($AT7&"|"&$CU7,LocTable,6,FALSE))-$CR7-0.75>=2.125)," cut down"," adj."),""),"ANSI/SDI A250.6"))) | BU7: =IF($CS7,"",IF($CT7,IF(N($AW7)>0,N($AW7),""),IF(1>$CQ7,"",IF($CQ7=1,$CW7,$CW7+($CX7-$CW7)*0/($CQ7-1))))) | BV7: =IF($CS7,"",IF($CT7,IF(N($AX7)>0,N($AX7),""),IF(2>$CQ7,"",IF($CQ7=1,$CW7,$CW7+($CX7-$CW7)*1/($CQ7-1))))) | BW7: =IF($CS7,"",IF($CT7,IF(N($AY7)>0,N($AY7),""),IF(3>$CQ7,"",IF($CQ7=1,$CW7,$CW7+($CX7-$CW7)*2/($CQ7-1))))) | BX7: =IF($CS7,"",IF($CT7,IF(N($AZ7)>0,N($AZ7),""),IF(4>$CQ7,"",IF($CQ7=1,$CW7,$CW7+($CX7-$CW7)*3/($CQ7-1))))) | BY7: =IF($CS7,"",IF($CT7,"",IF(5>$CQ7,"",IF($CQ7=1,$CW7,$CW7+($CX7-$CW7)*4/($CQ7-1))))) | BZ7: =IF(OR($CS7,$AP7="-",AND($AP7="",$AD7="")),"",IF(N($BA7)>0,N($BA7),IF($CV7,IF(AND($BI7<$CU7,$BI7-IF(N(VLOOKUP($AT7&"|"&$CU7,LocTable,7,FALSE))>0,VLOOKUP($AT7&"|"&$CU7,LocTable,7,FALSE),VLOOKUP($AT7&"|"&$CU7,LocTable,6,FALSE))-$CR7-0.75>=2.125),VLOOKUP($AT7&"|"&$CU7,LocTable,8,FALSE),VLOOKUP($AT7&"|"&$CU7,LocTable,8,FALSE)+($BI7-$CU7)),$BI7-LockAFF))) | CA7: =IF($BZ7="","",$BI7-$BZ7) | CB7: =IF(OR(NOT(AND($A7<>"",$C7<>"DOOR ONLY")),$BI7=""),"",IF(($BI7+IF(N($P7)>0,$P7+FaceW,0))<=90,3,IF(($BI7+IF(N($P7)>0,$P7+FaceW,0))<=114,4,5))) | CC7: =IF($CB7="","",$CB7*(2+IF(N($Q7)>0,IF($R7="LR",2,1),0))) | CD7: =IF($CB7="","",(2+IF(N($Q7)>0,IF($R7="LR",2,1),0))) | CE7: =IF(N($BJ7)=0,"",IF(OR($AL7="",$AL7="FLUSH"),"FLUSH",IFERROR(LEFT($AL7,FIND("-",$AL7)-1),LEFT($AL7,2)))) | CF7: =IF($CE7="","",IFERROR(VALUE(MID($AL7,FIND("-",$AL7)+1,FIND(CHAR(34)&"x",$AL7)-FIND("-",$AL7)-1)),0)) | CG7: =IF($CE7="","",IFERROR(VALUE(MID($AL7,FIND(CHAR(34)&"x",$AL7)+2,FIND(CHAR(34),$AL7,FIND(CHAR(34)&"x",$AL7)+2)-FIND(CHAR(34)&"x",$AL7)-2)),0)) | CH7: =IF(OR($A7="",$H7="",$H7="NO LAB"),0,IFERROR(VALUE(LEFT($H7,FIND(" ",$H7)-1)),0)) | CI7: =IF(OR($A7="",$I7="",$I7="NON-RATED",N($J7)=0),"",IFERROR(VLOOKUP($I7&"|"&$J7,IBC,2,FALSE),"?")) | CJ7: =IF(NOT(AND($A7<>"",$C7<>"DOOR ONLY")),"",TRIM(IFERROR(VLOOKUP($U7,CODES,2,FALSE),"")&" "&$BG7&" "&IFERROR(VLOOKUP($Z7,CODES,2,FALSE),"")&" "&IFERROR(VLOOKUP($X7,CODES,2,FALSE),"")&" "&IFERROR(VLOOKUP($S7,CODES,2,FALSE),"")&IF(N($P7)>0," w/TRANSOM "&$P7&CHAR(34),"")&IF(N($Q7)>0," w/SIDELITE "&$Q7&CHAR(34)&" "&IF($R7="","R",$R7),"")&IF($Y7=""," | "," | "&IFERROR(VLOOKUP($Y7,CODES,2,FALSE),"")&" | ")&IFERROR(VLOOKUP($AC7,CODES,2,FALSE),"")&" "&IFERROR(VLOOKUP($AD7,CODES,2,FALSE),"")&IF(OR($AE7="",$AE7="-"),""," "&$AE7)&IF(OR($AF7="",$AF7="-"),""," "&$AF7)&IF($AB7="Y"," 4"&CHAR(34)&" HEAD","")&" "&IFERROR(VLOOKUP($H7,CODES,2,FALSE),"")&IF($CT7," | LOC "&$CY7,""))) | CK7: =IF(NOT(AND($A7<>"",N($BJ7)>0)),"",TRIM(IFERROR(VLOOKUP($AH7,CODES,2,FALSE),"")&IF($AI7=""," "," "&$AI7&"GA ")&$BG7&" "&IF($AN7="",IFERROR(VLOOKUP($Z7,CODES,2,FALSE),""),IFERROR(VLOOKUP($AN7,CODES,2,FALSE),""))&IF($BJ7=2," PAIR","")&" DOOR | "&IF($AL7="","?",$AL7)&" | "&IF($AO7="",IFERROR(VLOOKUP($AC7,CODES,2,FALSE),""),IFERROR(VLOOKUP($AO7,CODES,2,FALSE),""))&" "&IFERROR(VLOOKUP($AP7,CODES,2,FALSE),"")&IF(OR($AQ7="",$AQ7="-"),""," SEAM "&$AQ7)&IF($AR7="Y"," ASTRAGAL","")&IF($AJ7=""," "," "&$AJ7)&IF($AK7=""," "," "&$AK7)&IF(OR($AT7="",$AT7="ANSI/SDI",$AT7="CUSTOM LOC"),""," "&$AT7)&IF($AM7=""," "," SERIES "&$AM7)&" "&IFERROR(VLOOKUP($H7,CODES,2,FALSE),"")&IF($CT7," | LOC "&$CZ7,""))) | CL7: =IF(CP7="","",IF(COUNTIF($CP$6:CP7,CP7)=1,MAX($CL$5:CL6)+1,INDEX($CL$5:CL6,MATCH(CP7,$CP$5:CP6,0)))) | CM7: =IF(NOT(AND($A7<>"",$C7<>"DOOR ONLY")),"",MAX($CM$5:CM6)+1) | CN7: =IF(NOT(AND($A7<>"",N($BJ7)>0)),"",MAX($CN$5:CN6)+1) | CO7: =IF($A7="","",MAX($CO$5:CO6)+1) | CP7: =IF(OR($A7="",$BH7="",$BI7=""),"",$BG7&"|"&$O7&"|"&$AL7&"|"&$S7&"|"&$P7&"|"&$Q7&$R7&"|"&$C7&"|"&$AB7) | CQ7: =N($BS7) | CR7: =IF(N($AU7)>0,N($AU7),4.5) | CS7: =OR($A7="",$BI7="",$S7="BL",AND($C7="FRAME ONLY",OR($AC7="",$AC7="BLK"))) | CT7: =AND(NOT($CS7),OR($AT7="CUSTOM LOC",N($AW7)+N($AX7)+N($AY7)+N($AZ7)+N($BA7)>0)) | CU7: =IF($BI7="","",IF($BI7<=80,80,IF($BI7<=84,84,96))) | CV7: =ISNUMBER(MATCH($AT7&"|80",LocKeys,0)) | CW7: =IF($CS7,"",IF($CV7,VLOOKUP($AT7&"|"&$CU7,LocTable,4,FALSE),5)) | CX7: =IF($CS7,"",IF($CV7,IF(OR($BI7=$CU7,AND($BI7<$CU7,$BI7-IF(N(VLOOKUP($AT7&"|"&$CU7,LocTable,7,FALSE))>0,VLOOKUP($AT7&"|"&$CU7,LocTable,7,FALSE),VLOOKUP($AT7&"|"&$CU7,LocTable,6,FALSE))-$CR7-0.75>=2.125)),IF(N(VLOOKUP($AT7&"|"&$CU7,LocTable,7,FALSE))>0,VLOOKUP($AT7&"|"&$CU7,LocTable,7,FALSE),VLOOKUP($AT7&"|"&$CU7,LocTable,6,FALSE)),$BI7-($CU7-IF(N(VLOOKUP($AT7&"|"&$CU7,LocTable,7,FALSE))>0,VLOOKUP($AT7&"|"&$CU7,LocTable,7,FALSE),VLOOKUP($AT7&"|"&$CU7,LocTable,6,FALSE)))),$BI7-10-$CR7)) | CY7: =IF($CS7,"",TRIM(IF(ISNUMBER($BU7),"A "&TRIM(TEXT($BU7,"# ?/??"))&CHAR(34)&" ","")&IF(ISNUMBER($BV7),"B "&TRIM(TEXT($BV7,"# ?/??"))&CHAR(34)&" ","")&IF(ISNUMBER($BW7),"C "&TRIM(TEXT($BW7,"# ?/??"))&CHAR(34)&" ","")&IF(ISNUMBER($BX7),"D "&TRIM(TEXT($BX7,"# ?/??"))&CHAR(34)&" ","")&IF(ISNUMBER($BY7),"F "&TRIM(TEXT($BY7,"# ?/??"))&CHAR(34)&" ","")&IF(ISNUMBER($BZ7),"E "&TRIM(TEXT($BZ7,"# ?/??"))&CHAR(34)&" ",""))) | CZ7: =IF(OR($CS7,N($BJ7)=0),"",TRIM(IF(ISNUMBER($BU7),"A "&TRIM(TEXT($BU7-HeadClr,"# ?/??"))&CHAR(34)&" ","")&IF(ISNUMBER($BV7),"B "&TRIM(TEXT($BV7-HeadClr,"# ?/??"))&CHAR(34)&" ","")&IF(ISNUMBER($BW7),"C "&TRIM(TEXT($BW7-HeadClr,"# ?/??"))&CHAR(34)&" ","")&IF(ISNUMBER($BX7),"D "&TRIM(TEXT($BX7-HeadClr,"# ?/??"))&CHAR(34)&" ","")&IF(ISNUMBER($BY7),"F "&TRIM(TEXT($BY7-HeadClr,"# ?/??"))&CHAR(34)&" ","")&IF(ISNUMBER($BZ7),"E "&TRIM(TEXT($BZ7-HeadClr,"# ?/??"))&CHAR(34)&" ",""))) | DA7: =IF($A7="","",IF($AN7="",IFERROR(VLOOKUP($Z7,CODES,2,FALSE),""),IFERROR(VLOOKUP($AN7,CODES,2,FALSE),""))) | DB7: =IF($A7="","",IF($O7="Y","PR",IF(OR($Z7="L",$Z7="RR",LEFT($Z7,2)="L-",LEFT($Z7,3)="RR-"),"LH","RH"))) | DC7: =IF($A7="","","S.HM"&IF(OR($C7="DOOR ONLY",$X7<>"KD"),"MASONRY","DRYWALL")&IF($C7="DOOR ONLY","",$U7)&IF(AND($C7<>"FRAME ONLY",OR(LEFT($AH7,3)="OAK",LEFT($AH7,3)="BIR",LEFT($AH7,3)="MAP",$AH7="PC",$AH7="MC",$AH7="SCLC",$AH7="P-LAM")),"WD","HM")&"1.75") | DD7: =IF($CJ7="","",IF($O7="Y",$CJ7,SUBSTITUTE($CJ7,$BG7&" "&IFERROR(VLOOKUP($Z7,CODES,2,FALSE),"")&" ",$BG7&" "))) | DE7: =IF($CK7="","",IF($O7="Y",$CK7,SUBSTITUTE($CK7,$BG7&" "&IF($AN7="",IFERROR(VLOOKUP($Z7,CODES,2,FALSE),""),IFERROR(VLOOKUP($AN7,CODES,2,FALSE),""))&" ",$BG7&" "))) | DF7: =IF($CJ7="","",$DC7&"|"&$DD7&"|"&$DB7&"|"&$AT7&"|"&$V7&"|"&$Y7&"|"&$AB7) | DG7: =IF(DF7="","",IF(COUNTIF($DF$6:DF7,DF7)=1,MAX($DG$5:DG6)+1,INDEX($DG$5:DG6,MATCH(DF7,$DF$5:DF6,0)))) | DH7: =IF($CK7="","",$DC7&"|"&$DE7&"|"&$AI7&"|"&$BK7&"|"&$BL7) | DI7: =IF(DH7="","",IF(COUNTIF($DH$6:DH7,DH7)=1,MAX($DI$5:DI6)+1,INDEX($DI$5:DI6,MATCH(DH7,$DH$5:DH6,0)))) | DJ7: =IF($A7="","",IF($B7="","qty, ","")&IF($C7="","scope, ","")&IF(OR($K7="",$M7=""),"size, ","")&IF(AND($A7<>"",$C7<>"DOOR ONLY"),IF($U7="","jamb depth, ","")&IF($X7="","construction, ","")&IF($Y7="","anchor, ","")&IF($S7="","frame type, ",""),"")&IF(AND(N($BJ7)>0,$Z7=""),"hand, ","")&IF(N($BJ7)>0,IF($AH7="","door material, ","")&IF($AL7="","face type, ","")&IF($AP7="","lock prep, ","")&IF(AND($AO7="",$AC7=""),"hinge prep, ",""),"")&IF(AND($CH7>0,$AH7="FRP"),"FRP cannot carry a label, ","")&IF(AND($O7="Y",OR($Z7="L",$Z7="R",$Z7="LR",$Z7="RR")),"pair marked but hand is single, ","")&IF(AND($O7<>"Y",OR($Z7="PR",AND(LEN($Z7)>1,ISNUMBER(SEARCH("-",$Z7))))),"pair hand on a single door, ","")&IF(AND(ISNUMBER($CI7),$CH7<N($CI7)),"wall needs a "&$CI7&" min door, ","")&IF(AND($CH7>=180,AND(OR($CE7="FG",$CE7="HG",$CE7="FNV",$CE7="FV"),N($CF7)*N($CG7)>100)),"180 min lite over 100 sq in, ","")&IF(N($BK7)>48,"leaf wider than 4'-0"&CHAR(34)&", ","")&IF(AND($CT7,COUNT($AW7:$AZ7)=0,$CQ7>0),"CUSTOM LOC with no locations typed, ","")) | DK7: =IF($A7="","",IF(AND($CH7>0,AND($A7<>"",$C7<>"DOOR ONLY"),$X7="KD",$E7="EXTERIOR"),"KD label on an exterior opening, ","")&IF(AND($E7="EXTERIOR",OR(AND(AND($A7<>"",$C7<>"DOOR ONLY"),$W7="CR"),AND(N($BJ7)>0,$AH7="CR"))),"exterior in CR steel (G9?), ","")&IF(AND(ISNUMBER($BQ7),N($BQ7)<32),"clear width ~"&TEXT($BQ7,"0.0")&CHAR(34)&" under 32"&CHAR(34)&" (ADA), ","")&IF(AND($CH7=90,AND(OR($CE7="FG",$CE7="HG",$CE7="FNV",$CE7="FV"),N($CF7)*N($CG7)>100)),"90 min lite over 100 sq in (stair/exit), ","")&IF(AND($CH7>0,AND($A7<>"",$C7<>"DOOR ONLY"),OR($AF7="",$AF7="-")),"rated: closer reinf.?, ","")&IF(OR($I7="CORRIDOR",$I7="SMOKE BARRIER"),"S label + smoke gasketing, ","")&IF($CI7="?","wall type/hr not in IBC table, ","")&IF(AND(N($BJ7)>0,$BB7=""),"no hardware set, ","")&IF(AND($BB7<>"",ISNA(MATCH($BB7&"",HWSets,0))),"set "&$BB7&" not on HW Sets, ","")&IF(N($BL7)>96,"leaf over 8'-0"&CHAR(34)&" - check listing, ","")&IF(AND($CT7,COUNT($AW7:$AZ7)>0,COUNT($AW7:$AZ7)<>$CQ7),COUNT($AW7:$AZ7)&" custom hinges typed, "&$CQ7&" expected, ","")&IF(AND(ISNUMBER($CA7),OR(N($CA7)<34,N($CA7)>48)),"lock "&TEXT($CA7,"0.0")&CHAR(34)&" AFF outside 34-48"&CHAR(34)&" (ADA), ","")&IF(AND(ISNUMBER($AV7),ISNUMBER($BL7),N($AV7)<IF(N($BL7)<=60,2,IF(N($BL7)<=90,3,IF(N($BL7)<=120,4,5)))),"fewer hinges than standard, ",""))
A8: 103 | B8: 1 | C8: FRAME & DOOR | D8: 1st | E8: INTERIOR | F8: CORRIDOR | G8: STAIR 1 | H8: 90 MIN | I8: SHAFT / EXIT ENCL. | J8: 2 | K8: 6 | L8: 0 | M8: 7 | N8: 0 | O8: Y | S8: 3F | T8: M | U8: 834 | V8: 14 | W8: CR | X8: WGS | Y8: T | Z8: RR-A | AA8: CU | AC8: U454 | AD8: E1 | AE8: H5 | AF8: E11 | AH8: CR | AI8: 16 | AL8: HG-24"x30" | AM8: 707 | AP8: G12 | AQ8: - | AR8: Y | AT8: CURRIES | AU8: 4.5 | BB8: 2 | BD8: =IF($A8="","",IF($DJ8<>"","FIX",IF($DK8<>"","CHECK","OK"))) | BE8: =IF($A8="","",IF($DJ8<>"","FIX: "&LEFT($DJ8,LEN($DJ8)-2)&IF($DK8<>""," · ",""),"")&IF($DK8<>"","CHECK: "&LEFT($DK8,LEN($DK8)-2),"")) | BF8: =IF(OR($A8="",$K8=""),"",$K8&"'-"&N($L8)&CHAR(34)&" x "&$M8&"'-"&N($N8)&CHAR(34)) | BG8: =IF(OR($A8="",$K8=""),"",$K8&N($L8)&$M8&N($N8)) | BH8: =IF(OR($A8="",$K8=""),"",$K8*12+N($L8)) | BI8: =IF(OR($A8="",$M8=""),"",$M8*12+N($N8)) | BJ8: =IF($A8="","",IF(OR($C8="FRAME ONLY",$S8="BL"),0,IF($O8="Y",2,1))) | BK8: =IF(OR(N($BJ8)=0,$BH8=""),"",($BH8-2*EdgeClr-IF($BJ8=2,MeetClr,0))/$BJ8) | BL8: =IF(OR(N($BJ8)=0,$BI8=""),"",$BI8-HeadClr-Undercut) | BM8: =IF($BH8="","",$BH8+2*FaceW+IF(N($Q8)>0,($Q8+FaceW)*IF($R8="LR",2,1),0)) | BN8: =IF($BI8="","",$BI8+IF($AB8="Y",4,FaceW)+IF(N($P8)>0,$P8+FaceW,0)+IF(OR($S8="4F",$S8="BL"),FaceW,0)) | BO8: =IF($BM8="","",$BM8+2*ROSide) | BP8: =IF($BN8="","",$BN8+ROTop) | BQ8: =IF(OR(N($BJ8)=0,$BH8=""),"",$BH8/$BJ8-ClearDeduct) | BR8: =IF(N($CH8)=0,"",IF($CH8>=180,"A · 3 HR",IF($CH8>=90,"B · 1-1/2 HR",IF($CH8>=60,"B · 1 HR",IF($CH8>=45,"C · 3/4 HR","20 MIN")))))&IF(AND(N($CH8)>0,OR($I8="CORRIDOR",$I8="SMOKE BARRIER"))," · S","") | BS8: =IF($CS8,"",IF($AV8<>"",$AV8,IF(OR($AC8="HGC",$AO8="HGC"),"CONT",IF(($BI8-HeadClr-Undercut)<=60,2,IF(($BI8-HeadClr-Undercut)<=90,3,IF(($BI8-HeadClr-Undercut)<=120,4,5)))))) | BT8: =IF($CS8,"",IF($CT8,"CUSTOM (typed)",IF($CV8,$AT8&" "&$CU8&CHAR(34)&IF($CU8<>$BI8,IF(AND($BI8<$CU8,$BI8-IF(N(VLOOKUP($AT8&"|"&$CU8,LocTable,7,FALSE))>0,VLOOKUP($AT8&"|"&$CU8,LocTable,7,FALSE),VLOOKUP($AT8&"|"&$CU8,LocTable,6,FALSE))-$CR8-0.75>=2.125)," cut down"," adj."),""),"ANSI/SDI A250.6"))) | BU8: =IF($CS8,"",IF($CT8,IF(N($AW8)>0,N($AW8),""),IF(1>$CQ8,"",IF($CQ8=1,$CW8,$CW8+($CX8-$CW8)*0/($CQ8-1))))) | BV8: =IF($CS8,"",IF($CT8,IF(N($AX8)>0,N($AX8),""),IF(2>$CQ8,"",IF($CQ8=1,$CW8,$CW8+($CX8-$CW8)*1/($CQ8-1))))) | BW8: =IF($CS8,"",IF($CT8,IF(N($AY8)>0,N($AY8),""),IF(3>$CQ8,"",IF($CQ8=1,$CW8,$CW8+($CX8-$CW8)*2/($CQ8-1))))) | BX8: =IF($CS8,"",IF($CT8,IF(N($AZ8)>0,N($AZ8),""),IF(4>$CQ8,"",IF($CQ8=1,$CW8,$CW8+($CX8-$CW8)*3/($CQ8-1))))) | BY8: =IF($CS8,"",IF($CT8,"",IF(5>$CQ8,"",IF($CQ8=1,$CW8,$CW8+($CX8-$CW8)*4/($CQ8-1))))) | BZ8: =IF(OR($CS8,$AP8="-",AND($AP8="",$AD8="")),"",IF(N($BA8)>0,N($BA8),IF($CV8,IF(AND($BI8<$CU8,$BI8-IF(N(VLOOKUP($AT8&"|"&$CU8,LocTable,7,FALSE))>0,VLOOKUP($AT8&"|"&$CU8,LocTable,7,FALSE),VLOOKUP($AT8&"|"&$CU8,LocTable,6,FALSE))-$CR8-0.75>=2.125),VLOOKUP($AT8&"|"&$CU8,LocTable,8,FALSE),VLOOKUP($AT8&"|"&$CU8,LocTable,8,FALSE)+($BI8-$CU8)),$BI8-LockAFF))) | CA8: =IF($BZ8="","",$BI8-$BZ8) | CB8: =IF(OR(NOT(AND($A8<>"",$C8<>"DOOR ONLY")),$BI8=""),"",IF(($BI8+IF(N($P8)>0,$P8+FaceW,0))<=90,3,IF(($BI8+IF(N($P8)>0,$P8+FaceW,0))<=114,4,5))) | CC8: =IF($CB8="","",$CB8*(2+IF(N($Q8)>0,IF($R8="LR",2,1),0))) | CD8: =IF($CB8="","",(2+IF(N($Q8)>0,IF($R8="LR",2,1),0))) | CE8: =IF(N($BJ8)=0,"",IF(OR($AL8="",$AL8="FLUSH"),"FLUSH",IFERROR(LEFT($AL8,FIND("-",$AL8)-1),LEFT($AL8,2)))) | CF8: =IF($CE8="","",IFERROR(VALUE(MID($AL8,FIND("-",$AL8)+1,FIND(CHAR(34)&"x",$AL8)-FIND("-",$AL8)-1)),0)) | CG8: =IF($CE8="","",IFERROR(VALUE(MID($AL8,FIND(CHAR(34)&"x",$AL8)+2,FIND(CHAR(34),$AL8,FIND(CHAR(34)&"x",$AL8)+2)-FIND(CHAR(34)&"x",$AL8)-2)),0)) | CH8: =IF(OR($A8="",$H8="",$H8="NO LAB"),0,IFERROR(VALUE(LEFT($H8,FIND(" ",$H8)-1)),0)) | CI8: =IF(OR($A8="",$I8="",$I8="NON-RATED",N($J8)=0),"",IFERROR(VLOOKUP($I8&"|"&$J8,IBC,2,FALSE),"?")) | CJ8: =IF(NOT(AND($A8<>"",$C8<>"DOOR ONLY")),"",TRIM(IFERROR(VLOOKUP($U8,CODES,2,FALSE),"")&" "&$BG8&" "&IFERROR(VLOOKUP($Z8,CODES,2,FALSE),"")&" "&IFERROR(VLOOKUP($X8,CODES,2,FALSE),"")&" "&IFERROR(VLOOKUP($S8,CODES,2,FALSE),"")&IF(N($P8)>0," w/TRANSOM "&$P8&CHAR(34),"")&IF(N($Q8)>0," w/SIDELITE "&$Q8&CHAR(34)&" "&IF($R8="","R",$R8),"")&IF($Y8=""," | "," | "&IFERROR(VLOOKUP($Y8,CODES,2,FALSE),"")&" | ")&IFERROR(VLOOKUP($AC8,CODES,2,FALSE),"")&" "&IFERROR(VLOOKUP($AD8,CODES,2,FALSE),"")&IF(OR($AE8="",$AE8="-"),""," "&$AE8)&IF(OR($AF8="",$AF8="-"),""," "&$AF8)&IF($AB8="Y"," 4"&CHAR(34)&" HEAD","")&" "&IFERROR(VLOOKUP($H8,CODES,2,FALSE),"")&IF($CT8," | LOC "&$CY8,""))) | CK8: =IF(NOT(AND($A8<>"",N($BJ8)>0)),"",TRIM(IFERROR(VLOOKUP($AH8,CODES,2,FALSE),"")&IF($AI8=""," "," "&$AI8&"GA ")&$BG8&" "&IF($AN8="",IFERROR(VLOOKUP($Z8,CODES,2,FALSE),""),IFERROR(VLOOKUP($AN8,CODES,2,FALSE),""))&IF($BJ8=2," PAIR","")&" DOOR | "&IF($AL8="","?",$AL8)&" | "&IF($AO8="",IFERROR(VLOOKUP($AC8,CODES,2,FALSE),""),IFERROR(VLOOKUP($AO8,CODES,2,FALSE),""))&" "&IFERROR(VLOOKUP($AP8,CODES,2,FALSE),"")&IF(OR($AQ8="",$AQ8="-"),""," SEAM "&$AQ8)&IF($AR8="Y"," ASTRAGAL","")&IF($AJ8=""," "," "&$AJ8)&IF($AK8=""," "," "&$AK8)&IF(OR($AT8="",$AT8="ANSI/SDI",$AT8="CUSTOM LOC"),""," "&$AT8)&IF($AM8=""," "," SERIES "&$AM8)&" "&IFERROR(VLOOKUP($H8,CODES,2,FALSE),"")&IF($CT8," | LOC "&$CZ8,""))) | CL8: =IF(CP8="","",IF(COUNTIF($CP$6:CP8,CP8)=1,MAX($CL$5:CL7)+1,INDEX($CL$5:CL7,MATCH(CP8,$CP$5:CP7,0)))) | CM8: =IF(NOT(AND($A8<>"",$C8<>"DOOR ONLY")),"",MAX($CM$5:CM7)+1) | CN8: =IF(NOT(AND($A8<>"",N($BJ8)>0)),"",MAX($CN$5:CN7)+1) | CO8: =IF($A8="","",MAX($CO$5:CO7)+1) | CP8: =IF(OR($A8="",$BH8="",$BI8=""),"",$BG8&"|"&$O8&"|"&$AL8&"|"&$S8&"|"&$P8&"|"&$Q8&$R8&"|"&$C8&"|"&$AB8) | CQ8: =N($BS8) | CR8: =IF(N($AU8)>0,N($AU8),4.5) | CS8: =OR($A8="",$BI8="",$S8="BL",AND($C8="FRAME ONLY",OR($AC8="",$AC8="BLK"))) | CT8: =AND(NOT($CS8),OR($AT8="CUSTOM LOC",N($AW8)+N($AX8)+N($AY8)+N($AZ8)+N($BA8)>0)) | CU8: =IF($BI8="","",IF($BI8<=80,80,IF($BI8<=84,84,96))) | CV8: =ISNUMBER(MATCH($AT8&"|80",LocKeys,0)) | CW8: =IF($CS8,"",IF($CV8,VLOOKUP($AT8&"|"&$CU8,LocTable,4,FALSE),5)) | CX8: =IF($CS8,"",IF($CV8,IF(OR($BI8=$CU8,AND($BI8<$CU8,$BI8-IF(N(VLOOKUP($AT8&"|"&$CU8,LocTable,7,FALSE))>0,VLOOKUP($AT8&"|"&$CU8,LocTable,7,FALSE),VLOOKUP($AT8&"|"&$CU8,LocTable,6,FALSE))-$CR8-0.75>=2.125)),IF(N(VLOOKUP($AT8&"|"&$CU8,LocTable,7,FALSE))>0,VLOOKUP($AT8&"|"&$CU8,LocTable,7,FALSE),VLOOKUP($AT8&"|"&$CU8,LocTable,6,FALSE)),$BI8-($CU8-IF(N(VLOOKUP($AT8&"|"&$CU8,LocTable,7,FALSE))>0,VLOOKUP($AT8&"|"&$CU8,LocTable,7,FALSE),VLOOKUP($AT8&"|"&$CU8,LocTable,6,FALSE)))),$BI8-10-$CR8)) | CY8: =IF($CS8,"",TRIM(IF(ISNUMBER($BU8),"A "&TRIM(TEXT($BU8,"# ?/??"))&CHAR(34)&" ","")&IF(ISNUMBER($BV8),"B "&TRIM(TEXT($BV8,"# ?/??"))&CHAR(34)&" ","")&IF(ISNUMBER($BW8),"C "&TRIM(TEXT($BW8,"# ?/??"))&CHAR(34)&" ","")&IF(ISNUMBER($BX8),"D "&TRIM(TEXT($BX8,"# ?/??"))&CHAR(34)&" ","")&IF(ISNUMBER($BY8),"F "&TRIM(TEXT($BY8,"# ?/??"))&CHAR(34)&" ","")&IF(ISNUMBER($BZ8),"E "&TRIM(TEXT($BZ8,"# ?/??"))&CHAR(34)&" ",""))) | CZ8: =IF(OR($CS8,N($BJ8)=0),"",TRIM(IF(ISNUMBER($BU8),"A "&TRIM(TEXT($BU8-HeadClr,"# ?/??"))&CHAR(34)&" ","")&IF(ISNUMBER($BV8),"B "&TRIM(TEXT($BV8-HeadClr,"# ?/??"))&CHAR(34)&" ","")&IF(ISNUMBER($BW8),"C "&TRIM(TEXT($BW8-HeadClr,"# ?/??"))&CHAR(34)&" ","")&IF(ISNUMBER($BX8),"D "&TRIM(TEXT($BX8-HeadClr,"# ?/??"))&CHAR(34)&" ","")&IF(ISNUMBER($BY8),"F "&TRIM(TEXT($BY8-HeadClr,"# ?/??"))&CHAR(34)&" ","")&IF(ISNUMBER($BZ8),"E "&TRIM(TEXT($BZ8-HeadClr,"# ?/??"))&CHAR(34)&" ",""))) | DA8: =IF($A8="","",IF($AN8="",IFERROR(VLOOKUP($Z8,CODES,2,FALSE),""),IFERROR(VLOOKUP($AN8,CODES,2,FALSE),""))) | DB8: =IF($A8="","",IF($O8="Y","PR",IF(OR($Z8="L",$Z8="RR",LEFT($Z8,2)="L-",LEFT($Z8,3)="RR-"),"LH","RH"))) | DC8: =IF($A8="","","S.HM"&IF(OR($C8="DOOR ONLY",$X8<>"KD"),"MASONRY","DRYWALL")&IF($C8="DOOR ONLY","",$U8)&IF(AND($C8<>"FRAME ONLY",OR(LEFT($AH8,3)="OAK",LEFT($AH8,3)="BIR",LEFT($AH8,3)="MAP",$AH8="PC",$AH8="MC",$AH8="SCLC",$AH8="P-LAM")),"WD","HM")&"1.75") | DD8: =IF($CJ8="","",IF($O8="Y",$CJ8,SUBSTITUTE($CJ8,$BG8&" "&IFERROR(VLOOKUP($Z8,CODES,2,FALSE),"")&" ",$BG8&" "))) | DE8: =IF($CK8="","",IF($O8="Y",$CK8,SUBSTITUTE($CK8,$BG8&" "&IF($AN8="",IFERROR(VLOOKUP($Z8,CODES,2,FALSE),""),IFERROR(VLOOKUP($AN8,CODES,2,FALSE),""))&" ",$BG8&" "))) | DF8: =IF($CJ8="","",$DC8&"|"&$DD8&"|"&$DB8&"|"&$AT8&"|"&$V8&"|"&$Y8&"|"&$AB8) | DG8: =IF(DF8="","",IF(COUNTIF($DF$6:DF8,DF8)=1,MAX($DG$5:DG7)+1,INDEX($DG$5:DG7,MATCH(DF8,$DF$5:DF7,0)))) | DH8: =IF($CK8="","",$DC8&"|"&$DE8&"|"&$AI8&"|"&$BK8&"|"&$BL8) | DI8: =IF(DH8="","",IF(COUNTIF($DH$6:DH8,DH8)=1,MAX($DI$5:DI7)+1,INDEX($DI$5:DI7,MATCH(DH8,$DH$5:DH7,0)))) | DJ8: =IF($A8="","",IF($B8="","qty, ","")&IF($C8="","scope, ","")&IF(OR($K8="",$M8=""),"size, ","")&IF(AND($A8<>"",$C8<>"DOOR ONLY"),IF($U8="","jamb depth, ","")&IF($X8="","construction, ","")&IF($Y8="","anchor, ","")&IF($S8="","frame type, ",""),"")&IF(AND(N($BJ8)>0,$Z8=""),"hand, ","")&IF(N($BJ8)>0,IF($AH8="","door material, ","")&IF($AL8="","face type, ","")&IF($AP8="","lock prep, ","")&IF(AND($AO8="",$AC8=""),"hinge prep, ",""),"")&IF(AND($CH8>0,$AH8="FRP"),"FRP cannot carry a label, ","")&IF(AND($O8="Y",OR($Z8="L",$Z8="R",$Z8="LR",$Z8="RR")),"pair marked but hand is single, ","")&IF(AND($O8<>"Y",OR($Z8="PR",AND(LEN($Z8)>1,ISNUMBER(SEARCH("-",$Z8))))),"pair hand on a single door, ","")&IF(AND(ISNUMBER($CI8),$CH8<N($CI8)),"wall needs a "&$CI8&" min door, ","")&IF(AND($CH8>=180,AND(OR($CE8="FG",$CE8="HG",$CE8="FNV",$CE8="FV"),N($CF8)*N($CG8)>100)),"180 min lite over 100 sq in, ","")&IF(N($BK8)>48,"leaf wider than 4'-0"&CHAR(34)&", ","")&IF(AND($CT8,COUNT($AW8:$AZ8)=0,$CQ8>0),"CUSTOM LOC with no locations typed, ","")) | DK8: =IF($A8="","",IF(AND($CH8>0,AND($A8<>"",$C8<>"DOOR ONLY"),$X8="KD",$E8="EXTERIOR"),"KD label on an exterior opening, ","")&IF(AND($E8="EXTERIOR",OR(AND(AND($A8<>"",$C8<>"DOOR ONLY"),$W8="CR"),AND(N($BJ8)>0,$AH8="CR"))),"exterior in CR steel (G9?), ","")&IF(AND(ISNUMBER($BQ8),N($BQ8)<32),"clear width ~"&TEXT($BQ8,"0.0")&CHAR(34)&" under 32"&CHAR(34)&" (ADA), ","")&IF(AND($CH8=90,AND(OR($CE8="FG",$CE8="HG",$CE8="FNV",$CE8="FV"),N($CF8)*N($CG8)>100)),"90 min lite over 100 sq in (stair/exit), ","")&IF(AND($CH8>0,AND($A8<>"",$C8<>"DOOR ONLY"),OR($AF8="",$AF8="-")),"rated: closer reinf.?, ","")&IF(OR($I8="CORRIDOR",$I8="SMOKE BARRIER"),"S label + smoke gasketing, ","")&IF($CI8="?","wall type/hr not in IBC table, ","")&IF(AND(N($BJ8)>0,$BB8=""),"no hardware set, ","")&IF(AND($BB8<>"",ISNA(MATCH($BB8&"",HWSets,0))),"set "&$BB8&" not on HW Sets, ","")&IF(N($BL8)>96,"leaf over 8'-0"&CHAR(34)&" - check listing, ","")&IF(AND($CT8,COUNT($AW8:$AZ8)>0,COUNT($AW8:$AZ8)<>$CQ8),COUNT($AW8:$AZ8)&" custom hinges typed, "&$CQ8&" expected, ","")&IF(AND(ISNUMBER($CA8),OR(N($CA8)<34,N($CA8)>48)),"lock "&TEXT($CA8,"0.0")&CHAR(34)&" AFF outside 34-48"&CHAR(34)&" (ADA), ","")&IF(AND(ISNUMBER($AV8),ISNUMBER($BL8),N($AV8)<IF(N($BL8)<=60,2,IF(N($BL8)<=90,3,IF(N($BL8)<=120,4,5)))),"fewer hinges than standard, ",""))
A9: 104 | B9: 1 | C9: FRAME & DOOR | D9: GROUND | E9: EXTERIOR | F9: EXTERIOR | G9: LOBBY | H9: NO LAB | I9: EXTERIOR | J9: 0 | K9: 3 | L9: 0 | M9: 7 | N9: 0 | P9: 24 | Q9: 18 | R9: R | S9: 3FV | T9: M | U9: 658 | V9: 14 | W9: G9 | X9: WGS | Y9: WMA | Z9: L | AA9: CU | AB9: Y | AC9: HGC | AD9: G18 | AF9: E11 | AH9: RK | AI9: 16 | AL9: FG-24"x64" | AM9: 707 | AP9: G11 | AT9: CURRIES | BB9: 3 | BD9: =IF($A9="","",IF($DJ9<>"","FIX",IF($DK9<>"","CHECK","OK"))) | BE9: =IF($A9="","",IF($DJ9<>"","FIX: "&LEFT($DJ9,LEN($DJ9)-2)&IF($DK9<>""," · ",""),"")&IF($DK9<>"","CHECK: "&LEFT($DK9,LEN($DK9)-2),"")) | BF9: =IF(OR($A9="",$K9=""),"",$K9&"'-"&N($L9)&CHAR(34)&" x "&$M9&"'-"&N($N9)&CHAR(34)) | BG9: =IF(OR($A9="",$K9=""),"",$K9&N($L9)&$M9&N($N9)) | BH9: =IF(OR($A9="",$K9=""),"",$K9*12+N($L9)) | BI9: =IF(OR($A9="",$M9=""),"",$M9*12+N($N9)) | BJ9: =IF($A9="","",IF(OR($C9="FRAME ONLY",$S9="BL"),0,IF($O9="Y",2,1))) | BK9: =IF(OR(N($BJ9)=0,$BH9=""),"",($BH9-2*EdgeClr-IF($BJ9=2,MeetClr,0))/$BJ9) | BL9: =IF(OR(N($BJ9)=0,$BI9=""),"",$BI9-HeadClr-Undercut) | BM9: =IF($BH9="","",$BH9+2*FaceW+IF(N($Q9)>0,($Q9+FaceW)*IF($R9="LR",2,1),0)) | BN9: =IF($BI9="","",$BI9+IF($AB9="Y",4,FaceW)+IF(N($P9)>0,$P9+FaceW,0)+IF(OR($S9="4F",$S9="BL"),FaceW,0)) | BO9: =IF($BM9="","",$BM9+2*ROSide) | BP9: =IF($BN9="","",$BN9+ROTop) | BQ9: =IF(OR(N($BJ9)=0,$BH9=""),"",$BH9/$BJ9-ClearDeduct) | BR9: =IF(N($CH9)=0,"",IF($CH9>=180,"A · 3 HR",IF($CH9>=90,"B · 1-1/2 HR",IF($CH9>=60,"B · 1 HR",IF($CH9>=45,"C · 3/4 HR","20 MIN")))))&IF(AND(N($CH9)>0,OR($I9="CORRIDOR",$I9="SMOKE BARRIER"))," · S","") | BS9: =IF($CS9,"",IF($AV9<>"",$AV9,IF(OR($AC9="HGC",$AO9="HGC"),"CONT",IF(($BI9-HeadClr-Undercut)<=60,2,IF(($BI9-HeadClr-Undercut)<=90,3,IF(($BI9-HeadClr-Undercut)<=120,4,5)))))) | BT9: =IF($CS9,"",IF($CT9,"CUSTOM (typed)",IF($CV9,$AT9&" "&$CU9&CHAR(34)&IF($CU9<>$BI9,IF(AND($BI9<$CU9,$BI9-IF(N(VLOOKUP($AT9&"|"&$CU9,LocTable,7,FALSE))>0,VLOOKUP($AT9&"|"&$CU9,LocTable,7,FALSE),VLOOKUP($AT9&"|"&$CU9,LocTable,6,FALSE))-$CR9-0.75>=2.125)," cut down"," adj."),""),"ANSI/SDI A250.6"))) | BU9: =IF($CS9,"",IF($CT9,IF(N($AW9)>0,N($AW9),""),IF(1>$CQ9,"",IF($CQ9=1,$CW9,$CW9+($CX9-$CW9)*0/($CQ9-1))))) | BV9: =IF($CS9,"",IF($CT9,IF(N($AX9)>0,N($AX9),""),IF(2>$CQ9,"",IF($CQ9=1,$CW9,$CW9+($CX9-$CW9)*1/($CQ9-1))))) | BW9: =IF($CS9,"",IF($CT9,IF(N($AY9)>0,N($AY9),""),IF(3>$CQ9,"",IF($CQ9=1,$CW9,$CW9+($CX9-$CW9)*2/($CQ9-1))))) | BX9: =IF($CS9,"",IF($CT9,IF(N($AZ9)>0,N($AZ9),""),IF(4>$CQ9,"",IF($CQ9=1,$CW9,$CW9+($CX9-$CW9)*3/($CQ9-1))))) | BY9: =IF($CS9,"",IF($CT9,"",IF(5>$CQ9,"",IF($CQ9=1,$CW9,$CW9+($CX9-$CW9)*4/($CQ9-1))))) | BZ9: =IF(OR($CS9,$AP9="-",AND($AP9="",$AD9="")),"",IF(N($BA9)>0,N($BA9),IF($CV9,IF(AND($BI9<$CU9,$BI9-IF(N(VLOOKUP($AT9&"|"&$CU9,LocTable,7,FALSE))>0,VLOOKUP($AT9&"|"&$CU9,LocTable,7,FALSE),VLOOKUP($AT9&"|"&$CU9,LocTable,6,FALSE))-$CR9-0.75>=2.125),VLOOKUP($AT9&"|"&$CU9,LocTable,8,FALSE),VLOOKUP($AT9&"|"&$CU9,LocTable,8,FALSE)+($BI9-$CU9)),$BI9-LockAFF))) | CA9: =IF($BZ9="","",$BI9-$BZ9) | CB9: =IF(OR(NOT(AND($A9<>"",$C9<>"DOOR ONLY")),$BI9=""),"",IF(($BI9+IF(N($P9)>0,$P9+FaceW,0))<=90,3,IF(($BI9+IF(N($P9)>0,$P9+FaceW,0))<=114,4,5))) | CC9: =IF($CB9="","",$CB9*(2+IF(N($Q9)>0,IF($R9="LR",2,1),0))) | CD9: =IF($CB9="","",(2+IF(N($Q9)>0,IF($R9="LR",2,1),0))) | CE9: =IF(N($BJ9)=0,"",IF(OR($AL9="",$AL9="FLUSH"),"FLUSH",IFERROR(LEFT($AL9,FIND("-",$AL9)-1),LEFT($AL9,2)))) | CF9: =IF($CE9="","",IFERROR(VALUE(MID($AL9,FIND("-",$AL9)+1,FIND(CHAR(34)&"x",$AL9)-FIND("-",$AL9)-1)),0)) | CG9: =IF($CE9="","",IFERROR(VALUE(MID($AL9,FIND(CHAR(34)&"x",$AL9)+2,FIND(CHAR(34),$AL9,FIND(CHAR(34)&"x",$AL9)+2)-FIND(CHAR(34)&"x",$AL9)-2)),0)) | CH9: =IF(OR($A9="",$H9="",$H9="NO LAB"),0,IFERROR(VALUE(LEFT($H9,FIND(" ",$H9)-1)),0)) | CI9: =IF(OR($A9="",$I9="",$I9="NON-RATED",N($J9)=0),"",IFERROR(VLOOKUP($I9&"|"&$J9,IBC,2,FALSE),"?")) | CJ9: =IF(NOT(AND($A9<>"",$C9<>"DOOR ONLY")),"",TRIM(IFERROR(VLOOKUP($U9,CODES,2,FALSE),"")&" "&$BG9&" "&IFERROR(VLOOKUP($Z9,CODES,2,FALSE),"")&" "&IFERROR(VLOOKUP($X9,CODES,2,FALSE),"")&" "&IFERROR(VLOOKUP($S9,CODES,2,FALSE),"")&IF(N($P9)>0," w/TRANSOM "&$P9&CHAR(34),"")&IF(N($Q9)>0," w/SIDELITE "&$Q9&CHAR(34)&" "&IF($R9="","R",$R9),"")&IF($Y9=""," | "," | "&IFERROR(VLOOKUP($Y9,CODES,2,FALSE),"")&" | ")&IFERROR(VLOOKUP($AC9,CODES,2,FALSE),"")&" "&IFERROR(VLOOKUP($AD9,CODES,2,FALSE),"")&IF(OR($AE9="",$AE9="-"),""," "&$AE9)&IF(OR($AF9="",$AF9="-"),""," "&$AF9)&IF($AB9="Y"," 4"&CHAR(34)&" HEAD","")&" "&IFERROR(VLOOKUP($H9,CODES,2,FALSE),"")&IF($CT9," | LOC "&$CY9,""))) | CK9: =IF(NOT(AND($A9<>"",N($BJ9)>0)),"",TRIM(IFERROR(VLOOKUP($AH9,CODES,2,FALSE),"")&IF($AI9=""," "," "&$AI9&"GA ")&$BG9&" "&IF($AN9="",IFERROR(VLOOKUP($Z9,CODES,2,FALSE),""),IFERROR(VLOOKUP($AN9,CODES,2,FALSE),""))&IF($BJ9=2," PAIR","")&" DOOR | "&IF($AL9="","?",$AL9)&" | "&IF($AO9="",IFERROR(VLOOKUP($AC9,CODES,2,FALSE),""),IFERROR(VLOOKUP($AO9,CODES,2,FALSE),""))&" "&IFERROR(VLOOKUP($AP9,CODES,2,FALSE),"")&IF(OR($AQ9="",$AQ9="-"),""," SEAM "&$AQ9)&IF($AR9="Y"," ASTRAGAL","")&IF($AJ9=""," "," "&$AJ9)&IF($AK9=""," "," "&$AK9)&IF(OR($AT9="",$AT9="ANSI/SDI",$AT9="CUSTOM LOC"),""," "&$AT9)&IF($AM9=""," "," SERIES "&$AM9)&" "&IFERROR(VLOOKUP($H9,CODES,2,FALSE),"")&IF($CT9," | LOC "&$CZ9,""))) | CL9: =IF(CP9="","",IF(COUNTIF($CP$6:CP9,CP9)=1,MAX($CL$5:CL8)+1,INDEX($CL$5:CL8,MATCH(CP9,$CP$5:CP8,0)))) | CM9: =IF(NOT(AND($A9<>"",$C9<>"DOOR ONLY")),"",MAX($CM$5:CM8)+1) | CN9: =IF(NOT(AND($A9<>"",N($BJ9)>0)),"",MAX($CN$5:CN8)+1) | CO9: =IF($A9="","",MAX($CO$5:CO8)+1) | CP9: =IF(OR($A9="",$BH9="",$BI9=""),"",$BG9&"|"&$O9&"|"&$AL9&"|"&$S9&"|"&$P9&"|"&$Q9&$R9&"|"&$C9&"|"&$AB9) | CQ9: =N($BS9) | CR9: =IF(N($AU9)>0,N($AU9),4.5) | CS9: =OR($A9="",$BI9="",$S9="BL",AND($C9="FRAME ONLY",OR($AC9="",$AC9="BLK"))) | CT9: =AND(NOT($CS9),OR($AT9="CUSTOM LOC",N($AW9)+N($AX9)+N($AY9)+N($AZ9)+N($BA9)>0)) | CU9: =IF($BI9="","",IF($BI9<=80,80,IF($BI9<=84,84,96))) | CV9: =ISNUMBER(MATCH($AT9&"|80",LocKeys,0)) | CW9: =IF($CS9,"",IF($CV9,VLOOKUP($AT9&"|"&$CU9,LocTable,4,FALSE),5)) | CX9: =IF($CS9,"",IF($CV9,IF(OR($BI9=$CU9,AND($BI9<$CU9,$BI9-IF(N(VLOOKUP($AT9&"|"&$CU9,LocTable,7,FALSE))>0,VLOOKUP($AT9&"|"&$CU9,LocTable,7,FALSE),VLOOKUP($AT9&"|"&$CU9,LocTable,6,FALSE))-$CR9-0.75>=2.125)),IF(N(VLOOKUP($AT9&"|"&$CU9,LocTable,7,FALSE))>0,VLOOKUP($AT9&"|"&$CU9,LocTable,7,FALSE),VLOOKUP($AT9&"|"&$CU9,LocTable,6,FALSE)),$BI9-($CU9-IF(N(VLOOKUP($AT9&"|"&$CU9,LocTable,7,FALSE))>0,VLOOKUP($AT9&"|"&$CU9,LocTable,7,FALSE),VLOOKUP($AT9&"|"&$CU9,LocTable,6,FALSE)))),$BI9-10-$CR9)) | CY9: =IF($CS9,"",TRIM(IF(ISNUMBER($BU9),"A "&TRIM(TEXT($BU9,"# ?/??"))&CHAR(34)&" ","")&IF(ISNUMBER($BV9),"B "&TRIM(TEXT($BV9,"# ?/??"))&CHAR(34)&" ","")&IF(ISNUMBER($BW9),"C "&TRIM(TEXT($BW9,"# ?/??"))&CHAR(34)&" ","")&IF(ISNUMBER($BX9),"D "&TRIM(TEXT($BX9,"# ?/??"))&CHAR(34)&" ","")&IF(ISNUMBER($BY9),"F "&TRIM(TEXT($BY9,"# ?/??"))&CHAR(34)&" ","")&IF(ISNUMBER($BZ9),"E "&TRIM(TEXT($BZ9,"# ?/??"))&CHAR(34)&" ",""))) | CZ9: =IF(OR($CS9,N($BJ9)=0),"",TRIM(IF(ISNUMBER($BU9),"A "&TRIM(TEXT($BU9-HeadClr,"# ?/??"))&CHAR(34)&" ","")&IF(ISNUMBER($BV9),"B "&TRIM(TEXT($BV9-HeadClr,"# ?/??"))&CHAR(34)&" ","")&IF(ISNUMBER($BW9),"C "&TRIM(TEXT($BW9-HeadClr,"# ?/??"))&CHAR(34)&" ","")&IF(ISNUMBER($BX9),"D "&TRIM(TEXT($BX9-HeadClr,"# ?/??"))&CHAR(34)&" ","")&IF(ISNUMBER($BY9),"F "&TRIM(TEXT($BY9-HeadClr,"# ?/??"))&CHAR(34)&" ","")&IF(ISNUMBER($BZ9),"E "&TRIM(TEXT($BZ9-HeadClr,"# ?/??"))&CHAR(34)&" ",""))) | DA9: =IF($A9="","",IF($AN9="",IFERROR(VLOOKUP($Z9,CODES,2,FALSE),""),IFERROR(VLOOKUP($AN9,CODES,2,FALSE),""))) | DB9: =IF($A9="","",IF($O9="Y","PR",IF(OR($Z9="L",$Z9="RR",LEFT($Z9,2)="L-",LEFT($Z9,3)="RR-"),"LH","RH"))) | DC9: =IF($A9="","","S.HM"&IF(OR($C9="DOOR ONLY",$X9<>"KD"),"MASONRY","DRYWALL")&IF($C9="DOOR ONLY","",$U9)&IF(AND($C9<>"FRAME ONLY",OR(LEFT($AH9,3)="OAK",LEFT($AH9,3)="BIR",LEFT($AH9,3)="MAP",$AH9="PC",$AH9="MC",$AH9="SCLC",$AH9="P-LAM")),"WD","HM")&"1.75") | DD9: =IF($CJ9="","",IF($O9="Y",$CJ9,SUBSTITUTE($CJ9,$BG9&" "&IFERROR(VLOOKUP($Z9,CODES,2,FALSE),"")&" ",$BG9&" "))) | DE9: =IF($CK9="","",IF($O9="Y",$CK9,SUBSTITUTE($CK9,$BG9&" "&IF($AN9="",IFERROR(VLOOKUP($Z9,CODES,2,FALSE),""),IFERROR(VLOOKUP($AN9,CODES,2,FALSE),""))&" ",$BG9&" "))) | DF9: =IF($CJ9="","",$DC9&"|"&$DD9&"|"&$DB9&"|"&$AT9&"|"&$V9&"|"&$Y9&"|"&$AB9) | DG9: =IF(DF9="","",IF(COUNTIF($DF$6:DF9,DF9)=1,MAX($DG$5:DG8)+1,INDEX($DG$5:DG8,MATCH(DF9,$DF$5:DF8,0)))) | DH9: =IF($CK9="","",$DC9&"|"&$DE9&"|"&$AI9&"|"&$BK9&"|"&$BL9) | DI9: =IF(DH9="","",IF(COUNTIF($DH$6:DH9,DH9)=1,MAX($DI$5:DI8)+1,INDEX($DI$5:DI8,MATCH(DH9,$DH$5:DH8,0)))) | DJ9: =IF($A9="","",IF($B9="","qty, ","")&IF($C9="","scope, ","")&IF(OR($K9="",$M9=""),"size, ","")&IF(AND($A9<>"",$C9<>"DOOR ONLY"),IF($U9="","jamb depth, ","")&IF($X9="","construction, ","")&IF($Y9="","anchor, ","")&IF($S9="","frame type, ",""),"")&IF(AND(N($BJ9)>0,$Z9=""),"hand, ","")&IF(N($BJ9)>0,IF($AH9="","door material, ","")&IF($AL9="","face type, ","")&IF($AP9="","lock prep, ","")&IF(AND($AO9="",$AC9=""),"hinge prep, ",""),"")&IF(AND($CH9>0,$AH9="FRP"),"FRP cannot carry a label, ","")&IF(AND($O9="Y",OR($Z9="L",$Z9="R",$Z9="LR",$Z9="RR")),"pair marked but hand is single, ","")&IF(AND($O9<>"Y",OR($Z9="PR",AND(LEN($Z9)>1,ISNUMBER(SEARCH("-",$Z9))))),"pair hand on a single door, ","")&IF(AND(ISNUMBER($CI9),$CH9<N($CI9)),"wall needs a "&$CI9&" min door, ","")&IF(AND($CH9>=180,AND(OR($CE9="FG",$CE9="HG",$CE9="FNV",$CE9="FV"),N($CF9)*N($CG9)>100)),"180 min lite over 100 sq in, ","")&IF(N($BK9)>48,"leaf wider than 4'-0"&CHAR(34)&", ","")&IF(AND($CT9,COUNT($AW9:$AZ9)=0,$CQ9>0),"CUSTOM LOC with no locations typed, ","")) | DK9: =IF($A9="","",IF(AND($CH9>0,AND($A9<>"",$C9<>"DOOR ONLY"),$X9="KD",$E9="EXTERIOR"),"KD label on an exterior opening, ","")&IF(AND($E9="EXTERIOR",OR(AND(AND($A9<>"",$C9<>"DOOR ONLY"),$W9="CR"),AND(N($BJ9)>0,$AH9="CR"))),"exterior in CR steel (G9?), ","")&IF(AND(ISNUMBER($BQ9),N($BQ9)<32),"clear width ~"&TEXT($BQ9,"0.0")&CHAR(34)&" under 32"&CHAR(34)&" (ADA), ","")&IF(AND($CH9=90,AND(OR($CE9="FG",$CE9="HG",$CE9="FNV",$CE9="FV"),N($CF9)*N($CG9)>100)),"90 min lite over 100 sq in (stair/exit), ","")&IF(AND($CH9>0,AND($A9<>"",$C9<>"DOOR ONLY"),OR($AF9="",$AF9="-")),"rated: closer reinf.?, ","")&IF(OR($I9="CORRIDOR",$I9="SMOKE BARRIER"),"S label + smoke gasketing, ","")&IF($CI9="?","wall type/hr not in IBC table, ","")&IF(AND(N($BJ9)>0,$BB9=""),"no hardware set, ","")&IF(AND($BB9<>"",ISNA(MATCH($BB9&"",HWSets,0))),"set "&$BB9&" not on HW Sets, ","")&IF(N($BL9)>96,"leaf over 8'-0"&CHAR(34)&" - check listing, ","")&IF(AND($CT9,COUNT($AW9:$AZ9)>0,COUNT($AW9:$AZ9)<>$CQ9),COUNT($AW9:$AZ9)&" custom hinges typed, "&$CQ9&" expected, ","")&IF(AND(ISNUMBER($CA9),OR(N($CA9)<34,N($CA9)>48)),"lock "&TEXT($CA9,"0.0")&CHAR(34)&" AFF outside 34-48"&CHAR(34)&" (ADA), ","")&IF(AND(ISNUMBER($AV9),ISNUMBER($BL9),N($AV9)<IF(N($BL9)<=60,2,IF(N($BL9)<=90,3,IF(N($BL9)<=120,4,5)))),"fewer hinges than standard, ",""))
