Workbook
Name Scope: Lists!$A$5:$A$7
Name Floor: Lists!$B$5:$B$15
Name Category: Lists!$C$5:$C$6
Name FireRating: Lists!$D$5:$D$10
Name FrameType: Lists!$E$5:$E$10
Name Profile: Lists!$F$5:$F$8
Name JambDepth: Lists!$G$5:$G$77
Name GaugeFrame: Lists!$H$5:$H$6
Name SteelType: Lists!$I$5:$I$8
Name Construction: Lists!$J$5:$J$6
Name AnchorType: Lists!$K$5:$K$12
Name Handing: Lists!$L$5:$L$20
Name YesNo: Lists!$M$5:$M$6
Name Manufacturer: Lists!$N$5:$N$6
Name HingePrep: Lists!$O$5:$O$12
Name StrikePrep: Lists!$P$5:$P$15
Name HeaderPrep: Lists!$Q$5:$Q$9
Name CloserPrep: Lists!$R$5:$R$11
Name DoorMaterial: Lists!$S$5:$S$14
Name GaugeDoor: Lists!$T$5:$T$7
Name WoodCore: Lists!$U$5:$U$8
Name FaceType: Lists!$V$5:$V$23
Name ManufLoc: Lists!$W$5:$W$10
Name LockPrep: Lists!$X$5:$X$27
Name Edge: Lists!$Y$5:$Y$8
Name Astragal: Lists!$Z$5:$Z$6
Name Series: Lists!$AA$5:$AA$11
Name WoodFinish: Lists!$AB$5:$AB$12
Name WallType: Lists!$AD$5:$AD$12
Name WallHR: Lists!$AE$5:$AE$11
Name SLSide: Lists!$AF$5:$AF$7
Name IBC: Lists!$AH$5:$AI$23
Name CODES: Codes!$A$5:$B$400
Name JobName: Job!$C$5
Name JobNo: Job!$C$6
Name JobAddress: Job!$C$7
Name JobGC: Job!$C$8
Name JobArch: Job!$C$9
Name JobEst: Job!$C$10
Name JobDate: Job!$C$11
Name JobBid: Job!$C$12
Name JobSupplier: Job!$C$13
Name JobRev: Job!$C$14
Name JobDocs: Job!$C$15
Name FaceW: Job!$C$21
Name EdgeClr: Job!$C$22
Name MeetClr: Job!$C$23
Name HeadClr: Job!$C$24
Name Undercut: Job!$C$25
Name ROSide: Job!$C$26
Name ROTop: Job!$C$27
Name ClearDeduct: Job!$C$28
Name LockAFF: Job!$C$29
Name tk_MARK: Takeoff!$A$6:$A$505
Name tk_QTY: Takeoff!$B$6:$B$505
Name tk_SCOPE: Takeoff!$C$6:$C$505
Name tk_FLOOR: Takeoff!$D$6:$D$505
Name tk_CAT: Takeoff!$E$6:$E$505
Name tk_ROOMF: Takeoff!$F$6:$F$505
Name tk_ROOMT: Takeoff!$G$6:$G$505

Sheet Start
B2: TAKEOFF FORM 3.0
B3: Door, frame and hardware takeoff · live elevations · code checks · order lines
B5: GO TO
B6: Job | C6: Job name, dates, clearances
B7: Takeoff | C7: One row per opening — the only place you type openings
B8: Elevation | C8: Pick a mark: drawing, sizes, order lines, checks
B9: Elevations | C9: Every elevation type, six to a page, ready to print
B10: Hardware | C10: Hardware sets, items, opening counts and job quantities
B11: Frame order | C11: Frame order lines for the supplier
B12: Door order | C12: Door order lines with leaf sizes
B13: Summary | C13: Counts by rating, scope, floor, material, lite
B14: Lists | C14: Every dropdown — edit here
B15: Codes | C15: What each code prints on an order line
B19: HOW TO USE IT
B20: 1 | C20: Fill in the Job sheet once. Set the clearances (undercut, edge gaps, frame face) to suit your frame maker.
B21: 2 | C21: On Takeoff type one row per opening. Pick SCOPE first: it decides whether the row makes a frame line, a door line, or both.
B22: 3 | C22: Size: W FT, W IN, H FT, H IN (3 · 0 · 7 · 0 = 3070). Fractions as decimals: 0.5 = 1/2". PAIR = Y for a pair. Transom and sidelite are glass sizes in inches.
B23: 4 | C23: Give WALL TYPE and WALL HR when the plans show them: the sheet then checks the door rating against IBC Table 716.1(2).
B24: 5 | C24: Amber cells are required and still empty. CHECK says OK, CHECK (worth a look) or FIX (missing or wrong) and the next column says why.
B25: 6 | C25: Elevation draws any mark at scale; Elevations draws one of each type for the submittal or the shop. Both follow the Takeoff live.
B26: 7 | C26: Hardware: list each set on the Hardware sheet, then pick the set on the Takeoff. Opening counts and job quantities follow.
B27: 8 | C27: Frame order and Door order build themselves. Print them or copy the lines into the supplier’s portal.
B28: 9 | C28: The eight sample openings (101–108) show every feature. Select the white/yellow input cells of those rows and press Delete to start a job; the formulas stay.
B31: COLOUR KEY
C32: Opening inputs
C33: Frame inputs
C34: Door inputs
C35: Hardware
C36: Calculated — do not type
C38: Required and still empty
B39: Blue | C39: Text you typed (inputs)
B41: WHAT IS NEW IN 3.0 (vs. 2.0)
B42: • | C42: Live elevations at scale: frame, leaves, lites/louvers, transom, sidelites, hinges, lever, swing and dimensions — for one mark or every type.
B43: • | C43: Calculated leaf size, frame overall, rough opening, clear width, hinges per leaf, lite size and elevation type on every row.
B44: • | C44: Code checks: door vs wall rating (IBC 716.1(2)), FRP labels, pair/hand both ways, 180/90 min glass limit, ADA 32" clear, S-label corridors, closer reinforcement, oversize leaves.
B45: • | C45: Two levels: FIX (blocks the order) and CHECK (worth a look). Required cells light up amber until filled.
B46: • | C46: Hardware sets with items, opening counts and job quantities.
B47: • | C47: Transom, sidelite and wall columns; door hand and hinge prep default to the frame when blank; foldable column groups; filters; print setup on every sheet.
B48: • | C48: Same codes and lists as 2.0: order lines read exactly as before.

Sheet Job
B2: JOB
B3: Fill this in once. It prints on the takeoff, the order sheets and the elevations.
B5: Job name
B6: Job number
B7: Address
B8: General contractor
B9: Architect
B10: Estimator
B11: Date | C11: =TODAY()
B12: Bid date
B13: Supplier | C13: CURRIES
B14: Revision | C14: REV 0
B15: Drawings / addenda
B18: SIZES AND CLEARANCES (inches)
B19: Used for leaf size, frame overall, rough opening, clear width and the elevations. Change them to suit the frame maker.
B21: Frame face (jamb & head) | C21: 2 | D21: Standard 2" face. A 4" head is picked per opening on the Takeoff.
B22: Hinge & strike edge clearance | C22: 0.125 | D22: Gap each side between leaf and frame rabbet (NFPA 80 max 1/8" on steel).
B23: Meeting edge clearance (pairs) | C23: 0.125 | D23: Gap between leaves of a pair.
B24: Head clearance | C24: 0.125 | D24: Gap between top of leaf and head rabbet.
B25: Undercut | C25: 0.75 | D25: Floor to bottom of leaf. NFPA 80 allows 3/4" max on rated doors over a non-combustible floor.
B26: Rough opening allowance, each side | C26: 0.25 | D26: Added to frame overall width, each side.
B27: Rough opening allowance, head | C27: 0.25 | D27: Added to frame overall height.
B28: Clear width deduction | C28: 2.625 | D28: Nominal leaf width minus this = approx. clear opening at 90° (stop + 1-3/4" door + knuckle).
B29: Lock / lever height (AFF) | C29: 40.3125 | D29: Lock centre line from finished floor, for the elevation.

Sheet Takeoff
A1: =IF(JobName="","TAKEOFF — fill in the job on the Job sheet",JobName&IF(JobNo="",""," — job "&JobNo))
A2: =COUNTIF(tk_MARK,"?*")&" rows · "&SUM(tk_QTY)&" openings · "&SUMPRODUCT(tk_QTY,tk_LEAVES)&" leaves · "&COUNTIF(tk_CHECK,"FIX")&" to fix · "&COUNTIF(tk_CHECK,"CHECK")&" to check"
A3: Yellow-tinted columns are yours; grey ones calculate. Pick from the dropdowns. Click a group’s [−] above the letters to fold it away.
A4: OPENING | S4: FRAME | AH4: DOOR | AU4: HARDWARE | AW4: CALCULATED
A5: MARK | B5: QTY | C5: SCOPE | D5: FLOOR | E5: CATEGORY | F5: ROOM FROM | G5: ROOM TO | H5: FIRE RATING | I5: WALL TYPE | J5: WALL HR | K5: W FT | L5: W IN | M5: H FT | N5: H IN | O5: PAIR | P5: TRANSOM H (IN) | Q5: SIDELITE W (IN) | R5: SIDELITE SIDE | S5: FRAME TYPE | T5: PROFILE | U5: JAMB DEPTH | V5: GAUGE | W5: STEEL | X5: CONSTR. | Y5: ANCHOR | Z5: HAND | AA5: MANUF. | AB5: 4" HEAD | AC5: HINGE PREP | AD5: STRIKE PREP | AE5: HEADER PREP | AF5: CLOSER REINF. | AG5: FRAME NOTES | AH5: MATERIAL | AI5: GAUGE | AJ5: WOOD CORE | AK5: WOOD FINISH | AL5: FACE TYPE | AM5: SERIES | AN5: DOOR HAND (blank = frame) | AO5: HW LOCATIONS | AP5: HINGE PREP (blank = frame) | AQ5: LOCK PREP | AR5: EDGE | AS5: ASTRAGAL | AT5: DOOR NOTES | AU5: HW SET | AV5: HARDWARE NOTES | AW5: CHECK | AX5: WHAT TO FIX / CHECK | AY5: SIZE | AZ5: CODE | BA5: W (IN) | BB5: H (IN) | BC5: LEAVES | BD5: LEAF W | BE5: LEAF H | BF5: FRAME O/A W | BG5: FRAME O/A H | BH5: ROUGH OPG W | BI5: ROUGH OPG H | BJ5: CLEAR W (approx) | BK5: HINGES / LEAF | BL5: LITE KIT | BM5: LITE W | BN5: LITE H | BO5: DOOR MIN | BP5: WALL NEEDS (MIN) | BQ5: FRAME ORDER LINE | BR5: DOOR ORDER LINE | BS5: ELEV TYPE | BT5: FSEQ | BU5: DSEQ | BV5: EKEY | BW5: ERRS | BX5: WARNS
A6: 101 | B6: 1 | C6: FRAME & DOOR | D6: 1st | E6: INTERIOR | F6: CORRIDOR | G6: OFFICE 101 | H6: 20 MIN | I6: CORRIDOR | J6: 1 | K6: 3 | L6: 0 | M6: 7 | N6: 0 | S6: 3F | T6: M | U6: 534 | V6: 16 | W6: CR | X6: KD | Y6: SC | Z6: R | AA6: CU | AC6: U453 | AD6: E1 | AF6: E11 | AH6: CR | AI6: 18 | AL6: FNV-6"x27" | AM6: 707 | AO6: CURRIES | AQ6: G2 | AU6: 1 | AW6: =IF($A6="","",IF($BW6<>"","FIX",IF($BX6<>"","CHECK","OK"))) | AX6: =IF($A6="","",IF($BW6<>"","FIX: "&LEFT($BW6,LEN($BW6)-2)&IF($BX6<>""," · ",""),"")&IF($BX6<>"","CHECK: "&LEFT($BX6,LEN($BX6)-2),"")) | AY6: =IF(OR($A6="",$K6=""),"",$K6&"'-"&N($L6)&CHAR(34)&" x "&$M6&"'-"&N($N6)&CHAR(34)) | AZ6: =IF(OR($A6="",$K6=""),"",$K6&N($L6)&$M6&N($N6)) | BA6: =IF(OR($A6="",$K6=""),"",$K6*12+N($L6)) | BB6: =IF(OR($A6="",$M6=""),"",$M6*12+N($N6)) | BC6: =IF($A6="","",IF(OR($C6="FRAME ONLY",$S6="BL"),0,IF($O6="Y",2,1))) | BD6: =IF(OR(N($BC6)=0,$BA6=""),"",($BA6-2*EdgeClr-IF($BC6=2,MeetClr,0))/$BC6) | BE6: =IF(OR(N($BC6)=0,$BB6=""),"",$BB6-HeadClr-Undercut) | BF6: =IF($BA6="","",$BA6+2*FaceW+IF(N($Q6)>0,($Q6+FaceW)*IF($R6="LR",2,1),0)) | BG6: =IF($BB6="","",$BB6+IF($AB6="Y",4,FaceW)+IF(N($P6)>0,$P6+FaceW,0)+IF(OR($S6="4F",$S6="BL"),FaceW,0)) | BH6: =IF($BF6="","",$BF6+2*ROSide) | BI6: =IF($BG6="","",$BG6+ROTop) | BJ6: =IF(OR(N($BC6)=0,$BA6=""),"",$BA6/$BC6-ClearDeduct) | BK6: =IF(OR(N($BC6)=0,$BE6=""),"",IF(OR($AC6="HGC",$AP6="HGC"),"CONT",IF($BE6<=60,2,IF($BE6<=90,3,IF($BE6<=120,4,5))))) | BL6: =IF(N($BC6)=0,"",IF(OR($AL6="",$AL6="FLUSH"),"FLUSH",IFERROR(LEFT($AL6,FIND("-",$AL6)-1),LEFT($AL6,2)))) | BM6: =IF($BL6="","",IFERROR(VALUE(MID($AL6,FIND("-",$AL6)+1,FIND(CHAR(34)&"x",$AL6)-FIND("-",$AL6)-1)),0)) | BN6: =IF($BL6="","",IFERROR(VALUE(MID($AL6,FIND(CHAR(34)&"x",$AL6)+2,FIND(CHAR(34),$AL6,FIND(CHAR(34)&"x",$AL6)+2)-FIND(CHAR(34)&"x",$AL6)-2)),0)) | BO6: =IF(OR($A6="",$H6="",$H6="NO LAB"),0,IFERROR(VALUE(LEFT($H6,FIND(" ",$H6)-1)),0)) | BP6: =IF(OR($A6="",$I6="",$I6="NON-RATED",N($J6)=0),"",IFERROR(VLOOKUP($I6&"|"&$J6,IBC,2,FALSE),"?")) | BQ6: =IF(NOT(AND($A6<>"",$C6<>"DOOR ONLY")),"",TRIM(IFERROR(VLOOKUP($U6,CODES,2,FALSE),"")&" "&$AZ6&" "&IFERROR(VLOOKUP($Z6,CODES,2,FALSE),"")&" "&IFERROR(VLOOKUP($X6,CODES,2,FALSE),"")&" "&IFERROR(VLOOKUP($S6,CODES,2,FALSE),"")&IF(N($P6)>0," w/TRANSOM "&$P6&CHAR(34),"")&IF(N($Q6)>0," w/SIDELITE "&$Q6&CHAR(34)&" "&IF($R6="","R",$R6),"")&IF($Y6=""," | "," | "&IFERROR(VLOOKUP($Y6,CODES,2,FALSE),"")&" | ")&IFERROR(VLOOKUP($AC6,CODES,2,FALSE),"")&" "&IFERROR(VLOOKUP($AD6,CODES,2,FALSE),"")&IF(OR($AE6="",$AE6="-"),""," "&$AE6)&IF(OR($AF6="",$AF6="-"),""," "&$AF6)&IF($AB6="Y"," 4"&CHAR(34)&" HEAD","")&" "&IFERROR(VLOOKUP($H6,CODES,2,FALSE),""))) | BR6: =IF(NOT(AND($A6<>"",N($BC6)>0)),"",TRIM(IFERROR(VLOOKUP($AH6,CODES,2,FALSE),"")&IF($AI6=""," "," "&$AI6&"GA ")&$AZ6&" "&IF($AN6="",IFERROR(VLOOKUP($Z6,CODES,2,FALSE),""),IFERROR(VLOOKUP($AN6,CODES,2,FALSE),""))&IF($BC6=2," PAIR","")&" DOOR | "&IF($AL6="","?",$AL6)&" | "&IF($AP6="",IFERROR(VLOOKUP($AC6,CODES,2,FALSE),""),IFERROR(VLOOKUP($AP6,CODES,2,FALSE),""))&" "&IFERROR(VLOOKUP($AQ6,CODES,2,FALSE),"")&IF(OR($AR6="",$AR6="-"),""," SEAM "&$AR6)&IF($AS6="Y"," ASTRAGAL","")&IF($AJ6=""," "," "&$AJ6)&IF($AK6=""," "," "&$AK6)&IF($AO6="",""," "&$AO6)&IF($AM6=""," "," SERIES "&$AM6)&" "&IFERROR(VLOOKUP($H6,CODES,2,FALSE),""))) | BS6: =IF(BV6="","",IF(COUNTIF($BV$6:BV6,BV6)=1,MAX($BS$5:BS5)+1,INDEX($BS$5:BS5,MATCH(BV6,$BV$5:BV5,0)))) | BT6: =IF(NOT(AND($A6<>"",$C6<>"DOOR ONLY")),"",MAX($BT$5:BT5)+1) | BU6: =IF(NOT(AND($A6<>"",N($BC6)>0)),"",MAX($BU$5:BU5)+1) | BV6: =IF(OR($A6="",$BA6="",$BB6=""),"",$AZ6&"|"&$O6&"|"&$AL6&"|"&$S6&"|"&$P6&"|"&$Q6&$R6&"|"&$C6&"|"&$AB6) | BW6: =IF($A6="","",IF($B6="","qty, ","")&IF($C6="","scope, ","")&IF(OR($K6="",$M6=""),"size, ","")&IF(AND($A6<>"",$C6<>"DOOR ONLY"),IF($U6="","jamb depth, ","")&IF($X6="","construction, ","")&IF($Y6="","anchor, ","")&IF($S6="","frame type, ",""),"")&IF(AND(N($BC6)>0,$Z6=""),"hand, ","")&IF(N($BC6)>0,IF($AH6="","door material, ","")&IF($AL6="","face type, ","")&IF($AQ6="","lock prep, ","")&IF(AND($AP6="",$AC6=""),"hinge prep, ",""),"")&IF(AND($BO6>0,$AH6="FRP"),"FRP cannot carry a label, ","")&IF(AND($O6="Y",OR($Z6="L",$Z6="R",$Z6="LR",$Z6="RR")),"pair marked but hand is single, ","")&IF(AND($O6<>"Y",OR($Z6="PR",AND(LEN($Z6)>1,ISNUMBER(SEARCH("-",$Z6))))),"pair hand on a single door, ","")&IF(AND(ISNUMBER($BP6),$BO6<N($BP6)),"wall needs a "&$BP6&" min door, ","")&IF(AND($BO6>=180,AND(OR($BL6="FG",$BL6="HG",$BL6="FNV",$BL6="FV"),N($BM6)*N($BN6)>100)),"180 min lite over 100 sq in, ","")&IF(N($BD6)>48,"leaf wider than 4'-0"&CHAR(34)&", ","")) | BX6: =IF($A6="","",IF(AND($BO6>0,AND($A6<>"",$C6<>"DOOR ONLY"),$X6="KD",$E6="EXTERIOR"),"KD label on an exterior opening, ","")&IF(AND($E6="EXTERIOR",OR(AND(AND($A6<>"",$C6<>"DOOR ONLY"),$W6="CR"),AND(N($BC6)>0,$AH6="CR"))),"exterior in CR steel (G9?), ","")&IF(AND(ISNUMBER($BJ6),N($BJ6)<32),"clear width ~"&TEXT($BJ6,"0.0")&CHAR(34)&" under 32"&CHAR(34)&" (ADA), ","")&IF(AND($BO6=90,AND(OR($BL6="FG",$BL6="HG",$BL6="FNV",$BL6="FV"),N($BM6)*N($BN6)>100)),"90 min lite over 100 sq in (stair/exit), ","")&IF(AND($BO6>0,AND($A6<>"",$C6<>"DOOR ONLY"),OR($AF6="",$AF6="-")),"rated: closer reinf.?, ","")&IF(OR($I6="CORRIDOR",$I6="SMOKE BARRIER"),"S label + smoke gasketing, ","")&IF($BP6="?","wall type/hr not in IBC table, ","")&IF(AND(N($BC6)>0,$AU6=""),"no hardware set, ","")&IF(AND($AU6<>"",ISNA(MATCH($AU6,HWSets,0))),"set "&$AU6&" not on Hardware sheet, ","")&IF(N($BE6)>96,"leaf over 8'-0"&CHAR(34)&" - check listing, ",""))
A7: 102 | B7: 4 | C7: FRAME & DOOR | D7: 1st | E7: INTERIOR | F7: OFFICE | G7: STORAGE | H7: NO LAB | I7: NON-RATED | K7: 3 | L7: 0 | M7: 7 | N7: 0 | S7: 3F | T7: M | U7: 478 | V7: 16 | W7: CR | X7: KD | Y7: SC | Z7: LR | AA7: CU | AC7: U453 | AD7: E1 | AH7: OAK-PC | AJ7: PC | AK7: RNB | AL7: FLUSH | AQ7: G2 | AU7: 1 | AW7: =IF($A7="","",IF($BW7<>"","FIX",IF($BX7<>"","CHECK","OK"))) | AX7: =IF($A7="","",IF($BW7<>"","FIX: "&LEFT($BW7,LEN($BW7)-2)&IF($BX7<>""," · ",""),"")&IF($BX7<>"","CHECK: "&LEFT($BX7,LEN($BX7)-2),"")) | AY7: =IF(OR($A7="",$K7=""),"",$K7&"'-"&N($L7)&CHAR(34)&" x "&$M7&"'-"&N($N7)&CHAR(34)) | AZ7: =IF(OR($A7="",$K7=""),"",$K7&N($L7)&$M7&N($N7)) | BA7: =IF(OR($A7="",$K7=""),"",$K7*12+N($L7)) | BB7: =IF(OR($A7="",$M7=""),"",$M7*12+N($N7)) | BC7: =IF($A7="","",IF(OR($C7="FRAME ONLY",$S7="BL"),0,IF($O7="Y",2,1))) | BD7: =IF(OR(N($BC7)=0,$BA7=""),"",($BA7-2*EdgeClr-IF($BC7=2,MeetClr,0))/$BC7) | BE7: =IF(OR(N($BC7)=0,$BB7=""),"",$BB7-HeadClr-Undercut) | BF7: =IF($BA7="","",$BA7+2*FaceW+IF(N($Q7)>0,($Q7+FaceW)*IF($R7="LR",2,1),0)) | BG7: =IF($BB7="","",$BB7+IF($AB7="Y",4,FaceW)+IF(N($P7)>0,$P7+FaceW,0)+IF(OR($S7="4F",$S7="BL"),FaceW,0)) | BH7: =IF($BF7="","",$BF7+2*ROSide) | BI7: =IF($BG7="","",$BG7+ROTop) | BJ7: =IF(OR(N($BC7)=0,$BA7=""),"",$BA7/$BC7-ClearDeduct) | BK7: =IF(OR(N($BC7)=0,$BE7=""),"",IF(OR($AC7="HGC",$AP7="HGC"),"CONT",IF($BE7<=60,2,IF($BE7<=90,3,IF($BE7<=120,4,5))))) | BL7: =IF(N($BC7)=0,"",IF(OR($AL7="",$AL7="FLUSH"),"FLUSH",IFERROR(LEFT($AL7,FIND("-",$AL7)-1),LEFT($AL7,2)))) | BM7: =IF($BL7="","",IFERROR(VALUE(MID($AL7,FIND("-",$AL7)+1,FIND(CHAR(34)&"x",$AL7)-FIND("-",$AL7)-1)),0)) | BN7: =IF($BL7="","",IFERROR(VALUE(MID($AL7,FIND(CHAR(34)&"x",$AL7)+2,FIND(CHAR(34),$AL7,FIND(CHAR(34)&"x",$AL7)+2)-FIND(CHAR(34)&"x",$AL7)-2)),0)) | BO7: =IF(OR($A7="",$H7="",$H7="NO LAB"),0,IFERROR(VALUE(LEFT($H7,FIND(" ",$H7)-1)),0)) | BP7: =IF(OR($A7="",$I7="",$I7="NON-RATED",N($J7)=0),"",IFERROR(VLOOKUP($I7&"|"&$J7,IBC,2,FALSE),"?")) | BQ7: =IF(NOT(AND($A7<>"",$C7<>"DOOR ONLY")),"",TRIM(IFERROR(VLOOKUP($U7,CODES,2,FALSE),"")&" "&$AZ7&" "&IFERROR(VLOOKUP($Z7,CODES,2,FALSE),"")&" "&IFERROR(VLOOKUP($X7,CODES,2,FALSE),"")&" "&IFERROR(VLOOKUP($S7,CODES,2,FALSE),"")&IF(N($P7)>0," w/TRANSOM "&$P7&CHAR(34),"")&IF(N($Q7)>0," w/SIDELITE "&$Q7&CHAR(34)&" "&IF($R7="","R",$R7),"")&IF($Y7=""," | "," | "&IFERROR(VLOOKUP($Y7,CODES,2,FALSE),"")&" | ")&IFERROR(VLOOKUP($AC7,CODES,2,FALSE),"")&" "&IFERROR(VLOOKUP($AD7,CODES,2,FALSE),"")&IF(OR($AE7="",$AE7="-"),""," "&$AE7)&IF(OR($AF7="",$AF7="-"),""," "&$AF7)&IF($AB7="Y"," 4"&CHAR(34)&" HEAD","")&" "&IFERROR(VLOOKUP($H7,CODES,2,FALSE),""))) | BR7: =IF(NOT(AND($A7<>"",N($BC7)>0)),"",TRIM(IFERROR(VLOOKUP($AH7,CODES,2,FALSE),"")&IF($AI7=""," "," "&$AI7&"GA ")&$AZ7&" "&IF($AN7="",IFERROR(VLOOKUP($Z7,CODES,2,FALSE),""),IFERROR(VLOOKUP($AN7,CODES,2,FALSE),""))&IF($BC7=2," PAIR","")&" DOOR | "&IF($AL7="","?",$AL7)&" | "&IF($AP7="",IFERROR(VLOOKUP($AC7,CODES,2,FALSE),""),IFERROR(VLOOKUP($AP7,CODES,2,FALSE),""))&" "&IFERROR(VLOOKUP($AQ7,CODES,2,FALSE),"")&IF(OR($AR7="",$AR7="-"),""," SEAM "&$AR7)&IF($AS7="Y"," ASTRAGAL","")&IF($AJ7=""," "," "&$AJ7)&IF($AK7=""," "," "&$AK7)&IF($AO7="",""," "&$AO7)&IF($AM7=""," "," SERIES "&$AM7)&" "&IFERROR(VLOOKUP($H7,CODES,2,FALSE),""))) | BS7: =IF(BV7="","",IF(COUNTIF($BV$6:BV7,BV7)=1,MAX($BS$5:BS6)+1,INDEX($BS$5:BS6,MATCH(BV7,$BV$5:BV6,0)))) | BT7: =IF(NOT(AND($A7<>"",$C7<>"DOOR ONLY")),"",MAX($BT$5:BT6)+1) | BU7: =IF(NOT(AND($A7<>"",N($BC7)>0)),"",MAX($BU$5:BU6)+1) | BV7: =IF(OR($A7="",$BA7="",$BB7=""),"",$AZ7&"|"&$O7&"|"&$AL7&"|"&$S7&"|"&$P7&"|"&$Q7&$R7&"|"&$C7&"|"&$AB7) | BW7: =IF($A7="","",IF($B7="","qty, ","")&IF($C7="","scope, ","")&IF(OR($K7="",$M7=""),"size, ","")&IF(AND($A7<>"",$C7<>"DOOR ONLY"),IF($U7="","jamb depth, ","")&IF($X7="","construction, ","")&IF($Y7="","anchor, ","")&IF($S7="","frame type, ",""),"")&IF(AND(N($BC7)>0,$Z7=""),"hand, ","")&IF(N($BC7)>0,IF($AH7="","door material, ","")&IF($AL7="","face type, ","")&IF($AQ7="","lock prep, ","")&IF(AND($AP7="",$AC7=""),"hinge prep, ",""),"")&IF(AND($BO7>0,$AH7="FRP"),"FRP cannot carry a label, ","")&IF(AND($O7="Y",OR($Z7="L",$Z7="R",$Z7="LR",$Z7="RR")),"pair marked but hand is single, ","")&IF(AND($O7<>"Y",OR($Z7="PR",AND(LEN($Z7)>1,ISNUMBER(SEARCH("-",$Z7))))),"pair hand on a single door, ","")&IF(AND(ISNUMBER($BP7),$BO7<N($BP7)),"wall needs a "&$BP7&" min door, ","")&IF(AND($BO7>=180,AND(OR($BL7="FG",$BL7="HG",$BL7="FNV",$BL7="FV"),N($BM7)*N($BN7)>100)),"180 min lite over 100 sq in, ","")&IF(N($BD7)>48,"leaf wider than 4'-0"&CHAR(34)&", ","")) | BX7: =IF($A7="","",IF(AND($BO7>0,AND($A7<>"",$C7<>"DOOR ONLY"),$X7="KD",$E7="EXTERIOR"),"KD label on an exterior opening, ","")&IF(AND($E7="EXTERIOR",OR(AND(AND($A7<>"",$C7<>"DOOR ONLY"),$W7="CR"),AND(N($BC7)>0,$AH7="CR"))),"exterior in CR steel (G9?), ","")&IF(AND(ISNUMBER($BJ7),N($BJ7)<32),"clear width ~"&TEXT($BJ7,"0.0")&CHAR(34)&" under 32"&CHAR(34)&" (ADA), ","")&IF(AND($BO7=90,AND(OR($BL7="FG",$BL7="HG",$BL7="FNV",$BL7="FV"),N($BM7)*N($BN7)>100)),"90 min lite over 100 sq in (stair/exit), ","")&IF(AND($BO7>0,AND($A7<>"",$C7<>"DOOR ONLY"),OR($AF7="",$AF7="-")),"rated: closer reinf.?, ","")&IF(OR($I7="CORRIDOR",$I7="SMOKE BARRIER"),"S label + smoke gasketing, ","")&IF($BP7="?","wall type/hr not in IBC table, ","")&IF(AND(N($BC7)>0,$AU7=""),"no hardware set, ","")&IF(AND($AU7<>"",ISNA(MATCH($AU7,HWSets,0))),"set "&$AU7&" not on Hardware sheet, ","")&IF(N($BE7)>96,"leaf over 8'-0"&CHAR(34)&" - check listing, ",""))
A8: 103 | B8: 1 | C8: FRAME & DOOR | D8: 1st | E8: INTERIOR | F8: CORRIDOR | G8: STAIR 1 | H8: 90 MIN | I8: SHAFT / EXIT ENCL. | J8: 2 | K8: 6 | L8: 0 | M8: 7 | N8: 0 | O8: Y | S8: 3F | T8: M | U8: 834 | V8: 14 | W8: CR | X8: WGS | Y8: T | Z8: RR-A | AA8: CU | AC8: U454 | AD8: E1 | AE8: H5 | AF8: E11 | AH8: CR | AI8: 16 | AL8: HG-24"x30" | AM8: 707 | AO8: CURRIES | AQ8: G12 | AR8: - | AS8: Y | AU8: 2 | AW8: =IF($A8="","",IF($BW8<>"","FIX",IF($BX8<>"","CHECK","OK"))) | AX8: =IF($A8="","",IF($BW8<>"","FIX: "&LEFT($BW8,LEN($BW8)-2)&IF($BX8<>""," · ",""),"")&IF($BX8<>"","CHECK: "&LEFT($BX8,LEN($BX8)-2),"")) | AY8: =IF(OR($A8="",$K8=""),"",$K8&"'-"&N($L8)&CHAR(34)&" x "&$M8&"'-"&N($N8)&CHAR(34)) | AZ8: =IF(OR($A8="",$K8=""),"",$K8&N($L8)&$M8&N($N8)) | BA8: =IF(OR($A8="",$K8=""),"",$K8*12+N($L8)) | BB8: =IF(OR($A8="",$M8=""),"",$M8*12+N($N8)) | BC8: =IF($A8="","",IF(OR($C8="FRAME ONLY",$S8="BL"),0,IF($O8="Y",2,1))) | BD8: =IF(OR(N($BC8)=0,$BA8=""),"",($BA8-2*EdgeClr-IF($BC8=2,MeetClr,0))/$BC8) | BE8: =IF(OR(N($BC8)=0,$BB8=""),"",$BB8-HeadClr-Undercut) | BF8: =IF($BA8="","",$BA8+2*FaceW+IF(N($Q8)>0,($Q8+FaceW)*IF($R8="LR",2,1),0)) | BG8: =IF($BB8="","",$BB8+IF($AB8="Y",4,FaceW)+IF(N($P8)>0,$P8+FaceW,0)+IF(OR($S8="4F",$S8="BL"),FaceW,0)) | BH8: =IF($BF8="","",$BF8+2*ROSide) | BI8: =IF($BG8="","",$BG8+ROTop) | BJ8: =IF(OR(N($BC8)=0,$BA8=""),"",$BA8/$BC8-ClearDeduct) | BK8: =IF(OR(N($BC8)=0,$BE8=""),"",IF(OR($AC8="HGC",$AP8="HGC"),"CONT",IF($BE8<=60,2,IF($BE8<=90,3,IF($BE8<=120,4,5))))) | BL8: =IF(N($BC8)=0,"",IF(OR($AL8="",$AL8="FLUSH"),"FLUSH",IFERROR(LEFT($AL8,FIND("-",$AL8)-1),LEFT($AL8,2)))) | BM8: =IF($BL8="","",IFERROR(VALUE(MID($AL8,FIND("-",$AL8)+1,FIND(CHAR(34)&"x",$AL8)-FIND("-",$AL8)-1)),0)) | BN8: =IF($BL8="","",IFERROR(VALUE(MID($AL8,FIND(CHAR(34)&"x",$AL8)+2,FIND(CHAR(34),$AL8,FIND(CHAR(34)&"x",$AL8)+2)-FIND(CHAR(34)&"x",$AL8)-2)),0)) | BO8: =IF(OR($A8="",$H8="",$H8="NO LAB"),0,IFERROR(VALUE(LEFT($H8,FIND(" ",$H8)-1)),0)) | BP8: =IF(OR($A8="",$I8="",$I8="NON-RATED",N($J8)=0),"",IFERROR(VLOOKUP($I8&"|"&$J8,IBC,2,FALSE),"?")) | BQ8: =IF(NOT(AND($A8<>"",$C8<>"DOOR ONLY")),"",TRIM(IFERROR(VLOOKUP($U8,CODES,2,FALSE),"")&" "&$AZ8&" "&IFERROR(VLOOKUP($Z8,CODES,2,FALSE),"")&" "&IFERROR(VLOOKUP($X8,CODES,2,FALSE),"")&" "&IFERROR(VLOOKUP($S8,CODES,2,FALSE),"")&IF(N($P8)>0," w/TRANSOM "&$P8&CHAR(34),"")&IF(N($Q8)>0," w/SIDELITE "&$Q8&CHAR(34)&" "&IF($R8="","R",$R8),"")&IF($Y8=""," | "," | "&IFERROR(VLOOKUP($Y8,CODES,2,FALSE),"")&" | ")&IFERROR(VLOOKUP($AC8,CODES,2,FALSE),"")&" "&IFERROR(VLOOKUP($AD8,CODES,2,FALSE),"")&IF(OR($AE8="",$AE8="-"),""," "&$AE8)&IF(OR($AF8="",$AF8="-"),""," "&$AF8)&IF($AB8="Y"," 4"&CHAR(34)&" HEAD","")&" "&IFERROR(VLOOKUP($H8,CODES,2,FALSE),""))) | BR8: =IF(NOT(AND($A8<>"",N($BC8)>0)),"",TRIM(IFERROR(VLOOKUP($AH8,CODES,2,FALSE),"")&IF($AI8=""," "," "&$AI8&"GA ")&$AZ8&" "&IF($AN8="",IFERROR(VLOOKUP($Z8,CODES,2,FALSE),""),IFERROR(VLOOKUP($AN8,CODES,2,FALSE),""))&IF($BC8=2," PAIR","")&" DOOR | "&IF($AL8="","?",$AL8)&" | "&IF($AP8="",IFERROR(VLOOKUP($AC8,CODES,2,FALSE),""),IFERROR(VLOOKUP($AP8,CODES,2,FALSE),""))&" "&IFERROR(VLOOKUP($AQ8,CODES,2,FALSE),"")&IF(OR($AR8="",$AR8="-"),""," SEAM "&$AR8)&IF($AS8="Y"," ASTRAGAL","")&IF($AJ8=""," "," "&$AJ8)&IF($AK8=""," "," "&$AK8)&IF($AO8="",""," "&$AO8)&IF($AM8=""," "," SERIES "&$AM8)&" "&IFERROR(VLOOKUP($H8,CODES,2,FALSE),""))) | BS8: =IF(BV8="","",IF(COUNTIF($BV$6:BV8,BV8)=1,MAX($BS$5:BS7)+1,INDEX($BS$5:BS7,MATCH(BV8,$BV$5:BV7,0)))) | BT8: =IF(NOT(AND($A8<>"",$C8<>"DOOR ONLY")),"",MAX($BT$5:BT7)+1) | BU8: =IF(NOT(AND($A8<>"",N($BC8)>0)),"",MAX($BU$5:BU7)+1) | BV8: =IF(OR($A8="",$BA8="",$BB8=""),"",$AZ8&"|"&$O8&"|"&$AL8&"|"&$S8&"|"&$P8&"|"&$Q8&$R8&"|"&$C8&"|"&$AB8) | BW8: =IF($A8="","",IF($B8="","qty, ","")&IF($C8="","scope, ","")&IF(OR($K8="",$M8=""),"size, ","")&IF(AND($A8<>"",$C8<>"DOOR ONLY"),IF($U8="","jamb depth, ","")&IF($X8="","construction, ","")&IF($Y8="","anchor, ","")&IF($S8="","frame type, ",""),"")&IF(AND(N($BC8)>0,$Z8=""),"hand, ","")&IF(N($BC8)>0,IF($AH8="","door material, ","")&IF($AL8="","face type, ","")&IF($AQ8="","lock prep, ","")&IF(AND($AP8="",$AC8=""),"hinge prep, ",""),"")&IF(AND($BO8>0,$AH8="FRP"),"FRP cannot carry a label, ","")&IF(AND($O8="Y",OR($Z8="L",$Z8="R",$Z8="LR",$Z8="RR")),"pair marked but hand is single, ","")&IF(AND($O8<>"Y",OR($Z8="PR",AND(LEN($Z8)>1,ISNUMBER(SEARCH("-",$Z8))))),"pair hand on a single door, ","")&IF(AND(ISNUMBER($BP8),$BO8<N($BP8)),"wall needs a "&$BP8&" min door, ","")&IF(AND($BO8>=180,AND(OR($BL8="FG",$BL8="HG",$BL8="FNV",$BL8="FV"),N($BM8)*N($BN8)>100)),"180 min lite over 100 sq in, ","")&IF(N($BD8)>48,"leaf wider than 4'-0"&CHAR(34)&", ","")) | BX8: =IF($A8="","",IF(AND($BO8>0,AND($A8<>"",$C8<>"DOOR ONLY"),$X8="KD",$E8="EXTERIOR"),"KD label on an exterior opening, ","")&IF(AND($E8="EXTERIOR",OR(AND(AND($A8<>"",$C8<>"DOOR ONLY"),$W8="CR"),AND(N($BC8)>0,$AH8="CR"))),"exterior in CR steel (G9?), ","")&IF(AND(ISNUMBER($BJ8),N($BJ8)<32),"clear width ~"&TEXT($BJ8,"0.0")&CHAR(34)&" under 32"&CHAR(34)&" (ADA), ","")&IF(AND($BO8=90,AND(OR($BL8="FG",$BL8="HG",$BL8="FNV",$BL8="FV"),N($BM8)*N($BN8)>100)),"90 min lite over 100 sq in (stair/exit), ","")&IF(AND($BO8>0,AND($A8<>"",$C8<>"DOOR ONLY"),OR($AF8="",$AF8="-")),"rated: closer reinf.?, ","")&IF(OR($I8="CORRIDOR",$I8="SMOKE BARRIER"),"S label + smoke gasketing, ","")&IF($BP8="?","wall type/hr not in IBC table, ","")&IF(AND(N($BC8)>0,$AU8=""),"no hardware set, ","")&IF(AND($AU8<>"",ISNA(MATCH($AU8,HWSets,0))),"set "&$AU8&" not on Hardware sheet, ","")&IF(N($BE8)>96,"leaf over 8'-0"&CHAR(34)&" - check listing, ",""))
A9: 104 | B9: 1 | C9: FRAME & DOOR | D9: GROUND | E9: EXTERIOR | F9: EXTERIOR | G9: LOBBY | H9: NO LAB | I9: EXTERIOR | J9: 0 | K9: 3 | L9: 0 | M9: 7 | N9: 0 | P9: 24 | Q9: 18 | R9: R | S9: 3FV | T9: M | U9: 658 | V9: 14 | W9: G9 | X9: WGS | Y9: WMA | Z9: L | AA9: CU | AB9: Y | AC9: HGC | AD9: G18 | AF9: E11 | AH9: RK | AI9: 16 | AL9: FG-24"x64" | AM9: 707 | AO9: CURRIES | AQ9: G11 | AU9: 3 | AW9: =IF($A9="","",IF($BW9<>"","FIX",IF($BX9<>"","CHECK","OK"))) | AX9: =IF($A9="","",IF($BW9<>"","FIX: "&LEFT($BW9,LEN($BW9)-2)&IF($BX9<>""," · ",""),"")&IF($BX9<>"","CHECK: "&LEFT($BX9,LEN($BX9)-2),"")) | AY9: =IF(OR($A9="",$K9=""),"",$K9&"'-"&N($L9)&CHAR(34)&" x "&$M9&"'-"&N($N9)&CHAR(34)) | AZ9: =IF(OR($A9="",$K9=""),"",$K9&N($L9)&$M9&N($N9)) | BA9: =IF(OR($A9="",$K9=""),"",$K9*12+N($L9)) | BB9: =IF(OR($A9="",$M9=""),"",$M9*12+N($N9)) | BC9: =IF($A9="","",IF(OR($C9="FRAME ONLY",$S9="BL"),0,IF($O9="Y",2,1))) | BD9: =IF(OR(N($BC9)=0,$BA9=""),"",($BA9-2*EdgeClr-IF($BC9=2,MeetClr,0))/$BC9) | BE9: =IF(OR(N($BC9)=0,$BB9=""),"",$BB9-HeadClr-Undercut) | BF9: =IF($BA9="","",$BA9+2*FaceW+IF(N($Q9)>0,($Q9+FaceW)*IF($R9="LR",2,1),0)) | BG9: =IF($BB9="","",$BB9+IF($AB9="Y",4,FaceW)+IF(N($P9)>0,$P9+FaceW,0)+IF(OR($S9="4F",$S9="BL"),FaceW,0)) | BH9: =IF($BF9="","",$BF9+2*ROSide) | BI9: =IF($BG9="","",$BG9+ROTop) | BJ9: =IF(OR(N($BC9)=0,$BA9=""),"",$BA9/$BC9-ClearDeduct) | BK9: =IF(OR(N($BC9)=0,$BE9=""),"",IF(OR($AC9="HGC",$AP9="HGC"),"CONT",IF($BE9<=60,2,IF($BE9<=90,3,IF($BE9<=120,4,5))))) | BL9: =IF(N($BC9)=0,"",IF(OR($AL9="",$AL9="FLUSH"),"FLUSH",IFERROR(LEFT($AL9,FIND("-",$AL9)-1),LEFT($AL9,2)))) | BM9: =IF($BL9="","",IFERROR(VALUE(MID($AL9,FIND("-",$AL9)+1,FIND(CHAR(34)&"x",$AL9)-FIND("-",$AL9)-1)),0)) | BN9: =IF($BL9="","",IFERROR(VALUE(MID($AL9,FIND(CHAR(34)&"x",$AL9)+2,FIND(CHAR(34),$AL9,FIND(CHAR(34)&"x",$AL9)+2)-FIND(CHAR(34)&"x",$AL9)-2)),0)) | BO9: =IF(OR($A9="",$H9="",$H9="NO LAB"),0,IFERROR(VALUE(LEFT($H9,FIND(" ",$H9)-1)),0)) | BP9: =IF(OR($A9="",$I9="",$I9="NON-RATED",N($J9)=0),"",IFERROR(VLOOKUP($I9&"|"&$J9,IBC,2,FALSE),"?")) | BQ9: =IF(NOT(AND($A9<>"",$C9<>"DOOR ONLY")),"",TRIM(IFERROR(VLOOKUP($U9,CODES,2,FALSE),"")&" "&$AZ9&" "&IFERROR(VLOOKUP($Z9,CODES,2,FALSE),"")&" "&IFERROR(VLOOKUP($X9,CODES,2,FALSE),"")&" "&IFERROR(VLOOKUP($S9,CODES,2,FALSE),"")&IF(N($P9)>0," w/TRANSOM "&$P9&CHAR(34),"")&IF(N($Q9)>0," w/SIDELITE "&$Q9&CHAR(34)&" "&IF($R9="","R",$R9),"")&IF($Y9=""," | "," | "&IFERROR(VLOOKUP($Y9,CODES,2,FALSE),"")&" | ")&IFERROR(VLOOKUP($AC9,CODES,2,FALSE),"")&" "&IFERROR(VLOOKUP($AD9,CODES,2,FALSE),"")&IF(OR($AE9="",$AE9="-"),""," "&$AE9)&IF(OR($AF9="",$AF9="-"),""," "&$AF9)&IF($AB9="Y"," 4"&CHAR(34)&" HEAD","")&" "&IFERROR(VLOOKUP($H9,CODES,2,FALSE),""))) | BR9: =IF(NOT(AND($A9<>"",N($BC9)>0)),"",TRIM(IFERROR(VLOOKUP($AH9,CODES,2,FALSE),"")&IF($AI9=""," "," "&$AI9&"GA ")&$AZ9&" "&IF($AN9="",IFERROR(VLOOKUP($Z9,CODES,2,FALSE),""),IFERROR(VLOOKUP($AN9,CODES,2,FALSE),""))&IF($BC9=2," PAIR","")&" DOOR | "&IF($AL9="","?",$AL9)&" | "&IF($AP9="",IFERROR(VLOOKUP($AC9,CODES,2,FALSE),""),IFERROR(VLOOKUP($AP9,CODES,2,FALSE),""))&" "&IFERROR(VLOOKUP($AQ9,CODES,2,FALSE),"")&IF(OR($AR9="",$AR9="-"),""," SEAM "&$AR9)&IF($AS9="Y"," ASTRAGAL","")&IF($AJ9=""," "," "&$AJ9)&IF($AK9=""," "," "&$AK9)&IF($AO9="",""," "&$AO9)&IF($AM9=""," "," SERIES "&$AM9)&" "&IFERROR(VLOOKUP($H9,CODES,2,FALSE),""))) | BS9: =IF(BV9="","",IF(COUNTIF($BV$6:BV9,BV9)=1,MAX($BS$5:BS8)+1,INDEX($BS$5:BS8,MATCH(BV9,$BV$5:BV8,0)))) | BT9: =IF(NOT(AND($A9<>"",$C9<>"DOOR ONLY")),"",MAX($BT$5:BT8)+1) | BU9: =IF(NOT(AND($A9<>"",N($BC9)>0)),"",MAX($BU$5:BU8)+1) | BV9: =IF(OR($A9="",$BA9="",$BB9=""),"",$AZ9&"|"&$O9&"|"&$AL9&"|"&$S9&"|"&$P9&"|"&$Q9&$R9&"|"&$C9&"|"&$AB9) | BW9: =IF($A9="","",IF($B9="","qty, ","")&IF($C9="","scope, ","")&IF(OR($K9="",$M9=""),"size, ","")&IF(AND($A9<>"",$C9<>"DOOR ONLY"),IF($U9="","jamb depth, ","")&IF($X9="","construction, ","")&IF($Y9="","anchor, ","")&IF($S9="","frame type, ",""),"")&IF(AND(N($BC9)>0,$Z9=""),"hand, ","")&IF(N($BC9)>0,IF($AH9="","door material, ","")&IF($AL9="","face type, ","")&IF($AQ9="","lock prep, ","")&IF(AND($AP9="",$AC9=""),"hinge prep, ",""),"")&IF(AND($BO9>0,$AH9="FRP"),"FRP cannot carry a label, ","")&IF(AND($O9="Y",OR($Z9="L",$Z9="R",$Z9="LR",$Z9="RR")),"pair marked but hand is single, ","")&IF(AND($O9<>"Y",OR($Z9="PR",AND(LEN($Z9)>1,ISNUMBER(SEARCH("-",$Z9))))),"pair hand on a single door, ","")&IF(AND(ISNUMBER($BP9),$BO9<N($BP9)),"wall needs a "&$BP9&" min door, ","")&IF(AND($BO9>=180,AND(OR($BL9="FG",$BL9="HG",$BL9="FNV",$BL9="FV"),N($BM9)*N($BN9)>100)),"180 min lite over 100 sq in, ","")&IF(N($BD9)>48,"leaf wider than 4'-0"&CHAR(34)&", ","")) | BX9: =IF($A9="","",IF(AND($BO9>0,AND($A9<>"",$C9<>"DOOR ONLY"),$X9="KD",$E9="EXTERIOR"),"KD label on an exterior opening, ","")&IF(AND($E9="EXTERIOR",OR(AND(AND($A9<>"",$C9<>"DOOR ONLY"),$W9="CR"),AND(N($BC9)>0,$AH9="CR"))),"exterior in CR steel (G9?), ","")&IF(AND(ISNUMBER($BJ9),N($BJ9)<32),"clear width ~"&TEXT($BJ9,"0.0")&CHAR(34)&" under 32"&CHAR(34)&" (ADA), ","")&IF(AND($BO9=90,AND(OR($BL9="FG",$BL9="HG",$BL9="FNV",$BL9="FV"),N($BM9)*N($BN9)>100)),"90 min lite over 100 sq in (stair/exit), ","")&IF(AND($BO9>0,AND($A9<>"",$C9<>"DOOR ONLY"),OR($AF9="",$AF9="-")),"rated: closer reinf.?, ","")&IF(OR($I9="CORRIDOR",$I9="SMOKE BARRIER"),"S label + smoke gasketing, ","")&IF($BP9="?","wall type/hr not in IBC table, ","")&IF(AND(N($BC9)>0,$AU9=""),"no hardware set, ","")&IF(AND($AU9<>"",ISNA(MATCH($AU9,HWSets,0))),"set "&$AU9&" not on Hardware sheet, ","")&IF(N($BE9)>96,"leaf over 8'-0"&CHAR(34)&" - check listing, ",""))
A10: 105 | B10: 2 | C10: FRAME ONLY | D10: 1st | E10: INTERIOR | F10: RECEPTION | G10: OFFICE | H10: NO LAB | K10: 4 | L10: 0 | M10: 3 | N10: 0 | S10: BL | T10: C | U10: 478 | V10: 16 | W10: CR | X10: KD | Y10: SC | AA10: CU | AC10: BLK | AW10: =IF($A10="","",IF($BW10<>"","FIX",IF($BX10<>"","CHECK","OK"))) | AX10: =IF($A10="","",IF($BW10<>"","FIX: "&LEFT($BW10,LEN($BW10)-2)&IF($BX10<>""," · ",""),"")&IF($BX10<>"","CHECK: "&LEFT($BX10,LEN($BX10)-2),"")) | AY10: =IF(OR($A10="",$K10=""),"",$K10&"'-"&N($L10)&CHAR(34)&" x "&$M10&"'-"&N($N10)&CHAR(34)) | AZ10: =IF(OR($A10="",$K10=""),"",$K10&N($L10)&$M10&N($N10)) | BA10: =IF(OR($A10="",$K10=""),"",$K10*12+N($L10)) | BB10: =IF(OR($A10="",$M10=""),"",$M10*12+N($N10)) | BC10: =IF($A10="","",IF(OR($C10="FRAME ONLY",$S10="BL"),0,IF($O10="Y",2,1))) | BD10: =IF(OR(N($BC10)=0,$BA10=""),"",($BA10-2*EdgeClr-IF($BC10=2,MeetClr,0))/$BC10) | BE10: =IF(OR(N($BC10)=0,$BB10=""),"",$BB10-HeadClr-Undercut) | BF10: =IF($BA10="","",$BA10+2*FaceW+IF(N($Q10)>0,($Q10+FaceW)*IF($R10="LR",2,1),0)) | BG10: =IF($BB10="","",$BB10+IF($AB10="Y",4,FaceW)+IF(N($P10)>0,$P10+FaceW,0)+IF(OR($S10="4F",$S10="BL"),FaceW,0)) | BH10: =IF($BF10="","",$BF10+2*ROSide) | BI10: =IF($BG10="","",$BG10+ROTop) | BJ10: =IF(OR(N($BC10)=0,$BA10=""),"",$BA10/$BC10-ClearDeduct) | BK10: =IF(OR(N($BC10)=0,$BE10=""),"",IF(OR($AC10="HGC",$AP10="HGC"),"CONT",IF($BE10<=60,2,IF($BE10<=90,3,IF($BE10<=120,4,5))))) | BL10: =IF(N($BC10)=0,"",IF(OR($AL10="",$AL10="FLUSH"),"FLUSH",IFERROR(LEFT($AL10,FIND("-",$AL10)-1),LEFT($AL10,2)))) | BM10: =IF($BL10="","",IFERROR(VALUE(MID($AL10,FIND("-",$AL10)+1,FIND(CHAR(34)&"x",$AL10)-FIND("-",$AL10)-1)),0)) | BN10: =IF($BL10="","",IFERROR(VALUE(MID($AL10,FIND(CHAR(34)&"x",$AL10)+2,FIND(CHAR(34),$AL10,FIND(CHAR(34)&"x",$AL10)+2)-FIND(CHAR(34)&"x",$AL10)-2)),0)) | BO10: =IF(OR($A10="",$H10="",$H10="NO LAB"),0,IFERROR(VALUE(LEFT($H10,FIND(" ",$H10)-1)),0)) | BP10: =IF(OR($A10="",$I10="",$I10="NON-RATED",N($J10)=0),"",IFERROR(VLOOKUP($I10&"|"&$J10,IBC,2,FALSE),"?")) | BQ10: =IF(NOT(AND($A10<>"",$C10<>"DOOR ONLY")),"",TRIM(IFERROR(VLOOKUP($U10,CODES,2,FALSE),"")&" "&$AZ10&" "&IFERROR(VLOOKUP($Z10,CODES,2,FALSE),"")&" "&IFERROR(VLOOKUP($X10,CODES,2,FALSE),"")&" "&IFERROR(VLOOKUP($S10,CODES,2,FALSE),"")&IF(N($P10)>0," w/TRANSOM "&$P10&CHAR(34),"")&IF(N($Q10)>0," w/SIDELITE "&$Q10&CHAR(34)&" "&IF($R10="","R",$R10),"")&IF($Y10=""," | "," | "&IFERROR(VLOOKUP($Y10,CODES,2,FALSE),"")&" | ")&IFERROR(VLOOKUP($AC10,CODES,2,FALSE),"")&" "&IFERROR(VLOOKUP($AD10,CODES,2,FALSE),"")&IF(OR($AE10="",$AE10="-"),""," "&$AE10)&IF(OR($AF10="",$AF10="-"),""," "&$AF10)&IF($AB10="Y"," 4"&CHAR(34)&" HEAD","")&" "&IFERROR(VLOOKUP($H10,CODES,2,FALSE),""))) | BR10: =IF(NOT(AND($A10<>"",N($BC10)>0)),"",TRIM(IFERROR(VLOOKUP($AH10,CODES,2,FALSE),"")&IF($AI10=""," "," "&$AI10&"GA ")&$AZ10&" "&IF($AN10="",IFERROR(VLOOKUP($Z10,CODES,2,FALSE),""),IFERROR(VLOOKUP($AN10,CODES,2,FALSE),""))&IF($BC10=2," PAIR","")&" DOOR | "&IF($AL10="","?",$AL10)&" | "&IF($AP10="",IFERROR(VLOOKUP($AC10,CODES,2,FALSE),""),IFERROR(VLOOKUP($AP10,CODES,2,FALSE),""))&" "&IFERROR(VLOOKUP($AQ10,CODES,2,FALSE),"")&IF(OR($AR10="",$AR10="-"),""," SEAM "&$AR10)&IF($AS10="Y"," ASTRAGAL","")&IF($AJ10=""," "," "&$AJ10)&IF($AK10=""," "," "&$AK10)&IF($AO10="",""," "&$AO10)&IF($AM10=""," "," SERIES "&$AM10)&" "&IFERROR(VLOOKUP($H10,CODES,2,FALSE),""))) | BS10: =IF(BV10="","",IF(COUNTIF($BV$6:BV10,BV10)=1,MAX($BS$5:BS9)+1,INDEX($BS$5:BS9,MATCH(BV10,$BV$5:BV9,0)))) | BT10: =IF(NOT(AND($A10<>"",$C10<>"DOOR ONLY")),"",MAX($BT$5:BT9)+1) | BU10: =IF(NOT(AND($A10<>"",N($BC10)>0)),"",MAX($BU$5:BU9)+1) | BV10: =IF(OR($A10="",$BA10="",$BB10=""),"",$AZ10&"|"&$O10&"|"&$AL10&"|"&$S10&"|"&$P10&"|"&$Q10&$R10&"|"&$C10&"|"&$AB10) | BW10: =IF($A10="","",IF($B10="","qty, ","")&IF($C10="","scope, ","")&IF(OR($K10="",$M10=""),"size, ","")&IF(AND($A10<>"",$C10<>"DOOR ONLY"),IF($U10="","jamb depth, ","")&IF($X10="","construction, ","")&IF($Y10="","anchor, ","")&IF($S10="","frame type, ",""),"")&IF(AND(N($BC10)>0,$Z10=""),"hand, ","")&IF(N($BC10)>0,IF($AH10="","door material, ","")&IF($AL10="","face type, ","")&IF($AQ10="","lock prep, ","")&IF(AND($AP10="",$AC10=""),"hinge prep, ",""),"")&IF(AND($BO10>0,$AH10="FRP"),"FRP cannot carry a label, ","")&IF(AND($O10="Y",OR($Z10="L",$Z10="R",$Z10="LR",$Z10="RR")),"pair marked but hand is single, ","")&IF(AND($O10<>"Y",OR($Z10="PR",AND(LEN($Z10)>1,ISNUMBER(SEARCH("-",$Z10))))),"pair hand on a single door, ","")&IF(AND(ISNUMBER($BP10),$BO10<N($BP10)),"wall needs a "&$BP10&" min door, ","")&IF(AND($BO10>=180,AND(OR($BL10="FG",$BL10="HG",$BL10="FNV",$BL10="FV"),N($BM10)*N($BN10)>100)),"180 min lite over 100 sq in, ","")&IF(N($BD10)>48,"leaf wider than 4'-0"&CHAR(34)&", ","")) | BX10: =IF($A10="","",IF(AND($BO10>0,AND($A10<>"",$C10<>"DOOR ONLY"),$X10="KD",$E10="EXTERIOR"),"KD label on an exterior opening, ","")&IF(AND($E10="EXTERIOR",OR(AND(AND($A10<>"",$C10<>"DOOR ONLY"),$W10="CR"),AND(N($BC10)>0,$AH10="CR"))),"exterior in CR steel (G9?), ","")&IF(AND(ISNUMBER($BJ10),N($BJ10)<32),"clear width ~"&TEXT($BJ10,"0.0")&CHAR(34)&" under 32"&CHAR(34)&" (ADA), ","")&IF(AND($BO10=90,AND(OR($BL10="FG",$BL10="HG",$BL10="FNV",$BL10="FV"),N($BM10)*N($BN10)>100)),"90 min lite over 100 sq in (stair/exit), ","")&IF(AND($BO10>0,AND($A10<>"",$C10<>"DOOR ONLY"),OR($AF10="",$AF10="-")),"rated: closer reinf.?, ","")&IF(OR($I10="CORRIDOR",$I10="SMOKE BARRIER"),"S label + smoke gasketing, ","")&IF($BP10="?","wall type/hr not in IBC table, ","")&IF(AND(N($BC10)>0,$AU10=""),"no hardware set, ","")&IF(AND($AU10<>"",ISNA(MATCH($AU10,HWSets,0))),"set "&$AU10&" not on Hardware sheet, ","")&IF(N($BE10)>96,"leaf over 8'-0"&CHAR(34)&" - check listing, ",""))
A11: 106 | B11: 1 | C11: FRAME & DOOR | D11: 2nd | E11: INTERIOR | F11: CORRIDOR | G11: MECH 201 | H11: 60 MIN | I11: FIRE BARRIER | J11: 2 | K11: 3 | L11: 6 | M11: 7 | N11: 0 | S11: 3F | T11: M | U11: 534 | V11: 16 | W11: CR | X11: KD | Y11: SC | Z11: L | AA11: CU | AC11: U453 | AD11: E1 | AF11: E11 | AH11: CR | AI11: 18 | AL11: FLUSH | AM11: 707 | AO11: CURRIES | AQ11: G2 | AU11: 1 | AW11: =IF($A11="","",IF($BW11<>"","FIX",IF($BX11<>"","CHECK","OK"))) | AX11: =IF($A11="","",IF($BW11<>"","FIX: "&LEFT($BW11,LEN($BW11)-2)&IF($BX11<>""," · ",""),"")&IF($BX11<>"","CHECK: "&LEFT($BX11,LEN($BX11)-2),"")) | AY11: =IF(OR($A11="",$K11=""),"",$K11&"'-"&N($L11)&CHAR(34)&" x "&$M11&"'-"&N($N11)&CHAR(34)) | AZ11: =IF(OR($A11="",$K11=""),"",$K11&N($L11)&$M11&N($N11)) | BA11: =IF(OR($A11="",$K11=""),"",$K11*12+N($L11)) | BB11: =IF(OR($A11="",$M11=""),"",$M11*12+N($N11)) | BC11: =IF($A11="","",IF(OR($C11="FRAME ONLY",$S11="BL"),0,IF($O11="Y",2,1))) | BD11: =IF(OR(N($BC11)=0,$BA11=""),"",($BA11-2*EdgeClr-IF($BC11=2,MeetClr,0))/$BC11) | BE11: =IF(OR(N($BC11)=0,$BB11=""),"",$BB11-HeadClr-Undercut) | BF11: =IF($BA11="","",$BA11+2*FaceW+IF(N($Q11)>0,($Q11+FaceW)*IF($R11="LR",2,1),0)) | BG11: =IF($BB11="","",$BB11+IF($AB11="Y",4,FaceW)+IF(N($P11)>0,$P11+FaceW,0)+IF(OR($S11="4F",$S11="BL"),FaceW,0)) | BH11: =IF($BF11="","",$BF11+2*ROSide) | BI11: =IF($BG11="","",$BG11+ROTop) | BJ11: =IF(OR(N($BC11)=0,$BA11=""),"",$BA11/$BC11-ClearDeduct) | BK11: =IF(OR(N($BC11)=0,$BE11=""),"",IF(OR($AC11="HGC",$AP11="HGC"),"CONT",IF($BE11<=60,2,IF($BE11<=90,3,IF($BE11<=120,4,5))))) | BL11: =IF(N($BC11)=0,"",IF(OR($AL11="",$AL11="FLUSH"),"FLUSH",IFERROR(LEFT($AL11,FIND("-",$AL11)-1),LEFT($AL11,2)))) | BM11: =IF($BL11="","",IFERROR(VALUE(MID($AL11,FIND("-",$AL11)+1,FIND(CHAR(34)&"x",$AL11)-FIND("-",$AL11)-1)),0)) | BN11: =IF($BL11="","",IFERROR(VALUE(MID($AL11,FIND(CHAR(34)&"x",$AL11)+2,FIND(CHAR(34),$AL11,FIND(CHAR(34)&"x",$AL11)+2)-FIND(CHAR(34)&"x",$AL11)-2)),0)) | BO11: =IF(OR($A11="",$H11="",$H11="NO LAB"),0,IFERROR(VALUE(LEFT($H11,FIND(" ",$H11)-1)),0)) | BP11: =IF(OR($A11="",$I11="",$I11="NON-RATED",N($J11)=0),"",IFERROR(VLOOKUP($I11&"|"&$J11,IBC,2,FALSE),"?")) | BQ11: =IF(NOT(AND($A11<>"",$C11<>"DOOR ONLY")),"",TRIM(IFERROR(VLOOKUP($U11,CODES,2,FALSE),"")&" "&$AZ11&" "&IFERROR(VLOOKUP($Z11,CODES,2,FALSE),"")&" "&IFERROR(VLOOKUP($X11,CODES,2,FALSE),"")&" "&IFERROR(VLOOKUP($S11,CODES,2,FALSE),"")&IF(N($P11)>0," w/TRANSOM "&$P11&CHAR(34),"")&IF(N($Q11)>0," w/SIDELITE "&$Q11&CHAR(34)&" "&IF($R11="","R",$R11),"")&IF($Y11=""," | "," | "&IFERROR(VLOOKUP($Y11,CODES,2,FALSE),"")&" | ")&IFERROR(VLOOKUP($AC11,CODES,2,FALSE),"")&" "&IFERROR(VLOOKUP($AD11,CODES,2,FALSE),"")&IF(OR($AE11="",$AE11="-"),""," "&$AE11)&IF(OR($AF11="",$AF11="-"),""," "&$AF11)&IF($AB11="Y"," 4"&CHAR(34)&" HEAD","")&" "&IFERROR(VLOOKUP($H11,CODES,2,FALSE),""))) | BR11: =IF(NOT(AND($A11<>"",N($BC11)>0)),"",TRIM(IFERROR(VLOOKUP($AH11,CODES,2,FALSE),"")&IF($AI11=""," "," "&$AI11&"GA ")&$AZ11&" "&IF($AN11="",IFERROR(VLOOKUP($Z11,CODES,2,FALSE),""),IFERROR(VLOOKUP($AN11,CODES,2,FALSE),""))&IF($BC11=2," PAIR","")&" DOOR | "&IF($AL11="","?",$AL11)&" | "&IF($AP11="",IFERROR(VLOOKUP($AC11,CODES,2,FALSE),""),IFERROR(VLOOKUP($AP11,CODES,2,FALSE),""))&" "&IFERROR(VLOOKUP($AQ11,CODES,2,FALSE),"")&IF(OR($AR11="",$AR11="-"),""," SEAM "&$AR11)&IF($AS11="Y"," ASTRAGAL","")&IF($AJ11=""," "," "&$AJ11)&IF($AK11=""," "," "&$AK11)&IF($AO11="",""," "&$AO11)&IF($AM11=""," "," SERIES "&$AM11)&" "&IFERROR(VLOOKUP($H11,CODES,2,FALSE),""))) | BS11: =IF(BV11="","",IF(COUNTIF($BV$6:BV11,BV11)=1,MAX($BS$5:BS10)+1,INDEX($BS$5:BS10,MATCH(BV11,$BV$5:BV10,0)))) | BT11: =IF(NOT(AND($A11<>"",$C11<>"DOOR ONLY")),"",MAX($BT$5:BT10)+1) | BU11: =IF(NOT(AND($A11<>"",N($BC11)>0)),"",MAX($BU$5:BU10)+1) | BV11: =IF(OR($A11="",$BA11="",$BB11=""),"",$AZ11&"|"&$O11&"|"&$AL11&"|"&$S11&"|"&$P11&"|"&$Q11&$R11&"|"&$C11&"|"&$AB11) | BW11: =IF($A11="","",IF($B11="","qty, ","")&IF($C11="","scope, ","")&IF(OR($K11="",$M11=""),"size, ","")&IF(AND($A11<>"",$C11<>"DOOR ONLY"),IF($U11="","jamb depth, ","")&IF($X11="","construction, ","")&IF($Y11="","anchor, ","")&IF($S11="","frame type, ",""),"")&IF(AND(N($BC11)>0,$Z11=""),"hand, ","")&IF(N($BC11)>0,IF($AH11="","door material, ","")&IF($AL11="","face type, ","")&IF($AQ11="","lock prep, ","")&IF(AND($AP11="",$AC11=""),"hinge prep, ",""),"")&IF(AND($BO11>0,$AH11="FRP"),"FRP cannot carry a label, ","")&IF(AND($O11="Y",OR($Z11="L",$Z11="R",$Z11="LR",$Z11="RR")),"pair marked but hand is single, ","")&IF(AND($O11<>"Y",OR($Z11="PR",AND(LEN($Z11)>1,ISNUMBER(SEARCH("-",$Z11))))),"pair hand on a single door, ","")&IF(AND(ISNUMBER($BP11),$BO11<N($BP11)),"wall needs a "&$BP11&" min door, ","")&IF(AND($BO11>=180,AND(OR($BL11="FG",$BL11="HG",$BL11="FNV",$BL11="FV"),N($BM11)*N($BN11)>100)),"180 min lite over 100 sq in, ","")&IF(N($BD11)>48,"leaf wider than 4'-0"&CHAR(34)&", ","")) | BX11: =IF($A11="","",IF(AND($BO11>0,AND($A11<>"",$C11<>"DOOR ONLY"),$X11="KD",$E11="EXTERIOR"),"KD label on an exterior opening, ","")&IF(AND($E11="EXTERIOR",OR(AND(AND($A11<>"",$C11<>"DOOR ONLY"),$W11="CR"),AND(N($BC11)>0,$AH11="CR"))),"exterior in CR steel (G9?), ","")&IF(AND(ISNUMBER($BJ11),N($BJ11)<32),"clear width ~"&TEXT($BJ11,"0.0")&CHAR(34)&" under 32"&CHAR(34)&" (ADA), ","")&IF(AND($BO11=90,AND(OR($BL11="FG",$BL11="HG",$BL11="FNV",$BL11="FV"),N($BM11)*N($BN11)>100)),"90 min lite over 100 sq in (stair/exit), ","")&IF(AND($BO11>0,AND($A11<>"",$C11<>"DOOR ONLY"),OR($AF11="",$AF11="-")),"rated: closer reinf.?, ","")&IF(OR($I11="CORRIDOR",$I11="SMOKE BARRIER"),"S label + smoke gasketing, ","")&IF($BP11="?","wall type/hr not in IBC table, ","")&IF(AND(N($BC11)>0,$AU11=""),"no hardware set, ","")&IF(AND($AU11<>"",ISNA(MATCH($AU11,HWSets,0))),"set "&$AU11&" not on Hardware sheet, ","")&IF(N($BE11)>96,"leaf over 8'-0"&CHAR(34)&" - check listing, ",""))
A12: 107 | B12: 2 | C12: DOOR ONLY | D12: 2nd | E12: INTERIOR | F12: OFFICE | G12: TOILET | H12: NO LAB | I12: NON-RATED | K12: 2 | L12: 8 | M12: 7 | N12: 0 | Z12: RR | AC12: U453 | AH12: BIR-PC | AJ12: PC | AK12: RWB | AL12: FLUSH | AQ12: G2 | AU12: 1 | AW12: =IF($A12="","",IF($BW12<>"","FIX",IF($BX12<>"","CHECK","OK"))) | AX12: =IF($A12="","",IF($BW12<>"","FIX: "&LEFT($BW12,LEN($BW12)-2)&IF($BX12<>""," · ",""),"")&IF($BX12<>"","CHECK: "&LEFT($BX12,LEN($BX12)-2),"")) | AY12: =IF(OR($A12="",$K12=""),"",$K12&"'-"&N($L12)&CHAR(34)&" x "&$M12&"'-"&N($N12)&CHAR(34)) | AZ12: =IF(OR($A12="",$K12=""),"",$K12&N($L12)&$M12&N($N12)) | BA12: =IF(OR($A12="",$K12=""),"",$K12*12+N($L12)) | BB12: =IF(OR($A12="",$M12=""),"",$M12*12+N($N12)) | BC12: =IF($A12="","",IF(OR($C12="FRAME ONLY",$S12="BL"),0,IF($O12="Y",2,1))) | BD12: =IF(OR(N($BC12)=0,$BA12=""),"",($BA12-2*EdgeClr-IF($BC12=2,MeetClr,0))/$BC12) | BE12: =IF(OR(N($BC12)=0,$BB12=""),"",$BB12-HeadClr-Undercut) | BF12: =IF($BA12="","",$BA12+2*FaceW+IF(N($Q12)>0,($Q12+FaceW)*IF($R12="LR",2,1),0)) | BG12: =IF($BB12="","",$BB12+IF($AB12="Y",4,FaceW)+IF(N($P12)>0,$P12+FaceW,0)+IF(OR($S12="4F",$S12="BL"),FaceW,0)) | BH12: =IF($BF12="","",$BF12+2*ROSide) | BI12: =IF($BG12="","",$BG12+ROTop) | BJ12: =IF(OR(N($BC12)=0,$BA12=""),"",$BA12/$BC12-ClearDeduct) | BK12: =IF(OR(N($BC12)=0,$BE12=""),"",IF(OR($AC12="HGC",$AP12="HGC"),"CONT",IF($BE12<=60,2,IF($BE12<=90,3,IF($BE12<=120,4,5))))) | BL12: =IF(N($BC12)=0,"",IF(OR($AL12="",$AL12="FLUSH"),"FLUSH",IFERROR(LEFT($AL12,FIND("-",$AL12)-1),LEFT($AL12,2)))) | BM12: =IF($BL12="","",IFERROR(VALUE(MID($AL12,FIND("-",$AL12)+1,FIND(CHAR(34)&"x",$AL12)-FIND("-",$AL12)-1)),0)) | BN12: =IF($BL12="","",IFERROR(VALUE(MID($AL12,FIND(CHAR(34)&"x",$AL12)+2,FIND(CHAR(34),$AL12,FIND(CHAR(34)&"x",$AL12)+2)-FIND(CHAR(34)&"x",$AL12)-2)),0)) | BO12: =IF(OR($A12="",$H12="",$H12="NO LAB"),0,IFERROR(VALUE(LEFT($H12,FIND(" ",$H12)-1)),0)) | BP12: =IF(OR($A12="",$I12="",$I12="NON-RATED",N($J12)=0),"",IFERROR(VLOOKUP($I12&"|"&$J12,IBC,2,FALSE),"?")) | BQ12: =IF(NOT(AND($A12<>"",$C12<>"DOOR ONLY")),"",TRIM(IFERROR(VLOOKUP($U12,CODES,2,FALSE),"")&" "&$AZ12&" "&IFERROR(VLOOKUP($Z12,CODES,2,FALSE),"")&" "&IFERROR(VLOOKUP($X12,CODES,2,FALSE),"")&" "&IFERROR(VLOOKUP($S12,CODES,2,FALSE),"")&IF(N($P12)>0," w/TRANSOM "&$P12&CHAR(34),"")&IF(N($Q12)>0," w/SIDELITE "&$Q12&CHAR(34)&" "&IF($R12="","R",$R12),"")&IF($Y12=""," | "," | "&IFERROR(VLOOKUP($Y12,CODES,2,FALSE),"")&" | ")&IFERROR(VLOOKUP($AC12,CODES,2,FALSE),"")&" "&IFERROR(VLOOKUP($AD12,CODES,2,FALSE),"")&IF(OR($AE12="",$AE12="-"),""," "&$AE12)&IF(OR($AF12="",$AF12="-"),""," "&$AF12)&IF($AB12="Y"," 4"&CHAR(34)&" HEAD","")&" "&IFERROR(VLOOKUP($H12,CODES,2,FALSE),""))) | BR12: =IF(NOT(AND($A12<>"",N($BC12)>0)),"",TRIM(IFERROR(VLOOKUP($AH12,CODES,2,FALSE),"")&IF($AI12=""," "," "&$AI12&"GA ")&$AZ12&" "&IF($AN12="",IFERROR(VLOOKUP($Z12,CODES,2,FALSE),""),IFERROR(VLOOKUP($AN12,CODES,2,FALSE),""))&IF($BC12=2," PAIR","")&" DOOR | "&IF($AL12="","?",$AL12)&" | "&IF($AP12="",IFERROR(VLOOKUP($AC12,CODES,2,FALSE),""),IFERROR(VLOOKUP($AP12,CODES,2,FALSE),""))&" "&IFERROR(VLOOKUP($AQ12,CODES,2,FALSE),"")&IF(OR($AR12="",$AR12="-"),""," SEAM "&$AR12)&IF($AS12="Y"," ASTRAGAL","")&IF($AJ12=""," "," "&$AJ12)&IF($AK12=""," "," "&$AK12)&IF($AO12="",""," "&$AO12)&IF($AM12=""," "," SERIES "&$AM12)&" "&IFERROR(VLOOKUP($H12,CODES,2,FALSE),""))) | BS12: =IF(BV12="","",IF(COUNTIF($BV$6:BV12,BV12)=1,MAX($BS$5:BS11)+1,INDEX($BS$5:BS11,MATCH(BV12,$BV$5:BV11,0)))) | BT12: =IF(NOT(AND($A12<>"",$C12<>"DOOR ONLY")),"",MAX($BT$5:BT11)+1) | BU12: =IF(NOT(AND($A12<>"",N($BC12)>0)),"",MAX($BU$5:BU11)+1) | BV12: =IF(OR($A12="",$BA12="",$BB12=""),"",$AZ12&"|"&$O12&"|"&$AL12&"|"&$S12&"|"&$P12&"|"&$Q12&$R12&"|"&$C12&"|"&$AB12) | BW12: =IF($A12="","",IF($B12="","qty, ","")&IF($C12="","scope, ","")&IF(OR($K12="",$M12=""),"size, ","")&IF(AND($A12<>"",$C12<>"DOOR ONLY"),IF($U12="","jamb depth, ","")&IF($X12="","construction, ","")&IF($Y12="","anchor, ","")&IF($S12="","frame type, ",""),"")&IF(AND(N($BC12)>0,$Z12=""),"hand, ","")&IF(N($BC12)>0,IF($AH12="","door material, ","")&IF($AL12="","face type, ","")&IF($AQ12="","lock prep, ","")&IF(AND($AP12="",$AC12=""),"hinge prep, ",""),"")&IF(AND($BO12>0,$AH12="FRP"),"FRP cannot carry a label, ","")&IF(AND($O12="Y",OR($Z12="L",$Z12="R",$Z12="LR",$Z12="RR")),"pair marked but hand is single, ","")&IF(AND($O12<>"Y",OR($Z12="PR",AND(LEN($Z12)>1,ISNUMBER(SEARCH("-",$Z12))))),"pair hand on a single door, ","")&IF(AND(ISNUMBER($BP12),$BO12<N($BP12)),"wall needs a "&$BP12&" min door, ","")&IF(AND($BO12>=180,AND(OR($BL12="FG",$BL12="HG",$BL12="FNV",$BL12="FV"),N($BM12)*N($BN12)>100)),"180 min lite over 100 sq in, ","")&IF(N($BD12)>48,"leaf wider than 4'-0"&CHAR(34)&", ","")) | BX12: =IF($A12="","",IF(AND($BO12>0,AND($A12<>"",$C12<>"DOOR ONLY"),$X12="KD",$E12="EXTERIOR"),"KD label on an exterior opening, ","")&IF(AND($E12="EXTERIOR",OR(AND(AND($A12<>"",$C12<>"DOOR ONLY"),$W12="CR"),AND(N($BC12)>0,$AH12="CR"))),"exterior in CR steel (G9?), ","")&IF(AND(ISNUMBER($BJ12),N($BJ12)<32),"clear width ~"&TEXT($BJ12,"0.0")&CHAR(34)&" under 32"&CHAR(34)&" (ADA), ","")&IF(AND($BO12=90,AND(OR($BL12="FG",$BL12="HG",$BL12="FNV",$BL12="FV"),N($BM12)*N($BN12)>100)),"90 min lite over 100 sq in (stair/exit), ","")&IF(AND($BO12>0,AND($A12<>"",$C12<>"DOOR ONLY"),OR($AF12="",$AF12="-")),"rated: closer reinf.?, ","")&IF(OR($I12="CORRIDOR",$I12="SMOKE BARRIER"),"S label + smoke gasketing, ","")&IF($BP12="?","wall type/hr not in IBC table, ","")&IF(AND(N($BC12)>0,$AU12=""),"no hardware set, ","")&IF(AND($AU12<>"",ISNA(MATCH($AU12,HWSets,0))),"set "&$AU12&" not on Hardware sheet, ","")&IF(N($BE12)>96,"leaf over 8'-0"&CHAR(34)&" - check listing, ",""))
A13: 108 | B13: 1 | C13: FRAME & DOOR | D13: 2nd | E13: INTERIOR | F13: CORRIDOR | G13: CONFERENCE | H13: 20 MIN | I13: CORRIDOR | J13: 1 | K13: 6 | L13: 0 | M13: 8 | N13: 0 | O13: Y | S13: 3F | T13: M | U13: 534 | V13: 16 | W13: CR | X13: KD | Y13: SC | Z13: LR-A | AA13: CU | AC13: U454 | AD13: E1 | AF13: E11 | AH13: MAP-MC | AJ13: MC | AK13: PWM | AL13: FG-22"x64" (WD) | AQ13: G2 | AS13: Y | AU13: 2 | AW13: =IF($A13="","",IF($BW13<>"","FIX",IF($BX13<>"","CHECK","OK"))) | AX13: =IF($A13="","",IF($BW13<>"","FIX: "&LEFT($BW13,LEN($BW13)-2)&IF($BX13<>""," · ",""),"")&IF($BX13<>"","CHECK: "&LEFT($BX13,LEN($BX13)-2),"")) | AY13: =IF(OR($A13="",$K13=""),"",$K13&"'-"&N($L13)&CHAR(34)&" x "&$M13&"'-"&N($N13)&CHAR(34)) | AZ13: =IF(OR($A13="",$K13=""),"",$K13&N($L13)&$M13&N($N13)) | BA13: =IF(OR($A13="",$K13=""),"",$K13*12+N($L13)) | BB13: =IF(OR($A13="",$M13=""),"",$M13*12+N($N13)) | BC13: =IF($A13="","",IF(OR($C13="FRAME ONLY",$S13="BL"),0,IF($O13="Y",2,1))) | BD13: =IF(OR(N($BC13)=0,$BA13=""),"",($BA13-2*EdgeClr-IF($BC13=2,MeetClr,0))/$BC13) | BE13: =IF(OR(N($BC13)=0,$BB13=""),"",$BB13-HeadClr-Undercut) | BF13: =IF($BA13="","",$BA13+2*FaceW+IF(N($Q13)>0,($Q13+FaceW)*IF($R13="LR",2,1),0)) | BG13: =IF($BB13="","",$BB13+IF($AB13="Y",4,FaceW)+IF(N($P13)>0,$P13+FaceW,0)+IF(OR($S13="4F",$S13="BL"),FaceW,0)) | BH13: =IF($BF13="","",$BF13+2*ROSide) | BI13: =IF($BG13="","",$BG13+ROTop) | BJ13: =IF(OR(N($BC13)=0,$BA13=""),"",$BA13/$BC13-ClearDeduct) | BK13: =IF(OR(N($BC13)=0,$BE13=""),"",IF(OR($AC13="HGC",$AP13="HGC"),"CONT",IF($BE13<=60,2,IF($BE13<=90,3,IF($BE13<=120,4,5))))) | BL13: =IF(N($BC13)=0,"",IF(OR($AL13="",$AL13="FLUSH"),"FLUSH",IFERROR(LEFT($AL13,FIND("-",$AL13)-1),LEFT($AL13,2)))) | BM13: =IF($BL13="","",IFERROR(VALUE(MID($AL13,FIND("-",$AL13)+1,FIND(CHAR(34)&"x",$AL13)-FIND("-",$AL13)-1)),0)) | BN13: =IF($BL13="","",IFERROR(VALUE(MID($AL13,FIND(CHAR(34)&"x",$AL13)+2,FIND(CHAR(34),$AL13,FIND(CHAR(34)&"x",$AL13)+2)-FIND(CHAR(34)&"x",$AL13)-2)),0)) | BO13: =IF(OR($A13="",$H13="",$H13="NO LAB"),0,IFERROR(VALUE(LEFT($H13,FIND(" ",$H13)-1)),0)) | BP13: =IF(OR($A13="",$I13="",$I13="NON-RATED",N($J13)=0),"",IFERROR(VLOOKUP($I13&"|"&$J13,IBC,2,FALSE),"?")) | BQ13: =IF(NOT(AND($A13<>"",$C13<>"DOOR ONLY")),"",TRIM(IFERROR(VLOOKUP($U13,CODES,2,FALSE),"")&" "&$AZ13&" "&IFERROR(VLOOKUP($Z13,CODES,2,FALSE),"")&" "&IFERROR(VLOOKUP($X13,CODES,2,FALSE),"")&" "&IFERROR(VLOOKUP($S13,CODES,2,FALSE),"")&IF(N($P13)>0," w/TRANSOM "&$P13&CHAR(34),"")&IF(N($Q13)>0," w/SIDELITE "&$Q13&CHAR(34)&" "&IF($R13="","R",$R13),"")&IF($Y13=""," | "," | "&IFERROR(VLOOKUP($Y13,CODES,2,FALSE),"")&" | ")&IFERROR(VLOOKUP($AC13,CODES,2,FALSE),"")&" "&IFERROR(VLOOKUP($AD13,CODES,2,FALSE),"")&IF(OR($AE13="",$AE13="-"),""," "&$AE13)&IF(OR($AF13="",$AF13="-"),""," "&$AF13)&IF($AB13="Y"," 4"&CHAR(34)&" HEAD","")&" "&IFERROR(VLOOKUP($H13,CODES,2,FALSE),""))) | BR13: =IF(NOT(AND($A13<>"",N($BC13)>0)),"",TRIM(IFERROR(VLOOKUP($AH13,CODES,2,FALSE),"")&IF($AI13=""," "," "&$AI13&"GA ")&$AZ13&" "&IF($AN13="",IFERROR(VLOOKUP($Z13,CODES,2,FALSE),""),IFERROR(VLOOKUP($AN13,CODES,2,FALSE),""))&IF($BC13=2," PAIR","")&" DOOR | "&IF($AL13="","?",$AL13)&" | "&IF($AP13="",IFERROR(VLOOKUP($AC13,CODES,2,FALSE),""),IFERROR(VLOOKUP($AP13,CODES,2,FALSE),""))&" "&IFERROR(VLOOKUP($AQ13,CODES,2,FALSE),"")&IF(OR($AR13="",$AR13="-"),""," SEAM "&$AR13)&IF($AS13="Y"," ASTRAGAL","")&IF($AJ13=""," "," "&$AJ13)&IF($AK13=""," "," "&$AK13)&IF($AO13="",""," "&$AO13)&IF($AM13=""," "," SERIES "&$AM13)&" "&IFERROR(VLOOKUP($H13,CODES,2,FALSE),""))) | BS13: =IF(BV13="","",IF(COUNTIF($BV$6:BV13,BV13)=1,MAX($BS$5:BS12)+1,INDEX($BS$5:BS12,MATCH(BV13,$BV$5:BV12,0)))) | BT13: =IF(NOT(AND($A13<>"",$C13<>"DOOR ONLY")),"",MAX($BT$5:BT12)+1) | BU13: =IF(NOT(AND($A13<>"",N($BC13)>0)),"",MAX($BU$5:BU12)+1) | BV13: =IF(OR($A13="",$BA13="",$BB13=""),"",$AZ13&"|"&$O13&"|"&$AL13&"|"&$S13&"|"&$P13&"|"&$Q13&$R13&"|"&$C13&"|"&$AB13) | BW13: =IF($A13="","",IF($B13="","qty, ","")&IF($C13="","scope, ","")&IF(OR($K13="",$M13=""),"size, ","")&IF(AND($A13<>"",$C13<>"DOOR ONLY"),IF($U13="","jamb depth, ","")&IF($X13="","construction, ","")&IF($Y13="","anchor, ","")&IF($S13="","frame type, ",""),"")&IF(AND(N($BC13)>0,$Z13=""),"hand, ","")&IF(N($BC13)>0,IF($AH13="","door material, ","")&IF($AL13="","face type, ","")&IF($AQ13="","lock prep, ","")&IF(AND($AP13="",$AC13=""),"hinge prep, ",""),"")&IF(AND($BO13>0,$AH13="FRP"),"FRP cannot carry a label, ","")&IF(AND($O13="Y",OR($Z13="L",$Z13="R",$Z13="LR",$Z13="RR")),"pair marked but hand is single, ","")&IF(AND($O13<>"Y",OR($Z13="PR",AND(LEN($Z13)>1,ISNUMBER(SEARCH("-",$Z13))))),"pair hand on a single door, ","")&IF(AND(ISNUMBER($BP13),$BO13<N($BP13)),"wall needs a "&$BP13&" min door, ","")&IF(AND($BO13>=180,AND(OR($BL13="FG",$BL13="HG",$BL13="FNV",$BL13="FV"),N($BM13)*N($BN13)>100)),"180 min lite over 100 sq in, ","")&IF(N($BD13)>48,"leaf wider than 4'-0"&CHAR(34)&", ","")) | BX13: =IF($A13="","",IF(AND($BO13>0,AND($A13<>"",$C13<>"DOOR ONLY"),$X13="KD",$E13="EXTERIOR"),"KD label on an exterior opening, ","")&IF(AND($E13="EXTERIOR",OR(AND(AND($A13<>"",$C13<>"DOOR ONLY"),$W13="CR"),AND(N($BC13)>0,$AH13="CR"))),"exterior in CR steel (G9?), ","")&IF(AND(ISNUMBER($BJ13),N($BJ13)<32),"clear width ~"&TEXT($BJ13,"0.0")&CHAR(34)&" under 32"&CHAR(34)&" (ADA), ","")&IF(AND($BO13=90,AND(OR($BL13="FG",$BL13="HG",$BL13="FNV",$BL13="FV"),N($BM13)*N($BN13)>100)),"90 min lite over 100 sq in (stair/exit), ","")&IF(AND($BO13>0,AND($A13<>"",$C13<>"DOOR ONLY"),OR($AF13="",$AF13="-")),"rated: closer reinf.?, ","")&IF(OR($I13="CORRIDOR",$I13="SMOKE BARRIER"),"S label + smoke gasketing, ","")&IF($BP13="?","wall type/hr not in IBC table, ","")&IF(AND(N($BC13)>0,$AU13=""),"no hardware set, ","")&IF(AND($AU13<>"",ISNA(MATCH($AU13,HWSets,0))),"set "&$AU13&" not on Hardware sheet, ","")&IF(N($BE13)>96,"leaf over 8'-0"&CHAR(34)&" - check listing, ",""))
AW14: =IF($A14="","",IF($BW14<>"","FIX",IF($BX14<>"","CHECK","OK"))) | AX14: =IF($A14="","",IF($BW14<>"","FIX: "&LEFT($BW14,LEN($BW14)-2)&IF($BX14<>""," · ",""),"")&IF($BX14<>"","CHECK: "&LEFT($BX14,LEN($BX14)-2),"")) | AY14: =IF(OR($A14="",$K14=""),"",$K14&"'-"&N($L14)&CHAR(34)&" x "&$M14&"'-"&N($N14)&CHAR(34)) | AZ14: =IF(OR($A14="",$K14=""),"",$K14&N($L14)&$M14&N($N14)) | BA14: =IF(OR($A14="",$K14=""),"",$K14*12+N($L14)) | BB14: =IF(OR($A14="",$M14=""),"",$M14*12+N($N14)) | BC14: =IF($A14="","",IF(OR($C14="FRAME ONLY",$S14="BL"),0,IF($O14="Y",2,1))) | BD14: =IF(OR(N($BC14)=0,$BA14=""),"",($BA14-2*EdgeClr-IF($BC14=2,MeetClr,0))/$BC14) | BE14: =IF(OR(N($BC14)=0,$BB14=""),"",$BB14-HeadClr-Undercut) | BF14: =IF($BA14="","",$BA14+2*FaceW+IF(N($Q14)>0,($Q14+FaceW)*IF($R14="LR",2,1),0)) | BG14: =IF($BB14="","",$BB14+IF($AB14="Y",4,FaceW)+IF(N($P14)>0,$P14+FaceW,0)+IF(OR($S14="4F",$S14="BL"),FaceW,0)) | BH14: =IF($BF14="","",$BF14+2*ROSide) | BI14: =IF($BG14="","",$BG14+ROTop) | BJ14: =IF(OR(N($BC14)=0,$BA14=""),"",$BA14/$BC14-ClearDeduct) | BK14: =IF(OR(N($BC14)=0,$BE14=""),"",IF(OR($AC14="HGC",$AP14="HGC"),"CONT",IF($BE14<=60,2,IF($BE14<=90,3,IF($BE14<=120,4,5))))) | BL14: =IF(N($BC14)=0,"",IF(OR($AL14="",$AL14="FLUSH"),"FLUSH",IFERROR(LEFT($AL14,FIND("-",$AL14)-1),LEFT($AL14,2)))) | BM14: =IF($BL14="","",IFERROR(VALUE(MID($AL14,FIND("-",$AL14)+1,FIND(CHAR(34)&"x",$AL14)-FIND("-",$AL14)-1)),0)) | BN14: =IF($BL14="","",IFERROR(VALUE(MID($AL14,FIND(CHAR(34)&"x",$AL14)+2,FIND(CHAR(34),$AL14,FIND(CHAR(34)&"x",$AL14)+2)-FIND(CHAR(34)&"x",$AL14)-2)),0)) | BO14: =IF(OR($A14="",$H14="",$H14="NO LAB"),0,IFERROR(VALUE(LEFT($H14,FIND(" ",$H14)-1)),0)) | BP14: =IF(OR($A14="",$I14="",$I14="NON-RATED",N($J14)=0),"",IFERROR(VLOOKUP($I14&"|"&$J14,IBC,2,FALSE),"?")) | BQ14: =IF(NOT(AND($A14<>"",$C14<>"DOOR ONLY")),"",TRIM(IFERROR(VLOOKUP($U14,CODES,2,FALSE),"")&" "&$AZ14&" "&IFERROR(VLOOKUP($Z14,CODES,2,FALSE),"")&" "&IFERROR(VLOOKUP($X14,CODES,2,FALSE),"")&" "&IFERROR(VLOOKUP($S14,CODES,2,FALSE),"")&IF(N($P14)>0," w/TRANSOM "&$P14&CHAR(34),"")&IF(N($Q14)>0," w/SIDELITE "&$Q14&CHAR(34)&" "&IF($R14="","R",$R14),"")&IF($Y14=""," | "," | "&IFERROR(VLOOKUP($Y14,CODES,2,FALSE),"")&" | ")&IFERROR(VLOOKUP($AC14,CODES,2,FALSE),"")&" "&IFERROR(VLOOKUP($AD14,CODES,2,FALSE),"")&IF(OR($AE14="",$AE14="-"),""," "&$AE14)&IF(OR($AF14="",$AF14="-"),""," "&$AF14)&IF($AB14="Y"," 4"&CHAR(34)&" HEAD","")&" "&IFERROR(VLOOKUP($H14,CODES,2,FALSE),""))) | BR14: =IF(NOT(AND($A14<>"",N($BC14)>0)),"",TRIM(IFERROR(VLOOKUP($AH14,CODES,2,FALSE),"")&IF($AI14=""," "," "&$AI14&"GA ")&$AZ14&" "&IF($AN14="",IFERROR(VLOOKUP($Z14,CODES,2,FALSE),""),IFERROR(VLOOKUP($AN14,CODES,2,FALSE),""))&IF($BC14=2," PAIR","")&" DOOR | "&IF($AL14="","?",$AL14)&" | "&IF($AP14="",IFERROR(VLOOKUP($AC14,CODES,2,FALSE),""),IFERROR(VLOOKUP($AP14,CODES,2,FALSE),""))&" "&IFERROR(VLOOKUP($AQ14,CODES,2,FALSE),"")&IF(OR($AR14="",$AR14="-"),""," SEAM "&$AR14)&IF($AS14="Y"," ASTRAGAL","")&IF($AJ14=""," "," "&$AJ14)&IF($AK14=""," "," "&$AK14)&IF($AO14="",""," "&$AO14)&IF($AM14=""," "," SERIES "&$AM14)&" "&IFERROR(VLOOKUP($H14,CODES,2,FALSE),""))) | BS14: =IF(BV14="","",IF(COUNTIF($BV$6:BV14,BV14)=1,MAX($BS$5:BS13)+1,INDEX($BS$5:BS13,MATCH(BV14,$BV$5:BV13,0)))) | BT14: =IF(NOT(AND($A14<>"",$C14<>"DOOR ONLY")),"",MAX($BT$5:BT13)+1) | BU14: =IF(NOT(AND($A14<>"",N($BC14)>0)),"",MAX($BU$5:BU13)+1) | BV14: =IF(OR($A14="",$BA14="",$BB14=""),"",$AZ14&"|"&$O14&"|"&$AL14&"|"&$S14&"|"&$P14&"|"&$Q14&$R14&"|"&$C14&"|"&$AB14) | BW14: =IF($A14="","",IF($B14="","qty, ","")&IF($C14="","scope, ","")&IF(OR($K14="",$M14=""),"size, ","")&IF(AND($A14<>"",$C14<>"DOOR ONLY"),IF($U14="","jamb depth, ","")&IF($X14="","construction, ","")&IF($Y14="","anchor, ","")&IF($S14="","frame type, ",""),"")&IF(AND(N($BC14)>0,$Z14=""),"hand, ","")&IF(N($BC14)>0,IF($AH14="","door material, ","")&IF($AL14="","face type, ","")&IF($AQ14="","lock prep, ","")&IF(AND($AP14="",$AC14=""),"hinge prep, ",""),"")&IF(AND($BO14>0,$AH14="FRP"),"FRP cannot carry a label, ","")&IF(AND($O14="Y",OR($Z14="L",$Z14="R",$Z14="LR",$Z14="RR")),"pair marked but hand is single, ","")&IF(AND($O14<>"Y",OR($Z14="PR",AND(LEN($Z14)>1,ISNUMBER(SEARCH("-",$Z14))))),"pair hand on a single door, ","")&IF(AND(ISNUMBER($BP14),$BO14<N($BP14)),"wall needs a "&$BP14&" min door, ","")&IF(AND($BO14>=180,AND(OR($BL14="FG",$BL14="HG",$BL14="FNV",$BL14="FV"),N($BM14)*N($BN14)>100)),"180 min lite over 100 sq in, ","")&IF(N($BD14)>48,"leaf wider than 4'-0"&CHAR(34)&", ","")) | BX14: =IF($A14="","",IF(AND($BO14>0,AND($A14<>"",$C14<>"DOOR ONLY"),$X14="KD",$E14="EXTERIOR"),"KD label on an exterior opening, ","")&IF(AND($E14="EXTERIOR",OR(AND(AND($A14<>"",$C14<>"DOOR ONLY"),$W14="CR"),AND(N($BC14)>0,$AH14="CR"))),"exterior in CR steel (G9?), ","")&IF(AND(ISNUMBER($BJ14),N($BJ14)<32),"clear width ~"&TEXT($BJ14,"0.0")&CHAR(34)&" under 32"&CHAR(34)&" (ADA), ","")&IF(AND($BO14=90,AND(OR($BL14="FG",$BL14="HG",$BL14="FNV",$BL14="FV"),N($BM14)*N($BN14)>100)),"90 min lite over 100 sq in (stair/exit), ","")&IF(AND($BO14>0,AND($A14<>"",$C14<>"DOOR ONLY"),OR($AF14="",$AF14="-")),"rated: closer reinf.?, ","")&IF(OR($I14="CORRIDOR",$I14="SMOKE BARRIER"),"S label + smoke gasketing, ","")&IF($BP14="?","wall type/hr not in IBC table, ","")&IF(AND(N($BC14)>0,$AU14=""),"no hardware set, ","")&IF(AND($AU14<>"",ISNA(MATCH($AU14,HWSets,0))),"set "&$AU14&" not on Hardware sheet, ","")&IF(N($BE14)>96,"leaf over 8'-0"&CHAR(34)&" - check listing, ",""))
